Workbook

Sheet TongHop
A1: BẢNG TỔNG HỢP VẬT TƯ BÈ PIN — 6 BÈ HỒ BẢN MÒNG (khung kết cấu "CT-KC-BE-01…06" 30/10/2026, HD lắp Mibet MRac G5)
A2: Nguồn: BV = lấy đúng bảng Revit trên tờ CT-BP; CAD = đếm / đo trên bản vẽ khung kết cấu; ƯL = ước lượng theo thông số sheet GiaDinh (phải đối chiếu BOM nhà sản xuất); NEO = theo mặt bằng neo trên web. Mục D vẽ trên bản vẽ khung có gia cường (lớp GC-*).
A3: STT | B3: Hạng mục | C3: Hình minh họa (tài liệu Mibet) | D3: Đơn vị | E3: BÈ 1 | F3: BÈ 2 | G3: BÈ 3 | H3: BÈ 4 | I3: BÈ 5 | J3: BÈ 6 | K3: TỔNG | L3: Tổng có hao hụt | M3: Nguồn | N3: Ghi chú
B4: A. PIN, INVERTER, PHAO NỔI
A5: 1 | B5: Tấm pin mặt trời | D5: tấm | E5: =DuLieuBanVe!C4 -> 2912 | F5: =DuLieuBanVe!D4 -> 4200 | G5: =DuLieuBanVe!E4 -> 700 | H5: =DuLieuBanVe!F4 -> 2100 | I5: =DuLieuBanVe!G4 -> 2800 | J5: =DuLieuBanVe!H4 -> 4200 | K5: =SUM(E5:J5) -> 16912 | L5: =K5 -> 16912 | M5: BV | N5: 16.912 tấm theo bảng từng tờ CT-BP (30/10/2026); lực gió và lực dây trên web tính theo số tấm từng bè này
A6: 2 | B6: Inverter SG-510HX | C6: (không có hình trong tài liệu) | D6: bộ | E6: =DuLieuBanVe!C7 -> 4 | F6: =DuLieuBanVe!D7 -> 6 | G6: =DuLieuBanVe!E7 -> 1 | H6: =DuLieuBanVe!F7 -> 3 | I6: =DuLieuBanVe!G7 -> 4 | J6: =DuLieuBanVe!H7 -> 4 | K6: =SUM(E6:J6) -> 22 | L6: =K6 -> 22 | M6: BV | N6: 22 inverter; bản vẽ không có SG350HX
A7: 3 | B7: Phao đỡ pin (Main Floater G5G) | D7: cái | E7: =DuLieuBanVe!C8 -> 2958 | F7: =DuLieuBanVe!D8 -> 4317 | G7: =DuLieuBanVe!E8 -> 714 | H7: =DuLieuBanVe!F8 -> 2128 | I7: =DuLieuBanVe!G8 -> 2842 | J7: =DuLieuBanVe!H8 -> 4312 | K7: =SUM(E7:J7) -> 17271 | L7: =K7 -> 17271 | M7: BV
A8: 4 | B8: Phao đi lại (Walkway Floater) — nhóm 1 | D8: cái | E8: =DuLieuBanVe!C10 -> 746 | F8: =DuLieuBanVe!D10 -> 668 | G8: =DuLieuBanVe!E10 -> 201 | H8: =DuLieuBanVe!F10 -> 445 | I8: =DuLieuBanVe!G10 -> 594 | J8: =DuLieuBanVe!H10 -> 471 | K8: =SUM(E8:J8) -> 3125 | L8: =K8 -> 3125 | M8: BV | N8: Dải phao đi lại kèm đỡ inverter. Bản vẽ chia phao đi lại thành 2 dòng; cần nhà sản xuất xác nhận là 1 hay 2 loại phao
A9: 5 | B9: Phao đi lại (Walkway Floater) — nhóm 2 | D9: cái | E9: =DuLieuBanVe!C11 -> 130 | F9: =DuLieuBanVe!D11 -> 162 | G9: =DuLieuBanVe!E11 -> 201 | H9: =DuLieuBanVe!F11 -> 253 | I9: =DuLieuBanVe!G11 -> 297 | J9: =DuLieuBanVe!H11 -> 290 | K9: =SUM(E9:J9) -> 1333 | L9: =K9 -> 1333 | M9: BV | N9: Dải phao đi lại
A10: 6 | B10: Tổng phao | C10: (không có hình trong tài liệu) | D10: cái | E10: =DuLieuBanVe!C13 -> 3834 | F10: =DuLieuBanVe!D13 -> 5147 | G10: =DuLieuBanVe!E13 -> 1116 | H10: =DuLieuBanVe!F13 -> 2826 | I10: =DuLieuBanVe!G13 -> 3733 | J10: =DuLieuBanVe!H13 -> 5073 | K10: =SUM(E10:J10) -> 21729 | L10: =K10 -> 21729 | M10: BV
A11: 7 | B11: Phao đỡ cáp điện giữa các bè | C11: (không có hình trong tài liệu) | D11: cái | K11: =DuLieuBanVe!I24 -> 2654 | L11: =K11 -> 2654 | M11: BV | N11: Tờ MB-B01-01: 1.327 hàng × 2 = 2.654 phao. cả hồ (không chia theo bè)
A12: 8 | B12: Bộ bulông nhựa nối phao | D12: bộ | E12: =ROUNDUP(DuLieuBanVe!C13*GiaDinh!$C$13,0) -> 7668 | F12: =ROUNDUP(DuLieuBanVe!D13*GiaDinh!$C$13,0) -> 10294 | G12: =ROUNDUP(DuLieuBanVe!E13*GiaDinh!$C$13,0) -> 2232 | H12: =ROUNDUP(DuLieuBanVe!F13*GiaDinh!$C$13,0) -> 5652 | I12: =ROUNDUP(DuLieuBanVe!G13*GiaDinh!$C$13,0) -> 7466 | J12: =ROUNDUP(DuLieuBanVe!H13*GiaDinh!$C$13,0) -> 10146 | K12: =SUM(E12:J12) -> 43458 | L12: =ROUNDUP(K12*(1+GiaDinh!$C$14/100),0) -> 44762 | M12: ƯL | N12: Tổng phao bè × hệ số K_FB ở GiaDinh
B13: B. DẦM C52 (đặt trên rãnh phao)
A14: 9 | B14: Dầm C52 — số thanh liên tục | C14: (không có hình trong tài liệu) | D14: thanh | E14: =DuLieuBanVe!C14 -> 100 | F14: =DuLieuBanVe!D14 -> 244 | G14: =DuLieuBanVe!E14 -> 32 | H14: =DuLieuBanVe!F14 -> 60 | I14: =DuLieuBanVe!G14 -> 92 | J14: =DuLieuBanVe!H14 -> 236 | K14: =SUM(E14:J14) -> 764 | L14: =K14 -> 764 | M14: CAD | N14: Đếm trên bản vẽ CAD khung kết cấu (đối chiếu bảng tờ CT-KC-BE: DoiChieu_KhungThep)
A15: 10 | B15: Dầm C52 — chiều dài | D15: m | E15: =DuLieuBanVe!C15 -> 12652.92 | F15: =DuLieuBanVe!D15 -> 17906.83 | G15: =DuLieuBanVe!E15 -> 3236 | H15: =DuLieuBanVe!F15 -> 9165.8 | I15: =DuLieuBanVe!G15 -> 12388.2 | J15: =DuLieuBanVe!H15 -> 17963.53 | K15: =SUM(E15:J15) -> 73313.28 | L15: =K15 -> 73313.28 | M15: CAD | N15: Cộng từng thanh trên bản vẽ CAD
A16: 11 | B16: Dầm C52 — số cây cấp hàng | D16: cây | E16: =SUMIF('C52_TungThanh'!$A$4:$A$767,"BÈ 1",'C52_TungThanh'!$D$4:$D$767) -> 2164 | F16: =SUMIF('C52_TungThanh'!$A$4:$A$767,"BÈ 2",'C52_TungThanh'!$D$4:$D$767) -> 3124 | G16: =SUMIF('C52_TungThanh'!$A$4:$A$767,"BÈ 3",'C52_TungThanh'!$D$4:$D$767) -> 544 | H16: =SUMIF('C52_TungThanh'!$A$4:$A$767,"BÈ 4",'C52_TungThanh'!$D$4:$D$767) -> 1576 | I16: =SUMIF('C52_TungThanh'!$A$4:$A$767,"BÈ 5",'C52_TungThanh'!$D$4:$D$767) -> 2090 | J16: =SUMIF('C52_TungThanh'!$A$4:$A$767,"BÈ 6",'C52_TungThanh'!$D$4:$D$767) -> 3182 | K16: =SUM(E16:J16) -> 12680 | L16: =K16 -> 12680 | M16: CAD | N16: Từng thanh: ROUNDUP(L / L_C52) (sheet C52_TungThanh)
A17: 12 | B17: Bộ nối dầm C52 (Splice for Beam-C) | D17: bộ | E17: =SUMIF('C52_TungThanh'!$A$4:$A$767,"BÈ 1",'C52_TungThanh'!$E$4:$E$767) -> 2064 | F17: =SUMIF('C52_TungThanh'!$A$4:$A$767,"BÈ 2",'C52_TungThanh'!$E$4:$E$767) -> 2880 | G17: =SUMIF('C52_TungThanh'!$A$4:$A$767,"BÈ 3",'C52_TungThanh'!$E$4:$E$767) -> 512 | H17: =SUMIF('C52_TungThanh'!$A$4:$A$767,"BÈ 4",'C52_TungThanh'!$E$4:$E$767) -> 1516 | I17: =SUMIF('C52_TungThanh'!$A$4:$A$767,"BÈ 5",'C52_TungThanh'!$E$4:$E$767) -> 1998 | J17: =SUMIF('C52_TungThanh'!$A$4:$A$767,"BÈ 6",'C52_TungThanh'!$E$4:$E$767) -> 2946 | K17: =SUM(E17:J17) -> 11916 | L17: =ROUNDUP(K17*(1+GiaDinh!$C$14/100),0) -> 12274 | M17: CAD | N17: Số cây − số thanh. Nối đối đầu; mỗi bộ: 1 bản nối + 2 bulông M10×70 + 2 chốt M10×60 + đai ốc, long đen (tài liệu phụ kiện Mibet)
A18: 13 | B18: Dầm C52 — khối lượng | D18: kg | E18: =DuLieuBanVe!C15*GiaDinh!$C$6 -> 29860.891 | F18: =DuLieuBanVe!D15*GiaDinh!$C$6 -> 42260.119 | G18: =DuLieuBanVe!E15*GiaDinh!$C$6 -> 7636.96 | H18: =DuLieuBanVe!F15*GiaDinh!$C$6 -> 21631.288 | I18: =DuLieuBanVe!G15*GiaDinh!$C$6 -> 29236.152 | J18: =DuLieuBanVe!H15*GiaDinh!$C$6 -> 42393.931 | K18: =SUM(E18:J18) -> 173019.34 | L18: =K18 -> 173019.34 | M18: ƯL | N18: Theo tiết diện GIẢ ĐỊNH
A19: 14 | B19: Bulông M8×35 bắt dầm C52 vào phao | D19: bộ | E19: =ROUNDUP(DuLieuBanVe!C15*GiaDinh!$C$19,0) -> 6327 | F19: =ROUNDUP(DuLieuBanVe!D15*GiaDinh!$C$19,0) -> 8954 | G19: =ROUNDUP(DuLieuBanVe!E15*GiaDinh!$C$19,0) -> 1618 | H19: =ROUNDUP(DuLieuBanVe!F15*GiaDinh!$C$19,0) -> 4583 | I19: =ROUNDUP(DuLieuBanVe!G15*GiaDinh!$C$19,0) -> 6195 | J19: =ROUNDUP(DuLieuBanVe!H15*GiaDinh!$C$19,0) -> 8982 | K19: =SUM(E19:J19) -> 36659 | L19: =ROUNDUP(K19*(1+GiaDinh!$C$14/100),0) -> 37759 | M19: ƯL | N19: 1 bộ tại mỗi chỗ dầm C52 vượt qua một hàng phao (K_XF)
B20: C. HỘP 40x60 KẾT CẤU (nằm ngang trên dầm C52)
A21: 15 | B21: Hộp 40x60 — số thanh liên tục | D21: thanh | E21: =DuLieuBanVe!C16 -> 38 | F21: =DuLieuBanVe!D16 -> 20 | G21: =DuLieuBanVe!E16 -> 18 | H21: =DuLieuBanVe!F16 -> 32 | I21: =DuLieuBanVe!G16 -> 27 | J21: =DuLieuBanVe!H16 -> 16 | K21: =SUM(E21:J21) -> 151 | L21: =K21 -> 151 | M21: CAD | N21: Đếm trên bản vẽ CAD khung kết cấu
A22: 16 | B22: Hộp 40x60 — chiều dài | D22: m | E22: =DuLieuBanVe!C17 -> 2986.38 | F22: =DuLieuBanVe!D17 -> 4449.14 | G22: =DuLieuBanVe!E17 -> 705.69 | H22: =DuLieuBanVe!F17 -> 2072.01 | I22: =DuLieuBanVe!G17 -> 2741.94 | J22: =DuLieuBanVe!H17 -> 4254.11 | K22: =SUM(E22:J22) -> 17209.27 | L22: =K22 -> 17209.27 | M22: CAD | N22: Cộng từng thanh trên bản vẽ CAD
A23: 17 | B23: Hộp 40x60 — số cây cấp hàng | D23: cây | E23: =SUMIF(Hop40x60_TungThanh!$A$4:$A$154,"BÈ 1",Hop40x60_TungThanh!$D$4:$D$154) -> 512 | F23: =SUMIF(Hop40x60_TungThanh!$A$4:$A$154,"BÈ 2",Hop40x60_TungThanh!$D$4:$D$154) -> 747 | G23: =SUMIF(Hop40x60_TungThanh!$A$4:$A$154,"BÈ 3",Hop40x60_TungThanh!$D$4:$D$154) -> 126 | H23: =SUMIF(Hop40x60_TungThanh!$A$4:$A$154,"BÈ 4",Hop40x60_TungThanh!$D$4:$D$154) -> 362 | I23: =SUMIF(Hop40x60_TungThanh!$A$4:$A$154,"BÈ 5",Hop40x60_TungThanh!$D$4:$D$154) -> 465 | J23: =SUMIF(Hop40x60_TungThanh!$A$4:$A$154,"BÈ 6",Hop40x60_TungThanh!$D$4:$D$154) -> 715 | K23: =SUM(E23:J23) -> 2927 | L23: =K23 -> 2927 | M23: CAD | N23: Từng thanh: ROUNDUP(L / L_H) (sheet Hop40x60_TungThanh)
A24: 18 | B24: Bộ nối hộp 40x60 (Splice for Square Steel) | D24: bộ | E24: =SUMIF(Hop40x60_TungThanh!$A$4:$A$154,"BÈ 1",Hop40x60_TungThanh!$E$4:$E$154) -> 474 | F24: =SUMIF(Hop40x60_TungThanh!$A$4:$A$154,"BÈ 2",Hop40x60_TungThanh!$E$4:$E$154) -> 727 | G24: =SUMIF(Hop40x60_TungThanh!$A$4:$A$154,"BÈ 3",Hop40x60_TungThanh!$E$4:$E$154) -> 108 | H24: =SUMIF(Hop40x60_TungThanh!$A$4:$A$154,"BÈ 4",Hop40x60_TungThanh!$E$4:$E$154) -> 330 | I24: =SUMIF(Hop40x60_TungThanh!$A$4:$A$154,"BÈ 5",Hop40x60_TungThanh!$E$4:$E$154) -> 438 | J24: =SUMIF(Hop40x60_TungThanh!$A$4:$A$154,"BÈ 6",Hop40x60_TungThanh!$E$4:$E$154) -> 699 | K24: =SUM(E24:J24) -> 2776 | L24: =ROUNDUP(K24*(1+GiaDinh!$C$14/100),0) -> 2860 | M24: CAD | N24: Nối đối đầu bằng bộ nối của nhà sản xuất (datasheet G5G)
A25: 19 | B25: Hộp 40x60 — khối lượng | D25: kg | E25: =DuLieuBanVe!C17*GiaDinh!$C$7 -> 8989.0038 | F25: =DuLieuBanVe!D17*GiaDinh!$C$7 -> 13391.911 | G25: =DuLieuBanVe!E17*GiaDinh!$C$7 -> 2124.1269 | H25: =DuLieuBanVe!F17*GiaDinh!$C$7 -> 6236.7501 | I25: =DuLieuBanVe!G17*GiaDinh!$C$7 -> 8253.2394 | J25: =DuLieuBanVe!H17*GiaDinh!$C$7 -> 12804.871 | K25: =SUM(E25:J25) -> 51799.903 | L25: =K25 -> 51799.903 | M25: ƯL | N25: Theo tiết diện GIẢ ĐỊNH
A26: 20 | B26: Bulông M10×120 bắt hộp 40x60 vào dầm C52 | D26: bộ | E26: =ROUNDUP(DuLieuBanVe!C17/GiaDinh!$C$20,0) -> 2475 | F26: =ROUNDUP(DuLieuBanVe!D17/GiaDinh!$C$20,0) -> 3687 | G26: =ROUNDUP(DuLieuBanVe!E17/GiaDinh!$C$20,0) -> 585 | H26: =ROUNDUP(DuLieuBanVe!F17/GiaDinh!$C$20,0) -> 1717 | I26: =ROUNDUP(DuLieuBanVe!G17/GiaDinh!$C$20,0) -> 2272 | J26: =ROUNDUP(DuLieuBanVe!H17/GiaDinh!$C$20,0) -> 3525 | K26: =SUM(E26:J26) -> 14261 | L26: =ROUNDUP(K26*(1+GiaDinh!$C$14/100),0) -> 14689 | M26: ƯL | N26: 1 bộ tại mỗi giao điểm hộp – dầm C52 (HD lắp G5 bước 8)
B27: D. HỘP 40x60 GIA CƯỜNG TẠI VỊ TRÍ NEO (vẽ trên bản vẽ khung kết cấu, lớp GC-*; sức chịu móc "几" GIẢ ĐỊNH)
A28: 21 | B28: Hộp 40x60 gia cường — số thanh | D28: thanh | E28: =SUMIF(GiaCuong_TaiNeo!$A$4:$A$317,"BÈ 1",GiaCuong_TaiNeo!$K$4:$K$317) -> 88 | F28: =SUMIF(GiaCuong_TaiNeo!$A$4:$A$317,"BÈ 2",GiaCuong_TaiNeo!$K$4:$K$317) -> 173 | G28: =SUMIF(GiaCuong_TaiNeo!$A$4:$A$317,"BÈ 3",GiaCuong_TaiNeo!$K$4:$K$317) -> 38 | H28: =SUMIF(GiaCuong_TaiNeo!$A$4:$A$317,"BÈ 4",GiaCuong_TaiNeo!$K$4:$K$317) -> 129 | I28: =SUMIF(GiaCuong_TaiNeo!$A$4:$A$317,"BÈ 5",GiaCuong_TaiNeo!$K$4:$K$317) -> 109 | J28: =SUMIF(GiaCuong_TaiNeo!$A$4:$A$317,"BÈ 6",GiaCuong_TaiNeo!$K$4:$K$317) -> 177 | K28: =SUM(E28:J28) -> 714 | L28: =K28 -> 714 | M28: CAD | N28: Sheet GiaCuong_TaiNeo (từng cụm, mã cụm như trên bản vẽ khung có gia cường)
A29: 22 | B29: Hộp 40x60 gia cường — chiều dài | D29: m | E29: =SUMIF(GiaCuong_TaiNeo!$A$4:$A$317,"BÈ 1",GiaCuong_TaiNeo!$M$4:$M$317) -> 1302.634 | F29: =SUMIF(GiaCuong_TaiNeo!$A$4:$A$317,"BÈ 2",GiaCuong_TaiNeo!$M$4:$M$317) -> 2489.998 | G29: =SUMIF(GiaCuong_TaiNeo!$A$4:$A$317,"BÈ 3",GiaCuong_TaiNeo!$M$4:$M$317) -> 570 | H29: =SUMIF(GiaCuong_TaiNeo!$A$4:$A$317,"BÈ 4",GiaCuong_TaiNeo!$M$4:$M$317) -> 1914.136 | I29: =SUMIF(GiaCuong_TaiNeo!$A$4:$A$317,"BÈ 5",GiaCuong_TaiNeo!$M$4:$M$317) -> 1616.33 | J29: =SUMIF(GiaCuong_TaiNeo!$A$4:$A$317,"BÈ 6",GiaCuong_TaiNeo!$M$4:$M$317) -> 2613.879 | K29: =SUM(E29:J29) -> 10506.977 | L29: =K29 -> 10506.977 | M29: CAD | N29: Đo trên bản vẽ khung có gia cường (thanh dài 15 m, ngắn hơn ở cụm sát nhau)
A30: 23 | B30: Hộp 40x60 gia cường — số cây cấp hàng | D30: cây | E30: =SUMIF(GiaCuong_TaiNeo!$A$4:$A$317,"BÈ 1",GiaCuong_TaiNeo!$N$4:$N$317) -> 260 | F30: =SUMIF(GiaCuong_TaiNeo!$A$4:$A$317,"BÈ 2",GiaCuong_TaiNeo!$N$4:$N$317) -> 506 | G30: =SUMIF(GiaCuong_TaiNeo!$A$4:$A$317,"BÈ 3",GiaCuong_TaiNeo!$N$4:$N$317) -> 114 | H30: =SUMIF(GiaCuong_TaiNeo!$A$4:$A$317,"BÈ 4",GiaCuong_TaiNeo!$N$4:$N$317) -> 384 | I30: =SUMIF(GiaCuong_TaiNeo!$A$4:$A$317,"BÈ 5",GiaCuong_TaiNeo!$N$4:$N$317) -> 322 | J30: =SUMIF(GiaCuong_TaiNeo!$A$4:$A$317,"BÈ 6",GiaCuong_TaiNeo!$N$4:$N$317) -> 528 | K30: =SUM(E30:J30) -> 2114 | L30: =K30 -> 2114 | M30: CAD | N30: Từng thanh: ROUNDUP(L / L_H)
A31: 24 | B31: Bộ nối hộp 40x60 (gia cường) | D31: bộ | E31: =SUMIF(GiaCuong_TaiNeo!$A$4:$A$317,"BÈ 1",GiaCuong_TaiNeo!$O$4:$O$317) -> 172 | F31: =SUMIF(GiaCuong_TaiNeo!$A$4:$A$317,"BÈ 2",GiaCuong_TaiNeo!$O$4:$O$317) -> 333 | G31: =SUMIF(GiaCuong_TaiNeo!$A$4:$A$317,"BÈ 3",GiaCuong_TaiNeo!$O$4:$O$317) -> 76 | H31: =SUMIF(GiaCuong_TaiNeo!$A$4:$A$317,"BÈ 4",GiaCuong_TaiNeo!$O$4:$O$317) -> 255 | I31: =SUMIF(GiaCuong_TaiNeo!$A$4:$A$317,"BÈ 5",GiaCuong_TaiNeo!$O$4:$O$317) -> 213 | J31: =SUMIF(GiaCuong_TaiNeo!$A$4:$A$317,"BÈ 6",GiaCuong_TaiNeo!$O$4:$O$317) -> 351 | K31: =SUM(E31:J31) -> 1400 | L31: =ROUNDUP(K31*(1+GiaDinh!$C$14/100),0) -> 1442 | M31: ƯL
A32: 25 | B32: Móc chữ "几" kẹp hộp vào dầm C52 | D32: cái | E32: =SUMIF(GiaCuong_TaiNeo!$A$4:$A$317,"BÈ 1",GiaCuong_TaiNeo!$P$4:$P$317) -> 1049 | F32: =SUMIF(GiaCuong_TaiNeo!$A$4:$A$317,"BÈ 2",GiaCuong_TaiNeo!$P$4:$P$317) -> 2011 | G32: =SUMIF(GiaCuong_TaiNeo!$A$4:$A$317,"BÈ 3",GiaCuong_TaiNeo!$P$4:$P$317) -> 466 | H32: =SUMIF(GiaCuong_TaiNeo!$A$4:$A$317,"BÈ 4",GiaCuong_TaiNeo!$P$4:$P$317) -> 1563 | I32: =SUMIF(GiaCuong_TaiNeo!$A$4:$A$317,"BÈ 5",GiaCuong_TaiNeo!$P$4:$P$317) -> 1326 | J32: =SUMIF(GiaCuong_TaiNeo!$A$4:$A$317,"BÈ 6",GiaCuong_TaiNeo!$P$4:$P$317) -> 2128 | K32: =SUM(E32:J32) -> 8543 | L32: =ROUNDUP(K32*(1+GiaDinh!$C$14/100),0) -> 8800 | M32: CAD | N32: HD lắp G5 bước 8: hộp dùng làm điểm neo kẹp bằng móc "几" tại mọi giao điểm với C52 — đếm giao điểm trên bản vẽ
A33: 26 | B33: Bộ đai ốc thoi M10×30 (cho móc "几") | D33: bộ | E33: =SUMIF(GiaCuong_TaiNeo!$A$4:$A$317,"BÈ 1",GiaCuong_TaiNeo!$Q$4:$Q$317) -> 2098 | F33: =SUMIF(GiaCuong_TaiNeo!$A$4:$A$317,"BÈ 2",GiaCuong_TaiNeo!$Q$4:$Q$317) -> 4022 | G33: =SUMIF(GiaCuong_TaiNeo!$A$4:$A$317,"BÈ 3",GiaCuong_TaiNeo!$Q$4:$Q$317) -> 932 | H33: =SUMIF(GiaCuong_TaiNeo!$A$4:$A$317,"BÈ 4",GiaCuong_TaiNeo!$Q$4:$Q$317) -> 3126 | I33: =SUMIF(GiaCuong_TaiNeo!$A$4:$A$317,"BÈ 5",GiaCuong_TaiNeo!$Q$4:$Q$317) -> 2652 | J33: =SUMIF(GiaCuong_TaiNeo!$A$4:$A$317,"BÈ 6",GiaCuong_TaiNeo!$Q$4:$Q$317) -> 4256 | K33: =SUM(E33:J33) -> 17086 | L33: =ROUNDUP(K33*(1+GiaDinh!$C$14/100),0) -> 17599 | M33: ƯL | N33: 2 bộ mỗi móc
A34: 27 | B34: Bulông M10×120 (hộp gia cường) | D34: bộ | E34: =SUMIF(GiaCuong_TaiNeo!$A$4:$A$317,"BÈ 1",GiaCuong_TaiNeo!$R$4:$R$317) -> 1049 | F34: =SUMIF(GiaCuong_TaiNeo!$A$4:$A$317,"BÈ 2",GiaCuong_TaiNeo!$R$4:$R$317) -> 2011 | G34: =SUMIF(GiaCuong_TaiNeo!$A$4:$A$317,"BÈ 3",GiaCuong_TaiNeo!$R$4:$R$317) -> 466 | H34: =SUMIF(GiaCuong_TaiNeo!$A$4:$A$317,"BÈ 4",GiaCuong_TaiNeo!$R$4:$R$317) -> 1563 | I34: =SUMIF(GiaCuong_TaiNeo!$A$4:$A$317,"BÈ 5",GiaCuong_TaiNeo!$R$4:$R$317) -> 1326 | J34: =SUMIF(GiaCuong_TaiNeo!$A$4:$A$317,"BÈ 6",GiaCuong_TaiNeo!$R$4:$R$317) -> 2128 | K34: =SUM(E34:J34) -> 8543 | L34: =ROUNDUP(K34*(1+GiaDinh!$C$14/100),0) -> 8800 | M34: ƯL | N34: 1 bộ mỗi móc
A35: 28 | B35: Hộp 40x60 gia cường — khối lượng | D35: kg | E35: =SUMIF(GiaCuong_TaiNeo!$A$4:$A$317,"BÈ 1",GiaCuong_TaiNeo!$S$4:$S$317) -> 3920.9283 | F35: =SUMIF(GiaCuong_TaiNeo!$A$4:$A$317,"BÈ 2",GiaCuong_TaiNeo!$S$4:$S$317) -> 7494.894 | G35: =SUMIF(GiaCuong_TaiNeo!$A$4:$A$317,"BÈ 3",GiaCuong_TaiNeo!$S$4:$S$317) -> 1715.7 | H35: =SUMIF(GiaCuong_TaiNeo!$A$4:$A$317,"BÈ 4",GiaCuong_TaiNeo!$S$4:$S$317) -> 5761.5494 | I35: =SUMIF(GiaCuong_TaiNeo!$A$4:$A$317,"BÈ 5",GiaCuong_TaiNeo!$S$4:$S$317) -> 4865.1533 | J35: =SUMIF(GiaCuong_TaiNeo!$A$4:$A$317,"BÈ 6",GiaCuong_TaiNeo!$S$4:$S$317) -> 7867.7758 | K35: =SUM(E35:J35) -> 31626.001 | L35: =K35 -> 31626.001 | M35: ƯL | N35: Theo tiết diện GIẢ ĐỊNH
B36: E. GÁ ĐỠ VÀ KẸP TẤM PIN
A37: 29 | B37: Gá trước (Front Support G5) | D37: cái | E37: =DuLieuBanVe!C4*GiaDinh!$C$8 -> 5824 | F37: =DuLieuBanVe!D4*GiaDinh!$C$8 -> 8400 | G37: =DuLieuBanVe!E4*GiaDinh!$C$8 -> 1400 | H37: =DuLieuBanVe!F4*GiaDinh!$C$8 -> 4200 | I37: =DuLieuBanVe!G4*GiaDinh!$C$8 -> 5600 | J37: =DuLieuBanVe!H4*GiaDinh!$C$8 -> 8400 | K37: =SUM(E37:J37) -> 33824 | L37: =ROUNDUP(K37*(1+GiaDinh!$C$14/100),0) -> 34839 | M37: ƯL
A38: 30 | B38: Gá sau (Back Support G5) | D38: cái | E38: =DuLieuBanVe!C4*GiaDinh!$C$9 -> 5824 | F38: =DuLieuBanVe!D4*GiaDinh!$C$9 -> 8400 | G38: =DuLieuBanVe!E4*GiaDinh!$C$9 -> 1400 | H38: =DuLieuBanVe!F4*GiaDinh!$C$9 -> 4200 | I38: =DuLieuBanVe!G4*GiaDinh!$C$9 -> 5600 | J38: =DuLieuBanVe!H4*GiaDinh!$C$9 -> 8400 | K38: =SUM(E38:J38) -> 33824 | L38: =ROUNDUP(K38*(1+GiaDinh!$C$14/100),0) -> 34839 | M38: ƯL
A39: 31 | B39: Bộ kẹp biên tấm pin (End Clamp Kit, bulông M8×30) | D39: bộ | E39: =DuLieuBanVe!C4*GiaDinh!$C$10 -> 5824 | F39: =DuLieuBanVe!D4*GiaDinh!$C$10 -> 8400 | G39: =DuLieuBanVe!E4*GiaDinh!$C$10 -> 1400 | H39: =DuLieuBanVe!F4*GiaDinh!$C$10 -> 4200 | I39: =DuLieuBanVe!G4*GiaDinh!$C$10 -> 5600 | J39: =DuLieuBanVe!H4*GiaDinh!$C$10 -> 8400 | K39: =SUM(E39:J39) -> 33824 | L39: =ROUNDUP(K39*(1+GiaDinh!$C$14/100),0) -> 34839 | M39: ƯL
A40: 32 | B40: Bộ kẹp tiếp địa tấm pin | C40: (không có hình trong tài liệu) | D40: bộ | E40: =DuLieuBanVe!C4*GiaDinh!$C$11 -> 5824 | F40: =DuLieuBanVe!D4*GiaDinh!$C$11 -> 8400 | G40: =DuLieuBanVe!E4*GiaDinh!$C$11 -> 1400 | H40: =DuLieuBanVe!F4*GiaDinh!$C$11 -> 4200 | I40: =DuLieuBanVe!G4*GiaDinh!$C$11 -> 5600 | J40: =DuLieuBanVe!H4*GiaDinh!$C$11 -> 8400 | K40: =SUM(E40:J40) -> 33824 | L40: =ROUNDUP(K40*(1+GiaDinh!$C$14/100),0) -> 34839 | M40: ƯL | N40: Cần nối đẳng thế khung tấm pin; hỏi Mibet kẹp của MRac G5 có răng tiếp địa không và định mức bộ/tấm trước khi đặt
...

Sheet DuLieuBanVe
A1: SỐ LIỆU LẤY TỪ BẢN VẼ "BO TRI BE PIN HO BAN MONG" (bảng Revit trên các tờ CT-BP-01…06, MB-B01-01) VÀ BẢN VẼ CAD KHUNG "CT-KC-BE-01…06" (30/10/2026)
A3: Mã | B3: Hạng mục | C3: BÈ 1 | D3: BÈ 2 | E3: BÈ 3 | F3: BÈ 4 | G3: BÈ 5 | H3: BÈ 6 | I3: TỔNG | J3: Nguồn
A4: PV | B4: Tấm pin (tấm) | C4: 2912 | D4: 4200 | E4: 700 | F4: 2100 | G4: 2800 | H4: 4200 | I4: =SUM(C4:H4) -> 16912 | J4: Bảng "THỐNG KÊ TẤM PIN MẶT TRỜI" (tờ CT-BP), cột Số tấm pin
A5: DPV | B5: Dải pin (hàng) | C5: 119 | D5: 158 | E5: 50 | F5: 87 | G5: 148 | H5: 150 | I5: =SUM(C5:H5) -> 712 | J5: Như trên, cột SỐ LƯỢNG HÀNG
A6: STR | B6: Số string | C6: 104 | D6: 150 | E6: 25 | F6: 75 | G6: 100 | H6: 150 | I6: =SUM(C6:H6) -> 604 | J6: Như trên, cột So string
A7: I510 | B7: Inverter SG-510HX (bộ) | C7: 4 | D7: 6 | E7: 1 | F7: 3 | G7: 4 | H7: 4 | I7: =SUM(C7:H7) -> 22 | J7: Bảng "INVESTER" (tờ CT-BP)
A8: FS | B8: Phao đỡ pin — Main Floater (cái) | C8: 2958 | D8: 4317 | E8: 714 | F8: 2128 | G8: 2842 | H8: 4312 | I8: =SUM(C8:H8) -> 17271 | J8: Bảng "SỐ PHAO NỔI THEO BÈ", dòng "Dai phao do pin"
A9: FSR | B9: Số hàng phao đỡ pin | C9: 122 | D9: 162 | E9: 51 | F9: 88 | G9: 150 | H9: 154 | I9: =SUM(C9:H9) -> 727 | J9: Như trên, cột SỐ LƯỢNG HÀNG
A10: FWA | B10: Phao đi lại kèm đỡ inverter (cái) | C10: 746 | D10: 668 | E10: 201 | F10: 445 | G10: 594 | H10: 471 | I10: =SUM(C10:H10) -> 3125 | J10: Dòng "Dải phao đi lại kèm đỡ invester"
A11: FWB | B11: Phao đi lại (cái) | C11: 130 | D11: 162 | E11: 201 | F11: 253 | G11: 297 | H11: 290 | I11: =SUM(C11:H11) -> 1333 | J11: Dòng "Dai phaodi lai"
A12: FWR | B12: Số hàng phao đi lại | C12: 7 | D12: 12 | E12: 2 | F12: 3 | G12: 4 | H12: 5 | I12: =SUM(C12:H12) -> 33 | J12: Cộng cột SỐ LƯỢNG HÀNG hai dòng phao đi lại
A13: FT | B13: Tổng phao (cái) | C13: =C8+C10+C11 -> 3834 | D13: =D8+D10+D11 -> 5147 | E13: =E8+E10+E11 -> 1116 | F13: =F8+F10+F11 -> 2826 | G13: =G8+G10+G11 -> 3733 | H13: =H8+H10+H11 -> 5073 | I13: =SUM(C13:H13) -> 21729 | J13: Khớp "Grand total" của bảng phao từng tờ
A14: C52N | B14: Dầm C52 — số thanh (ĐO CAD) | C14: 100 | D14: 244 | E14: 32 | F14: 60 | G14: 92 | H14: 236 | I14: =SUM(C14:H14) -> 764 | J14: Đếm trên bản vẽ CAD khung (sheet C52_TungThanh)
A15: C52L | B15: Dầm C52 — chiều dài (m, ĐO CAD) | C15: 12652.92 | D15: 17906.83 | E15: 3236 | F15: 9165.8 | G15: 12388.2 | H15: 17963.53 | I15: =SUM(C15:H15) -> 73313.28 | J15: Cộng từng thanh trên bản vẽ CAD
A16: HN | B16: Hộp 40x60 kết cấu — số thanh (ĐO CAD) | C16: 38 | D16: 20 | E16: 18 | F16: 32 | G16: 27 | H16: 16 | I16: =SUM(C16:H16) -> 151 | J16: Đếm trên bản vẽ CAD (sheet Hop40x60_TungThanh)
A17: HL | B17: Hộp 40x60 kết cấu — chiều dài (m, ĐO CAD) | C17: 2986.38 | D17: 4449.14 | E17: 705.69 | F17: 2072.01 | G17: 2741.94 | H17: 4254.11 | I17: =SUM(C17:H17) -> 17209.27 | J17: Cộng từng thanh trên bản vẽ CAD
A18: C52N_BV | B18: Dầm C52 — số thanh (bảng tờ CT-KC-BE) | C18: 100 | D18: 244 | E18: 32 | F18: 60 | G18: 92 | H18: 236 | I18: =SUM(C18:H18) -> 764 | J18: Bảng "THỐNG KÊ KHUNG THÉP" trên tờ khung — để đối chiếu
A19: C52L_BV | B19: Dầm C52 — chiều dài (m, bảng tờ CT-KC-BE) | C19: 12652.9 | D19: 17906.84 | E19: 3236.01 | F19: 9165.79 | G19: 12388.18 | H19: 17963.45 | I19: =SUM(C19:H19) -> 73313.17 | J19: Như trên
A20: HN_BV | B20: Hộp 40x60 — số thanh (bảng tờ CT-KC-BE) | C20: 38 | D20: 20 | E20: 18 | F20: 32 | G20: 27 | H20: 16 | I20: =SUM(C20:H20) -> 151 | J20: Như trên
A21: HL_BV | B21: Hộp 40x60 — chiều dài (m, bảng tờ CT-KC-BE) | C21: 2986.38 | D21: 4449.15 | E21: 705.69 | F21: 2072.02 | G21: 2741.95 | H21: 4254.11 | I21: =SUM(C21:H21) -> 17209.3 | J21: Như trên
A22: LINE | B22: Số dây neo của bè (tuyến cáp) | C22: 43 | D22: 52 | E22: 19 | F22: 30 | G22: 37 | H22: 50 | I22: =SUM(C22:H22) -> 231 | J22: Mặt bằng neo trên web (ưu tiên bờ, 80 m)
A23: TIE | B23: Số dây nối sang bè bên cạnh | C23: 0 | D23: 6 | E23: 0 | F23: 6 | G23: 0 | H23: 0 | I23: =SUM(C23:H23) -> 12 | J23: ties.json của web (BÈ 2 – BÈ 4 nối thay cho các đế dùng chung ở khe)
A24: FC | B24: Phao đỡ cáp điện giữa các bè (cái, cả hồ) | I24: 2654 | J24: Tờ MB-B01-01, bảng "SỐ PHAO ĐỠ CÁP": 1327 hàng, 2654 phao (không chia theo bè)

Sheet GiaCuong_TaiNeo
A1: HỘP 40x60 GIA CƯỜNG TẠI VỊ TRÍ NEO — VẼ TRÊN BẢN VẼ KHUNG KẾT CẤU "CT-KC-BE-01…06" (lớp GC-*), CÁP 2 NHÁNH CHỮ Y (2 bích mỗi dây, cách nhau 3,5 m)
A2: Mỗi thanh nằm trên một hàng phao, theo phương hộp 40x60 kết cấu (vuông góc dầm C52), kẹp móc "几" vào MỌI dầm C52 nó cắt qua — số dầm cắt qua ĐẾM trên bản vẽ khung. Bích trên cạnh song song với hộp: các bích trong 14 m dùng chung thanh dọc cạnh (hàng phao thứ 2 tính từ mép); bích trên cạnh vuông góc: mỗi bích một thanh từ dầm C52 ngoài cùng vào trong. Số thanh cần = MAX(1; ROUNDUP(số bích × K_Y × T × γ / (dầm C52 cắt qua × P_KEP))); cột "Số thanh vẽ" là số thanh trên bản vẽ (theo giá trị mặc định ở GiaDinh) — sửa P_KEP mà cột Kiểm tra báo THIẾU thì phải vẽ thêm thanh.
A3: Bè | B3: Mã cụm (trên bản vẽ) | C3: Cách bố trí | D3: Bích trong cụm (mã dây + a/b) | E3: Số bích | F3: T dây (kN, gió 20 m/s) | G3: Lực thiết kế cụm = (số bích dây neo × K_Y × T + lực dây nối) × γ (kN) | H3: Dầm C52 cắt qua — thanh ít nhất (ĐO CAD) | I3: Sức chịu 1 thanh (kN) | J3: Số thanh cần | K3: Số thanh vẽ | L3: Kiểm tra | M3: Tổng dài (m, ĐO CAD) | N3: Số cây cấp hàng | O3: Số mối nối | P3: Móc "几" (cái, ĐO CAD) | Q3: Đai ốc thoi M10×30 (bộ) | R3: Bulông M10×120 (bộ) | S3: Khối lượng (kg)
A4: BÈ 1 | B4: B1-01 | C4: Dọc cạnh | D4: B1-D12a, B1-D12b | E4: 2 | F4: 85.7 | G4: =2*F4*GiaDinh!$C$18*GiaDinh!$C$17 -> 143.976 | H4: 13 | I4: =H4*GiaDinh!$C$16 -> 91 | J4: =MAX(1,ROUNDUP(G4/I4-0.0005,0)) -> 2 | K4: 2 | L4: =IF(K4>=J4,"ĐỦ","THIẾU") -> ĐỦ | M4: 30 | N4: =ROUNDUP(15/GiaDinh!$C$5-0.0005,0)+ROUNDUP(15/GiaDinh!$C$5-0.0005,0) -> 6 | O4: =N4-K4 -> 4 | P4: 26 | Q4: =2*P4 -> 52 | R4: =P4 -> 26 | S4: =M4*GiaDinh!$C$7 -> 90.3
A5: BÈ 1 | B5: B1-02 | C5: Dọc cạnh | D5: B1-D31a, B1-D31b | E5: 2 | F5: 85.7 | G5: =2*F5*GiaDinh!$C$18*GiaDinh!$C$17 -> 143.976 | H5: 11 | I5: =H5*GiaDinh!$C$16 -> 77 | J5: =MAX(1,ROUNDUP(G5/I5-0.0005,0)) -> 2 | K5: 2 | L5: =IF(K5>=J5,"ĐỦ","THIẾU") -> ĐỦ | M5: 27.948 | N5: =ROUNDUP(13.974/GiaDinh!$C$5-0.0005,0)+ROUNDUP(13.974/GiaDinh!$C$5-0.0005,0) -> 6 | O5: =N5-K5 -> 4 | P5: 22 | Q5: =2*P5 -> 44 | R5: =P5 -> 22 | S5: =M5*GiaDinh!$C$7 -> 84.12348
A6: BÈ 1 | B6: B1-03 | C6: Dọc cạnh | D6: B1-D05a, B1-D05b, B1-D35a, B1-D35b | E6: 4 | F6: 85.7 | G6: =4*F6*GiaDinh!$C$18*GiaDinh!$C$17 -> 287.952 | H6: 12 | I6: =H6*GiaDinh!$C$16 -> 84 | J6: =MAX(1,ROUNDUP(G6/I6-0.0005,0)) -> 4 | K6: 4 | L6: =IF(K6>=J6,"ĐỦ","THIẾU") -> ĐỦ | M6: 60 | N6: =ROUNDUP(15/GiaDinh!$C$5-0.0005,0)+ROUNDUP(15/GiaDinh!$C$5-0.0005,0)+ROUNDUP(15/GiaDinh!$C$5-0.0005,0)+ROUNDUP(15/GiaDinh!$C$5-0.0005,0) -> 12 | O6: =N6-K6 -> 8 | P6: 48 | Q6: =2*P6 -> 96 | R6: =P6 -> 48 | S6: =M6*GiaDinh!$C$7 -> 180.6
A7: BÈ 1 | B7: B1-04 | C7: Dọc cạnh | D7: B1-D22a, B1-D22b | E7: 2 | F7: 85.7 | G7: =2*F7*GiaDinh!$C$18*GiaDinh!$C$17 -> 143.976 | H7: 12 | I7: =H7*GiaDinh!$C$16 -> 84 | J7: =MAX(1,ROUNDUP(G7/I7-0.0005,0)) -> 2 | K7: 2 | L7: =IF(K7>=J7,"ĐỦ","THIẾU") -> ĐỦ | M7: 30 | N7: =ROUNDUP(15/GiaDinh!$C$5-0.0005,0)+ROUNDUP(15/GiaDinh!$C$5-0.0005,0) -> 6 | O7: =N7-K7 -> 4 | P7: 24 | Q7: =2*P7 -> 48 | R7: =P7 -> 24 | S7: =M7*GiaDinh!$C$7 -> 90.3
A8: BÈ 1 | B8: B1-05 | C8: Dọc cạnh | D8: B1-D09a, B1-D09b, B1-D41a, B1-D41b | E8: 4 | F8: 85.7 | G8: =4*F8*GiaDinh!$C$18*GiaDinh!$C$17 -> 287.952 | H8: 12 | I8: =H8*GiaDinh!$C$16 -> 84 | J8: =MAX(1,ROUNDUP(G8/I8-0.0005,0)) -> 4 | K8: 4 | L8: =IF(K8>=J8,"ĐỦ","THIẾU") -> ĐỦ | M8: 60 | N8: =ROUNDUP(15/GiaDinh!$C$5-0.0005,0)+ROUNDUP(15/GiaDinh!$C$5-0.0005,0)+ROUNDUP(15/GiaDinh!$C$5-0.0005,0)+ROUNDUP(15/GiaDinh!$C$5-0.0005,0) -> 12 | O8: =N8-K8 -> 8 | P8: 48 | Q8: =2*P8 -> 96 | R8: =P8 -> 48 | S8: =M8*GiaDinh!$C$7 -> 180.6
A9: BÈ 1 | B9: B1-06 | C9: Dọc cạnh | D9: B1-D27b, B1-D27a, B1-D42b, B1-D42a | E9: 4 | F9: 85.7 | G9: =4*F9*GiaDinh!$C$18*GiaDinh!$C$17 -> 287.952 | H9: 12 | I9: =H9*GiaDinh!$C$16 -> 84 | J9: =MAX(1,ROUNDUP(G9/I9-0.0005,0)) -> 4 | K9: 4 | L9: =IF(K9>=J9,"ĐỦ","THIẾU") -> ĐỦ | M9: 60 | N9: =ROUNDUP(15/GiaDinh!$C$5-0.0005,0)+ROUNDUP(15/GiaDinh!$C$5-0.0005,0)+ROUNDUP(15/GiaDinh!$C$5-0.0005,0)+ROUNDUP(15/GiaDinh!$C$5-0.0005,0) -> 12 | O9: =N9-K9 -> 8 | P9: 48 | Q9: =2*P9 -> 96 | R9: =P9 -> 48 | S9: =M9*GiaDinh!$C$7 -> 180.6
A10: BÈ 1 | B10: B1-07 | C10: Dọc cạnh | D10: B1-D06b, B1-D06a, B1-D38b, B1-D38a | E10: 4 | F10: 85.7 | G10: =4*F10*GiaDinh!$C$18*GiaDinh!$C$17 -> 287.952 | H10: 12 | I10: =H10*GiaDinh!$C$16 -> 84 | J10: =MAX(1,ROUNDUP(G10/I10-0.0005,0)) -> 4 | K10: 4 | L10: =IF(K10>=J10,"ĐỦ","THIẾU") -> ĐỦ | M10: 60 | N10: =ROUNDUP(15/GiaDinh!$C$5-0.0005,0)+ROUNDUP(15/GiaDinh!$C$5-0.0005,0)+ROUNDUP(15/GiaDinh!$C$5-0.0005,0)+ROUNDUP(15/GiaDinh!$C$5-0.0005,0) -> 12 | O10: =N10-K10 -> 8 | P10: 48 | Q10: =2*P10 -> 96 | R10: =P10 -> 48 | S10: =M10*GiaDinh!$C$7 -> 180.6
A11: BÈ 1 | B11: B1-08 | C11: Dọc cạnh | D11: B1-D24b, B1-D24a | E11: 2 | F11: 85.7 | G11: =2*F11*GiaDinh!$C$18*GiaDinh!$C$17 -> 143.976 | H11: 11 | I11: =H11*GiaDinh!$C$16 -> 77 | J11: =MAX(1,ROUNDUP(G11/I11-0.0005,0)) -> 2 | K11: 2 | L11: =IF(K11>=J11,"ĐỦ","THIẾU") -> ĐỦ | M11: 30 | N11: =ROUNDUP(15/GiaDinh!$C$5-0.0005,0)+ROUNDUP(15/GiaDinh!$C$5-0.0005,0) -> 6 | O11: =N11-K11 -> 4 | P11: 22 | Q11: =2*P11 -> 44 | R11: =P11 -> 22 | S11: =M11*GiaDinh!$C$7 -> 90.3
A12: BÈ 1 | B12: B1-09 | C12: Dọc cạnh | D12: B1-D17a, B1-D17b, B1-D33a, B1-D33b | E12: 4 | F12: 85.7 | G12: =4*F12*GiaDinh!$C$18*GiaDinh!$C$17 -> 287.952 | H12: 12 | I12: =H12*GiaDinh!$C$16 -> 84 | J12: =MAX(1,ROUNDUP(G12/I12-0.0005,0)) -> 4 | K12: 4 | L12: =IF(K12>=J12,"ĐỦ","THIẾU") -> ĐỦ | M12: 60 | N12: =ROUNDUP(15/GiaDinh!$C$5-0.0005,0)+ROUNDUP(15/GiaDinh!$C$5-0.0005,0)+ROUNDUP(15/GiaDinh!$C$5-0.0005,0)+ROUNDUP(15/GiaDinh!$C$5-0.0005,0) -> 12 | O12: =N12-K12 -> 8 | P12: 48 | Q12: =2*P12 -> 96 | R12: =P12 -> 48 | S12: =M12*GiaDinh!$C$7 -> 180.6
A13: BÈ 1 | B13: B1-10 | C13: Dọc cạnh | D13: B1-D28a, B1-D28b | E13: 2 | F13: 85.7 | G13: =2*F13*GiaDinh!$C$18*GiaDinh!$C$17 -> 143.976 | H13: 12 | I13: =H13*GiaDinh!$C$16 -> 84 | J13: =MAX(1,ROUNDUP(G13/I13-0.0005,0)) -> 2 | K13: 2 | L13: =IF(K13>=J13,"ĐỦ","THIẾU") -> ĐỦ | M13: 30 | N13: =ROUNDUP(15/GiaDinh!$C$5-0.0005,0)+ROUNDUP(15/GiaDinh!$C$5-0.0005,0) -> 6 | O13: =N13-K13 -> 4 | P13: 24 | Q13: =2*P13 -> 48 | R13: =P13 -> 24 | S13: =M13*GiaDinh!$C$7 -> 90.3
A14: BÈ 1 | B14: B1-11 | C14: Dọc cạnh | D14: B1-D01b, B1-D01a | E14: 2 | F14: 85.7 | G14: =2*F14*GiaDinh!$C$18*GiaDinh!$C$17 -> 143.976 | H14: 13 | I14: =H14*GiaDinh!$C$16 -> 91 | J14: =MAX(1,ROUNDUP(G14/I14-0.0005,0)) -> 2 | K14: 2 | L14: =IF(K14>=J14,"ĐỦ","THIẾU") -> ĐỦ | M14: 30 | N14: =ROUNDUP(15/GiaDinh!$C$5-0.0005,0)+ROUNDUP(15/GiaDinh!$C$5-0.0005,0) -> 6 | O14: =N14-K14 -> 4 | P14: 26 | Q14: =2*P14 -> 52 | R14: =P14 -> 26 | S14: =M14*GiaDinh!$C$7 -> 90.3
A15: BÈ 1 | B15: B1-12 | C15: Vuông góc cạnh | D15: B1-D34a | E15: 1 | F15: 85.7 | G15: =1*F15*GiaDinh!$C$18*GiaDinh!$C$17 -> 71.988 | H15: 13 | I15: =H15*GiaDinh!$C$16 -> 91 | J15: =MAX(1,ROUNDUP(G15/I15-0.0005,0)) -> 1 | K15: 1 | L15: =IF(K15>=J15,"ĐỦ","THIẾU") -> ĐỦ | M15: 15 | N15: =ROUNDUP(15/GiaDinh!$C$5-0.0005,0) -> 3 | O15: =N15-K15 -> 2 | P15: 13 | Q15: =2*P15 -> 26 | R15: =P15 -> 13 | S15: =M15*GiaDinh!$C$7 -> 45.15
A16: BÈ 1 | B16: B1-13 | C16: Vuông góc cạnh | D16: B1-D34b | E16: 1 | F16: 85.7 | G16: =1*F16*GiaDinh!$C$18*GiaDinh!$C$17 -> 71.988 | H16: 13 | I16: =H16*GiaDinh!$C$16 -> 91 | J16: =MAX(1,ROUNDUP(G16/I16-0.0005,0)) -> 1 | K16: 1 | L16: =IF(K16>=J16,"ĐỦ","THIẾU") -> ĐỦ | M16: 15 | N16: =ROUNDUP(15/GiaDinh!$C$5-0.0005,0) -> 3 | O16: =N16-K16 -> 2 | P16: 13 | Q16: =2*P16 -> 26 | R16: =P16 -> 13 | S16: =M16*GiaDinh!$C$7 -> 45.15
A17: BÈ 1 | B17: B1-14 | C17: Vuông góc cạnh | D17: B1-D18a | E17: 1 | F17: 85.7 | G17: =1*F17*GiaDinh!$C$18*GiaDinh!$C$17 -> 71.988 | H17: 13 | I17: =H17*GiaDinh!$C$16 -> 91 | J17: =MAX(1,ROUNDUP(G17/I17-0.0005,0)) -> 1 | K17: 1 | L17: =IF(K17>=J17,"ĐỦ","THIẾU") -> ĐỦ | M17: 15 | N17: =ROUNDUP(15/GiaDinh!$C$5-0.0005,0) -> 3 | O17: =N17-K17 -> 2 | P17: 13 | Q17: =2*P17 -> 26 | R17: =P17 -> 13 | S17: =M17*GiaDinh!$C$7 -> 45.15
A18: BÈ 1 | B18: B1-15 | C18: Vuông góc cạnh | D18: B1-D18b | E18: 1 | F18: 85.7 | G18: =1*F18*GiaDinh!$C$18*GiaDinh!$C$17 -> 71.988 | H18: 13 | I18: =H18*GiaDinh!$C$16 -> 91 | J18: =MAX(1,ROUNDUP(G18/I18-0.0005,0)) -> 1 | K18: 1 | L18: =IF(K18>=J18,"ĐỦ","THIẾU") -> ĐỦ | M18: 15 | N18: =ROUNDUP(15/GiaDinh!$C$5-0.0005,0) -> 3 | O18: =N18-K18 -> 2 | P18: 13 | Q18: =2*P18 -> 26 | R18: =P18 -> 13 | S18: =M18*GiaDinh!$C$7 -> 45.15
A19: BÈ 1 | B19: B1-16 | C19: Vuông góc cạnh | D19: B1-D13b | E19: 1 | F19: 85.7 | G19: =1*F19*GiaDinh!$C$18*GiaDinh!$C$17 -> 71.988 | H19: 12 | I19: =H19*GiaDinh!$C$16 -> 84 | J19: =MAX(1,ROUNDUP(G19/I19-0.0005,0)) -> 1 | K19: 1 | L19: =IF(K19>=J19,"ĐỦ","THIẾU") -> ĐỦ | M19: 15 | N19: =ROUNDUP(15/GiaDinh!$C$5-0.0005,0) -> 3 | O19: =N19-K19 -> 2 | P19: 12 | Q19: =2*P19 -> 24 | R19: =P19 -> 12 | S19: =M19*GiaDinh!$C$7 -> 45.15
A20: BÈ 1 | B20: B1-17 | C20: Vuông góc cạnh | D20: B1-D13a | E20: 1 | F20: 85.7 | G20: =1*F20*GiaDinh!$C$18*GiaDinh!$C$17 -> 71.988 | H20: 12 | I20: =H20*GiaDinh!$C$16 -> 84 | J20: =MAX(1,ROUNDUP(G20/I20-0.0005,0)) -> 1 | K20: 1 | L20: =IF(K20>=J20,"ĐỦ","THIẾU") -> ĐỦ | M20: 15 | N20: =ROUNDUP(15/GiaDinh!$C$5-0.0005,0) -> 3 | O20: =N20-K20 -> 2 | P20: 12 | Q20: =2*P20 -> 24 | R20: =P20 -> 12 | S20: =M20*GiaDinh!$C$7 -> 45.15
A21: BÈ 1 | B21: B1-18 | C21: Vuông góc cạnh | D21: B1-D25b | E21: 1 | F21: 85.7 | G21: =1*F21*GiaDinh!$C$18*GiaDinh!$C$17 -> 71.988 | H21: 12 | I21: =H21*GiaDinh!$C$16 -> 84 | J21: =MAX(1,ROUNDUP(G21/I21-0.0005,0)) -> 1 | K21: 1 | L21: =IF(K21>=J21,"ĐỦ","THIẾU") -> ĐỦ | M21: 15 | N21: =ROUNDUP(15/GiaDinh!$C$5-0.0005,0) -> 3 | O21: =N21-K21 -> 2 | P21: 12 | Q21: =2*P21 -> 24 | R21: =P21 -> 12 | S21: =M21*GiaDinh!$C$7 -> 45.15
A22: BÈ 1 | B22: B1-19 | C22: Vuông góc cạnh | D22: B1-D25a | E22: 1 | F22: 85.7 | G22: =1*F22*GiaDinh!$C$18*GiaDinh!$C$17 -> 71.988 | H22: 12 | I22: =H22*GiaDinh!$C$16 -> 84 | J22: =MAX(1,ROUNDUP(G22/I22-0.0005,0)) -> 1 | K22: 1 | L22: =IF(K22>=J22,"ĐỦ","THIẾU") -> ĐỦ | M22: 15 | N22: =ROUNDUP(15/GiaDinh!$C$5-0.0005,0) -> 3 | O22: =N22-K22 -> 2 | P22: 12 | Q22: =2*P22 -> 24 | R22: =P22 -> 12 | S22: =M22*GiaDinh!$C$7 -> 45.15
A23: BÈ 1 | B23: B1-20 | C23: Vuông góc cạnh | D23: B1-D07b | E23: 1 | F23: 85.7 | G23: =1*F23*GiaDinh!$C$18*GiaDinh!$C$17 -> 71.988 | H23: 12 | I23: =H23*GiaDinh!$C$16 -> 84 | J23: =MAX(1,ROUNDUP(G23/I23-0.0005,0)) -> 1 | K23: 1 | L23: =IF(K23>=J23,"ĐỦ","THIẾU") -> ĐỦ | M23: 15 | N23: =ROUNDUP(15/GiaDinh!$C$5-0.0005,0) -> 3 | O23: =N23-K23 -> 2 | P23: 12 | Q23: =2*P23 -> 24 | R23: =P23 -> 12 | S23: =M23*GiaDinh!$C$7 -> 45.15
A24: BÈ 1 | B24: B1-21 | C24: Vuông góc cạnh | D24: B1-D07a | E24: 1 | F24: 85.7 | G24: =1*F24*GiaDinh!$C$18*GiaDinh!$C$17 -> 71.988 | H24: 12 | I24: =H24*GiaDinh!$C$16 -> 84 | J24: =MAX(1,ROUNDUP(G24/I24-0.0005,0)) -> 1 | K24: 1 | L24: =IF(K24>=J24,"ĐỦ","THIẾU") -> ĐỦ | M24: 15 | N24: =ROUNDUP(15/GiaDinh!$C$5-0.0005,0) -> 3 | O24: =N24-K24 -> 2 | P24: 12 | Q24: =2*P24 -> 24 | R24: =P24 -> 12 | S24: =M24*GiaDinh!$C$7 -> 45.15
A25: BÈ 1 | B25: B1-22 | C25: Vuông góc cạnh | D25: B1-D37b | E25: 1 | F25: 85.7 | G25: =1*F25*GiaDinh!$C$18*GiaDinh!$C$17 -> 71.988 | H25: 12 | I25: =H25*GiaDinh!$C$16 -> 84 | J25: =MAX(1,ROUNDUP(G25/I25-0.0005,0)) -> 1 | K25: 1 | L25: =IF(K25>=J25,"ĐỦ","THIẾU") -> ĐỦ | M25: 15 | N25: =ROUNDUP(15/GiaDinh!$C$5-0.0005,0) -> 3 | O25: =N25-K25 -> 2 | P25: 12 | Q25: =2*P25 -> 24 | R25: =P25 -> 12 | S25: =M25*GiaDinh!$C$7 -> 45.15
A26: BÈ 1 | B26: B1-23 | C26: Vuông góc cạnh | D26: B1-D37a | E26: 1 | F26: 85.7 | G26: =1*F26*GiaDinh!$C$18*GiaDinh!$C$17 -> 71.988 | H26: 12 | I26: =H26*GiaDinh!$C$16 -> 84 | J26: =MAX(1,ROUNDUP(G26/I26-0.0005,0)) -> 1 | K26: 1 | L26: =IF(K26>=J26,"ĐỦ","THIẾU") -> ĐỦ | M26: 15 | N26: =ROUNDUP(15/GiaDinh!$C$5-0.0005,0) -> 3 | O26: =N26-K26 -> 2 | P26: 12 | Q26: =2*P26 -> 24 | R26: =P26 -> 12 | S26: =M26*GiaDinh!$C$7 -> 45.15
... A43: BÈ 1 | B43: B1-40 | C43: Vuông góc cạnh | D43: B1-D10b | E43: 1 | F43: 85.7 | G43: =1*F43*GiaDinh!$C$18*GiaDinh!$C$17 -> 71.988 | H43: 12 | I43: =H43*GiaDinh!$C$16 -> 84 | J43: =MAX(1,ROUNDUP(G43/I43-0.0005,0)) -> 1 | K43: 1 | L43: =IF(K43>=J43,"ĐỦ","THIẾU") -> ĐỦ | M43: 15 | N43: =ROUNDUP(15/GiaDinh!$C$5-0.0005,0) -> 3 | O43: =N43-K43 -> 2 | P43: 12 | Q43: =2*P43 -> 24 | R43: =P43 -> 12 | S43: =M43*GiaDinh!$C$7 -> 45.15
A44: BÈ 1 | B44: B1-41 | C44: Vuông góc cạnh | D44: B1-D10a | E44: 1 | F44: 85.7 | G44: =1*F44*GiaDinh!$C$18*GiaDinh!$C$17 -> 71.988 | H44: 9 | I44: =H44*GiaDinh!$C$16 -> 63 | J44: =MAX(1,ROUNDUP(G44/I44-0.0005,0)) -> 2 | K44: 2 | L44: =IF(K44>=J44,"ĐỦ","THIẾU") -> ĐỦ | M44: 22.699 | N44: =ROUNDUP(11.35/GiaDinh!$C$5-0.0005,0)+ROUNDUP(11.35/GiaDinh!$C$5-0.0005,0) -> 4 | O44: =N44-K44 -> 2 | P44: 18 | Q44: =2*P44 -> 36 | R44: =P44 -> 18 | S44: =M44*GiaDinh!$C$7 -> 68.32399
A45: BÈ 1 | B45: B1-42 | C45: Vuông góc cạnh | D45: B1-D36b | E45: 1 | F45: 85.7 | G45: =1*F45*GiaDinh!$C$18*GiaDinh!$C$17 -> 71.988 | H45: 12 | I45: =H45*GiaDinh!$C$16 -> 84 | J45: =MAX(1,ROUNDUP(G45/I45-0.0005,0)) -> 1 | K45: 1 | L45: =IF(K45>=J45,"ĐỦ","THIẾU") -> ĐỦ | M45: 15 | N45: =ROUNDUP(15/GiaDinh!$C$5-0.0005,0) -> 3 | O45: =N45-K45 -> 2 | P45: 12 | Q45: =2*P45 -> 24 | R45: =P45 -> 12 | S45: =M45*GiaDinh!$C$7 -> 45.15
A46: BÈ 1 | B46: B1-43 | C46: Vuông góc cạnh | D46: B1-D36a | E46: 1 | F46: 85.7 | G46: =1*F46*GiaDinh!$C$18*GiaDinh!$C$17 -> 71.988 | H46: 12 | I46: =H46*GiaDinh!$C$16 -> 84 | J46: =MAX(1,ROUNDUP(G46/I46-0.0005,0)) -> 1 | K46: 1 | L46: =IF(K46>=J46,"ĐỦ","THIẾU") -> ĐỦ | M46: 15 | N46: =ROUNDUP(15/GiaDinh!$C$5-0.0005,0) -> 3 | O46: =N46-K46 -> 2 | P46: 12 | Q46: =2*P46 -> 24 | R46: =P46 -> 12 | S46: =M46*GiaDinh!$C$7 -> 45.15
A47: BÈ 1 | B47: B1-44 | C47: Vuông góc cạnh | D47: B1-D21b | E47: 1 | F47: 85.7 | G47: =1*F47*GiaDinh!$C$18*GiaDinh!$C$17 -> 71.988 | H47: 12 | I47: =H47*GiaDinh!$C$16 -> 84 | J47: =MAX(1,ROUNDUP(G47/I47-0.0005,0)) -> 1 | K47: 1 | L47: =IF(K47>=J47,"ĐỦ","THIẾU") -> ĐỦ | M47: 15 | N47: =ROUNDUP(15/GiaDinh!$C$5-0.0005,0) -> 3 | O47: =N47-K47 -> 2 | P47: 12 | Q47: =2*P47 -> 24 | R47: =P47 -> 12 | S47: =M47*GiaDinh!$C$7 -> 45.15
A48: BÈ 1 | B48: B1-45 | C48: Vuông góc cạnh | D48: B1-D21a | E48: 1 | F48: 85.7 | G48: =1*F48*GiaDinh!$C$18*GiaDinh!$C$17 -> 71.988 | H48: 12 | I48: =H48*GiaDinh!$C$16 -> 84 | J48: =MAX(1,ROUNDUP(G48/I48-0.0005,0)) -> 1 | K48: 1 | L48: =IF(K48>=J48,"ĐỦ","THIẾU") -> ĐỦ | M48: 15 | N48: =ROUNDUP(15/GiaDinh!$C$5-0.0005,0) -> 3 | O48: =N48-K48 -> 2 | P48: 12 | Q48: =2*P48 -> 24 | R48: =P48 -> 12 | S48: =M48*GiaDinh!$C$7 -> 45.15
A49: BÈ 1 | B49: B1-46 | C49: Vuông góc cạnh | D49: B1-D11a | E49: 1 | F49: 85.7 | G49: =1*F49*GiaDinh!$C$18*GiaDinh!$C$17 -> 71.988 | H49: 9 | I49: =H49*GiaDinh!$C$16 -> 63 | J49: =MAX(1,ROUNDUP(G49/I49-0.0005,0)) -> 2 | K49: 2 | L49: =IF(K49>=J49,"ĐỦ","THIẾU") -> ĐỦ | M49: 21.987 | N49: =ROUNDUP(10.994/GiaDinh!$C$5-0.0005,0)+ROUNDUP(10.994/GiaDinh!$C$5-0.0005,0) -> 4 | O49: =N49-K49 -> 2 | P49: 18 | Q49: =2*P49 -> 36 | R49: =P49 -> 18 | S49: =M49*GiaDinh!$C$7 -> 66.18087
A50: BÈ 1 | B50: B1-47 | C50: Vuông góc cạnh | D50: B1-D11b | E50: 1 | F50: 85.7 | G50: =1*F50*GiaDinh!$C$18*GiaDinh!$C$17 -> 71.988 | H50: 13 | I50: =H50*GiaDinh!$C$16 -> 91 | J50: =MAX(1,ROUNDUP(G50/I50-0.0005,0)) -> 1 | K50: 1 | L50: =IF(K50>=J50,"ĐỦ","THIẾU") -> ĐỦ | M50: 15 | N50: =ROUNDUP(15/GiaDinh!$C$5-0.0005,0) -> 3 | O50: =N50-K50 -> 2 | P50: 13 | Q50: =2*P50 -> 26 | R50: =P50 -> 13 | S50: =M50*GiaDinh!$C$7 -> 45.15
A51: BÈ 1 | B51: B1-48 | C51: Vuông góc cạnh | D51: B1-D04a | E51: 1 | F51: 85.7 | G51: =1*F51*GiaDinh!$C$18*GiaDinh!$C$17 -> 71.988 | H51: 12 | I51: =H51*GiaDinh!$C$16 -> 84 | J51: =MAX(1,ROUNDUP(G51/I51-0.0005,0)) -> 1 | K51: 1 | L51: =IF(K51>=J51,"ĐỦ","THIẾU") -> ĐỦ | M51: 15 | N51: =ROUNDUP(15/GiaDinh!$C$5-0.0005,0) -> 3 | O51: =N51-K51 -> 2 | P51: 12 | Q51: =2*P51 -> 24 | R51: =P51 -> 12 | S51: =M51*GiaDinh!$C$7 -> 45.15
A52: BÈ 1 | B52: B1-49 | C52: Vuông góc cạnh | D52: B1-D04b | E52: 1 | F52: 85.7 | G52: =1*F52*GiaDinh!$C$18*GiaDinh!$C$17 -> 71.988 | H52: 12 | I52: =H52*GiaDinh!$C$16 -> 84 | J52: =MAX(1,ROUNDUP(G52/I52-0.0005,0)) -> 1 | K52: 1 | L52: =IF(K52>=J52,"ĐỦ","THIẾU") -> ĐỦ | M52: 15 | N52: =ROUNDUP(15/GiaDinh!$C$5-0.0005,0) -> 3 | O52: =N52-K52 -> 2 | P52: 12 | Q52: =2*P52 -> 24 | R52: =P52 -> 12 | S52: =M52*GiaDinh!$C$7 -> 45.15
A53: BÈ 1 | B53: B1-50 | C53: Vuông góc cạnh | D53: B1-D14a | E53: 1 | F53: 85.7 | G53: =1*F53*GiaDinh!$C$18*GiaDinh!$C$17 -> 71.988 | H53: 12 | I53: =H53*GiaDinh!$C$16 -> 84 | J53: =MAX(1,ROUNDUP(G53/I53-0.0005,0)) -> 1 | K53: 1 | L53: =IF(K53>=J53,"ĐỦ","THIẾU") -> ĐỦ | M53: 15 | N53: =ROUNDUP(15/GiaDinh!$C$5-0.0005,0) -> 3 | O53: =N53-K53 -> 2 | P53: 12 | Q53: =2*P53 -> 24 | R53: =P53 -> 12 | S53: =M53*GiaDinh!$C$7 -> 45.15
A54: BÈ 1 | B54: B1-51 | C54: Vuông góc cạnh | D54: B1-D14b | E54: 1 | F54: 85.7 | G54: =1*F54*GiaDinh!$C$18*GiaDinh!$C$17 -> 71.988 | H54: 12 | I54: =H54*GiaDinh!$C$16 -> 84 | J54: =MAX(1,ROUNDUP(G54/I54-0.0005,0)) -> 1 | K54: 1 | L54: =IF(K54>=J54,"ĐỦ","THIẾU") -> ĐỦ | M54: 15 | N54: =ROUNDUP(15/GiaDinh!$C$5-0.0005,0) -> 3 | O54: =N54-K54 -> 2 | P54: 12 | Q54: =2*P54 -> 24 | R54: =P54 -> 12 | S54: =M54*GiaDinh!$C$7 -> 45.15
A55: BÈ 1 | B55: B1-52 | C55: Vuông góc cạnh | D55: B1-D39a | E55: 1 | F55: 85.7 | G55: =1*F55*GiaDinh!$C$18*GiaDinh!$C$17 -> 71.988 | H55: 12 | I55: =H55*GiaDinh!$C$16 -> 84 | J55: =MAX(1,ROUNDUP(G55/I55-0.0005,0)) -> 1 | K55: 1 | L55: =IF(K55>=J55,"ĐỦ","THIẾU") -> ĐỦ | M55: 15 | N55: =ROUNDUP(15/GiaDinh!$C$5-0.0005,0) -> 3 | O55: =N55-K55 -> 2 | P55: 12 | Q55: =2*P55 -> 24 | R55: =P55 -> 12 | S55: =M55*GiaDinh!$C$7 -> 45.15
A56: BÈ 1 | B56: B1-53 | C56: Vuông góc cạnh | D56: B1-D39b | E56: 1 | F56: 85.7 | G56: =1*F56*GiaDinh!$C$18*GiaDinh!$C$17 -> 71.988 | H56: 12 | I56: =H56*GiaDinh!$C$16 -> 84 | J56: =MAX(1,ROUNDUP(G56/I56-0.0005,0)) -> 1 | K56: 1 | L56: =IF(K56>=J56,"ĐỦ","THIẾU") -> ĐỦ | M56: 15 | N56: =ROUNDUP(15/GiaDinh!$C$5-0.0005,0) -> 3 | O56: =N56-K56 -> 2 | P56: 12 | Q56: =2*P56 -> 24 | R56: =P56 -> 12 | S56: =M56*GiaDinh!$C$7 -> 45.15
...

Sheet C52_TungThanh
A1: DẦM C52 — TỪNG THANH ĐO TRÊN BẢN VẼ CAD "CT-KC-BE-01…06" (khung bao của từng thanh Revit, m)
A3: Bè | B3: STT | C3: Chiều dài thanh (m) | D3: Số cây cấp hàng = ROUNDUP(L / L_C52) | E3: Số mối nối = số cây − 1
A4: BÈ 1 | B4: 1 | C4: 25.349 | D4: =ROUNDUP(C4/GiaDinh!$C$4-0.0005,0) -> 5 | E4: =D4-1 -> 4
A5: BÈ 1 | B5: 2 | C5: 25.349 | D5: =ROUNDUP(C5/GiaDinh!$C$4-0.0005,0) -> 5 | E5: =D5-1 -> 4
A6: BÈ 1 | B6: 3 | C6: 25.349 | D6: =ROUNDUP(C6/GiaDinh!$C$4-0.0005,0) -> 5 | E6: =D6-1 -> 4
A7: BÈ 1 | B7: 4 | C7: 25.349 | D7: =ROUNDUP(C7/GiaDinh!$C$4-0.0005,0) -> 5 | E7: =D7-1 -> 4
A8: BÈ 1 | B8: 5 | C8: 25.349 | D8: =ROUNDUP(C8/GiaDinh!$C$4-0.0005,0) -> 5 | E8: =D8-1 -> 4
A9: BÈ 1 | B9: 6 | C9: 25.349 | D9: =ROUNDUP(C9/GiaDinh!$C$4-0.0005,0) -> 5 | E9: =D9-1 -> 4
A10: BÈ 1 | B10: 7 | C10: 25.349 | D10: =ROUNDUP(C10/GiaDinh!$C$4-0.0005,0) -> 5 | E10: =D10-1 -> 4
A11: BÈ 1 | B11: 8 | C11: 25.349 | D11: =ROUNDUP(C11/GiaDinh!$C$4-0.0005,0) -> 5 | E11: =D11-1 -> 4
A12: BÈ 1 | B12: 9 | C12: 25.349 | D12: =ROUNDUP(C12/GiaDinh!$C$4-0.0005,0) -> 5 | E12: =D12-1 -> 4
A13: BÈ 1 | B13: 10 | C13: 25.349 | D13: =ROUNDUP(C13/GiaDinh!$C$4-0.0005,0) -> 5 | E13: =D13-1 -> 4
A14: BÈ 1 | B14: 11 | C14: 25.349 | D14: =ROUNDUP(C14/GiaDinh!$C$4-0.0005,0) -> 5 | E14: =D14-1 -> 4
A15: BÈ 1 | B15: 12 | C15: 25.349 | D15: =ROUNDUP(C15/GiaDinh!$C$4-0.0005,0) -> 5 | E15: =D15-1 -> 4
... A767: BÈ 6 | B767: 236 | C767: 79.227 | D767: =ROUNDUP(C767/GiaDinh!$C$4-0.0005,0) -> 14 | E767: =D767-1 -> 13

Sheet Hop40x60_TungThanh
A1: HỘP 40x60 KẾT CẤU — TỪNG THANH ĐO TRÊN BẢN VẼ CAD "CT-KC-BE-01…06" (khung bao của từng thanh Revit, m)
A3: Bè | B3: STT | C3: Chiều dài thanh (m) | D3: Số cây cấp hàng = ROUNDUP(L / L_H) | E3: Số mối nối = số cây − 1
A4: BÈ 1 | B4: 1 | C4: 34.698 | D4: =ROUNDUP(C4/GiaDinh!$C$5-0.0005,0) -> 6 | E4: =D4-1 -> 5
A5: BÈ 1 | B5: 2 | C5: 35.762 | D5: =ROUNDUP(C5/GiaDinh!$C$5-0.0005,0) -> 6 | E5: =D5-1 -> 5
A6: BÈ 1 | B6: 3 | C6: 74.345 | D6: =ROUNDUP(C6/GiaDinh!$C$5-0.0005,0) -> 13 | E6: =D6-1 -> 12
A7: BÈ 1 | B7: 4 | C7: 74.345 | D7: =ROUNDUP(C7/GiaDinh!$C$5-0.0005,0) -> 13 | E7: =D7-1 -> 12
A8: BÈ 1 | B8: 5 | C8: 74.345 | D8: =ROUNDUP(C8/GiaDinh!$C$5-0.0005,0) -> 13 | E8: =D8-1 -> 12
A9: BÈ 1 | B9: 6 | C9: 74.345 | D9: =ROUNDUP(C9/GiaDinh!$C$5-0.0005,0) -> 13 | E9: =D9-1 -> 12
A10: BÈ 1 | B10: 7 | C10: 75.409 | D10: =ROUNDUP(C10/GiaDinh!$C$5-0.0005,0) -> 13 | E10: =D10-1 -> 12
A11: BÈ 1 | B11: 8 | C11: 75.409 | D11: =ROUNDUP(C11/GiaDinh!$C$5-0.0005,0) -> 13 | E11: =D11-1 -> 12
A12: BÈ 1 | B12: 9 | C12: 75.409 | D12: =ROUNDUP(C12/GiaDinh!$C$5-0.0005,0) -> 13 | E12: =D12-1 -> 12
A13: BÈ 1 | B13: 10 | C13: 75.409 | D13: =ROUNDUP(C13/GiaDinh!$C$5-0.0005,0) -> 13 | E13: =D13-1 -> 12
A14: BÈ 1 | B14: 11 | C14: 75.714 | D14: =ROUNDUP(C14/GiaDinh!$C$5-0.0005,0) -> 13 | E14: =D14-1 -> 12
A15: BÈ 1 | B15: 12 | C15: 75.714 | D15: =ROUNDUP(C15/GiaDinh!$C$5-0.0005,0) -> 13 | E15: =D15-1 -> 12
... A154: BÈ 6 | B154: 16 | C154: 291.782 | D154: =ROUNDUP(C154/GiaDinh!$C$5-0.0005,0) -> 49 | E154: =D154-1 -> 48

Sheet DoiChieu_KhungThep
A1: ĐỐI CHIẾU BẢNG "THỐNG KÊ KHUNG THÉP" TRÊN TỜ CT-KC-BE-01…06 VỚI KHUNG VẼ TRONG CHÍNH TỜ ĐÓ (đếm và đo từng thanh)
A3: Bè | B3: Hạng mục | C3: Số thanh — bảng | D3: Số thanh — CAD | E3: Lệch | F3: Chiều dài — bảng (m) | G3: Chiều dài — CAD (m) | H3: Lệch (m) | I3: Kết luận
A4: BÈ 1 | B4: Dầm C52 | C4: =DuLieuBanVe!C18 -> 100 | D4: =DuLieuBanVe!C14 -> 100 | E4: =D4-C4 -> 0 | F4: =DuLieuBanVe!C19 -> 12652.9 | G4: =DuLieuBanVe!C15 -> 12652.92 | H4: =G4-F4 -> 0.02 | I4: =IF(AND(E4=0,ABS(H4)<=0.05),"KHỚP",IF(AND(E4=0,ABS(H4)<=0.01*F4),"KHỚP (lệch nhỏ)","KHÔNG KHỚP bảng tờ — lấy theo bản vẽ CAD")) -> KHỚP
A5: BÈ 1 | B5: Hộp 40x60 | C5: =DuLieuBanVe!C20 -> 38 | D5: =DuLieuBanVe!C16 -> 38 | E5: =D5-C5 -> 0 | F5: =DuLieuBanVe!C21 -> 2986.38 | G5: =DuLieuBanVe!C17 -> 2986.38 | H5: =G5-F5 -> 0 | I5: =IF(AND(E5=0,ABS(H5)<=0.05),"KHỚP",IF(AND(E5=0,ABS(H5)<=0.01*F5),"KHỚP (lệch nhỏ)","KHÔNG KHỚP bảng tờ — lấy theo bản vẽ CAD")) -> KHỚP
A6: BÈ 2 | B6: Dầm C52 | C6: =DuLieuBanVe!D18 -> 244 | D6: =DuLieuBanVe!D14 -> 244 | E6: =D6-C6 -> 0 | F6: =DuLieuBanVe!D19 -> 17906.84 | G6: =DuLieuBanVe!D15 -> 17906.83 | H6: =G6-F6 -> -0.01 | I6: =IF(AND(E6=0,ABS(H6)<=0.05),"KHỚP",IF(AND(E6=0,ABS(H6)<=0.01*F6),"KHỚP (lệch nhỏ)","KHÔNG KHỚP bảng tờ — lấy theo bản vẽ CAD")) -> KHỚP
A7: BÈ 2 | B7: Hộp 40x60 | C7: =DuLieuBanVe!D20 -> 20 | D7: =DuLieuBanVe!D16 -> 20 | E7: =D7-C7 -> 0 | F7: =DuLieuBanVe!D21 -> 4449.15 | G7: =DuLieuBanVe!D17 -> 4449.14 | H7: =G7-F7 -> -0.01 | I7: =IF(AND(E7=0,ABS(H7)<=0.05),"KHỚP",IF(AND(E7=0,ABS(H7)<=0.01*F7),"KHỚP (lệch nhỏ)","KHÔNG KHỚP bảng tờ — lấy theo bản vẽ CAD")) -> KHỚP
A8: BÈ 3 | B8: Dầm C52 | C8: =DuLieuBanVe!E18 -> 32 | D8: =DuLieuBanVe!E14 -> 32 | E8: =D8-C8 -> 0 | F8: =DuLieuBanVe!E19 -> 3236.01 | G8: =DuLieuBanVe!E15 -> 3236 | H8: =G8-F8 -> -0.01 | I8: =IF(AND(E8=0,ABS(H8)<=0.05),"KHỚP",IF(AND(E8=0,ABS(H8)<=0.01*F8),"KHỚP (lệch nhỏ)","KHÔNG KHỚP bảng tờ — lấy theo bản vẽ CAD")) -> KHỚP
A9: BÈ 3 | B9: Hộp 40x60 | C9: =DuLieuBanVe!E20 -> 18 | D9: =DuLieuBanVe!E16 -> 18 | E9: =D9-C9 -> 0 | F9: =DuLieuBanVe!E21 -> 705.69 | G9: =DuLieuBanVe!E17 -> 705.69 | H9: =G9-F9 -> 0 | I9: =IF(AND(E9=0,ABS(H9)<=0.05),"KHỚP",IF(AND(E9=0,ABS(H9)<=0.01*F9),"KHỚP (lệch nhỏ)","KHÔNG KHỚP bảng tờ — lấy theo bản vẽ CAD")) -> KHỚP
A10: BÈ 4 | B10: Dầm C52 | C10: =DuLieuBanVe!F18 -> 60 | D10: =DuLieuBanVe!F14 -> 60 | E10: =D10-C10 -> 0 | F10: =DuLieuBanVe!F19 -> 9165.79 | G10: =DuLieuBanVe!F15 -> 9165.8 | H10: =G10-F10 -> 0.01 | I10: =IF(AND(E10=0,ABS(H10)<=0.05),"KHỚP",IF(AND(E10=0,ABS(H10)<=0.01*F10),"KHỚP (lệch nhỏ)","KHÔNG KHỚP bảng tờ — lấy theo bản vẽ CAD")) -> KHỚP
A11: BÈ 4 | B11: Hộp 40x60 | C11: =DuLieuBanVe!F20 -> 32 | D11: =DuLieuBanVe!F16 -> 32 | E11: =D11-C11 -> 0 | F11: =DuLieuBanVe!F21 -> 2072.02 | G11: =DuLieuBanVe!F17 -> 2072.01 | H11: =G11-F11 -> -0.01 | I11: =IF(AND(E11=0,ABS(H11)<=0.05),"KHỚP",IF(AND(E11=0,ABS(H11)<=0.01*F11),"KHỚP (lệch nhỏ)","KHÔNG KHỚP bảng tờ — lấy theo bản vẽ CAD")) -> KHỚP
A12: BÈ 5 | B12: Dầm C52 | C12: =DuLieuBanVe!G18 -> 92 | D12: =DuLieuBanVe!G14 -> 92 | E12: =D12-C12 -> 0 | F12: =DuLieuBanVe!G19 -> 12388.18 | G12: =DuLieuBanVe!G15 -> 12388.2 | H12: =G12-F12 -> 0.02 | I12: =IF(AND(E12=0,ABS(H12)<=0.05),"KHỚP",IF(AND(E12=0,ABS(H12)<=0.01*F12),"KHỚP (lệch nhỏ)","KHÔNG KHỚP bảng tờ — lấy theo bản vẽ CAD")) -> KHỚP
A13: BÈ 5 | B13: Hộp 40x60 | C13: =DuLieuBanVe!G20 -> 27 | D13: =DuLieuBanVe!G16 -> 27 | E13: =D13-C13 -> 0 | F13: =DuLieuBanVe!G21 -> 2741.95 | G13: =DuLieuBanVe!G17 -> 2741.94 | H13: =G13-F13 -> -0.01 | I13: =IF(AND(E13=0,ABS(H13)<=0.05),"KHỚP",IF(AND(E13=0,ABS(H13)<=0.01*F13),"KHỚP (lệch nhỏ)","KHÔNG KHỚP bảng tờ — lấy theo bản vẽ CAD")) -> KHỚP
A14: BÈ 6 | B14: Dầm C52 | C14: =DuLieuBanVe!H18 -> 236 | D14: =DuLieuBanVe!H14 -> 236 | E14: =D14-C14 -> 0 | F14: =DuLieuBanVe!H19 -> 17963.45 | G14: =DuLieuBanVe!H15 -> 17963.53 | H14: =G14-F14 -> 0.08 | I14: =IF(AND(E14=0,ABS(H14)<=0.05),"KHỚP",IF(AND(E14=0,ABS(H14)<=0.01*F14),"KHỚP (lệch nhỏ)","KHÔNG KHỚP bảng tờ — lấy theo bản vẽ CAD")) -> KHỚP (lệch nhỏ)
A15: BÈ 6 | B15: Hộp 40x60 | C15: =DuLieuBanVe!H20 -> 16 | D15: =DuLieuBanVe!H16 -> 16 | E15: =D15-C15 -> 0 | F15: =DuLieuBanVe!H21 -> 4254.11 | G15: =DuLieuBanVe!H17 -> 4254.11 | H15: =G15-F15 -> 0 | I15: =IF(AND(E15=0,ABS(H15)<=0.05),"KHỚP",IF(AND(E15=0,ABS(H15)<=0.01*F15),"KHỚP (lệch nhỏ)","KHÔNG KHỚP bảng tờ — lấy theo bản vẽ CAD")) -> KHỚP

Sheet DoiChieu_MatBang
A1: ĐỐI CHIẾU TỜ CT-BP VÀ KHUNG CT-KC-BE (30/10/2026) VỚI MẶT BẰNG BÈ MÀ WEB DÙNG TÍNH NEO (bản vẽ CAD bố trí bè 30/10/2026)
A2: Diện tích tờ CT-BP đo trên ảnh tờ (tỷ lệ in trên tờ, gồm cả mép phao); diện tích khung = phần phủ của dầm C52, hộp 40x60 và dải phao trên bản vẽ khung. Bản vẽ khung là mặt bằng neo xoay quanh gốc tọa độ: góc xoay và độ lệch khi khớp đường bao vào mép dải phao.
A3: Bè | B3: Diện tích khung CAD (m²) | C3: Diện tích trên web (m²) | D3: Lệch diện tích | E3: Tấm pin (tờ CT-BP = web) | F3: Dầm C52 TB 1 thanh (m) | G3: Hộp 40x60 TB 1 thanh (m) | H3: Góc xoay khung (°) | I3: Lệch khớp TB (m) | J3: Số dây neo | K3: Diện tích tờ CT-BP (m²)
A4: BÈ 1 | B4: 15820 | C4: 15185 | D4: =B4/C4-1 -> 0.041817583 | E4: 2912 | F4: =DuLieuBanVe!C15/DuLieuBanVe!C14 -> 126.5292 | G4: =DuLieuBanVe!C17/DuLieuBanVe!C16 -> 78.588947 | H4: 105 | I4: 0.81 | J4: 43 | K4: 15845
A5: BÈ 2 | B5: 22358 | C5: 21836 | D5: =B5/C5-1 -> 0.023905477 | E5: 4200 | F5: =DuLieuBanVe!D15/DuLieuBanVe!D14 -> 73.388648 | G5: =DuLieuBanVe!D17/DuLieuBanVe!D16 -> 222.457 | H5: 15 | I5: 0.39 | J5: 52 | K5: 22397
A6: BÈ 3 | B6: 3958 | C6: 3714 | D6: =B6/C6-1 -> 0.065697361 | E6: 700 | F6: =DuLieuBanVe!E15/DuLieuBanVe!E14 -> 101.125 | G6: =DuLieuBanVe!E17/DuLieuBanVe!E16 -> 39.205 | H6: 94 | I6: 0.76 | J6: 19 | K6: 3966
A7: BÈ 4 | B7: 11375 | C7: 10912 | D7: =B7/C7-1 -> 0.042430352 | E7: 2100 | F7: =DuLieuBanVe!F15/DuLieuBanVe!F14 -> 152.76333 | G7: =DuLieuBanVe!F17/DuLieuBanVe!F16 -> 64.750313 | H7: 84.9 | I7: 0.82 | J7: 30 | K7: 11434
A8: BÈ 5 | B8: 15129 | C8: 14633 | D8: =B8/C8-1 -> 0.033895989 | E8: 2800 | F8: =DuLieuBanVe!G15/DuLieuBanVe!G14 -> 134.65435 | G8: =DuLieuBanVe!G17/DuLieuBanVe!G16 -> 101.55333 | H8: 60.3 | I8: 0.82 | J8: 37 | K8: 15352
A9: BÈ 6 | B9: 22200 | C9: 21763 | D9: =B9/C9-1 -> 0.020079952 | E9: 4200 | F9: =DuLieuBanVe!H15/DuLieuBanVe!H14 -> 76.116653 | G9: =DuLieuBanVe!H17/DuLieuBanVe!H16 -> 265.88187 | H9: 35 | I9: 0.32 | J9: 50 | K9: 22263
A10: TỔNG | B10: =SUM(B4:B9) -> 90840 | C10: =SUM(C4:C9) -> 88043 | D10: =B10/C10-1 -> 0.031768568 | E10: =SUM(E4:E9) -> 16912 | J10: =SUM(J4:J9) -> 231 | K10: =SUM(K4:K9) -> 91257

Sheet GiaDinh
A1: THÔNG SỐ GIẢ ĐỊNH — ô tô vàng là ô NHẬP, sửa là cả file tự tính lại (bản vẽ gia cường vẽ theo giá trị mặc định)
A3: Mã | B3: Thông số | C3: Giá trị | D3: Đơn vị | E3: Ghi chú
A4: L_C52 | B4: Chiều dài cây dầm C52 khi cấp hàng | C4: 6 | D4: m | E4: GIẢ ĐỊNH. HD lắp Mibet G5 dùng đoạn L2990 / L3750 — nếu cấp đoạn ~3 m thì số mối nối gần gấp đôi
A5: L_H | B5: Chiều dài cây hộp 40x60 | C5: 6 | D5: m | E5: GIẢ ĐỊNH, cây thép hộp thương mại 6 m
A6: M_C52 | B6: Khối lượng dầm C52 | C6: 2.36 | D6: kg/m | E6: GIẢ ĐỊNH tiết diện C 52×41×12×2,0 (chưa có catalogue nhà sản xuất)
A7: M_H | B7: Khối lượng hộp 40x60 | C7: 3.01 | D7: kg/m | E7: GIẢ ĐỊNH 40×60×2,0
A8: K_FS | B8: Gá trước (Front Support) mỗi tấm pin | C8: 2 | D8: cái/tấm | E8: ƯỚC LƯỢNG theo HD lắp G5
A9: K_BS | B9: Gá sau (Back Support) mỗi tấm pin | C9: 2 | D9: cái/tấm | E9: ƯỚC LƯỢNG
A10: K_EC | B10: Bộ kẹp biên tấm pin (End Clamp Kit) mỗi tấm | C10: 2 | D10: bộ/tấm | E10: ƯỚC LƯỢNG
A11: K_GC | B11: Bộ kẹp tiếp địa mỗi tấm | C11: 2 | D11: bộ/tấm | E11: ƯỚC LƯỢNG; hỏi Mibet: kẹp biên/kẹp giữa có răng tiếp địa thì bỏ được hạng mục này, hoặc 1 bộ/tấm
A12: K_RN8 | B12: Bộ đai ốc thoi M8×25 bắt gá vào C52 | C12: 4 | D12: bộ/tấm | E12: ƯỚC LƯỢNG = 1 bộ mỗi gá
A13: K_FB | B13: Bộ bulông nhựa nối phao | C13: 2 | D13: bộ/phao | E13: ƯỚC LƯỢNG (HD: các phao nối với nhau bằng bulông + đai ốc nhựa)
A14: HH | B14: Hao hụt phụ kiện, bulông | C14: 3 | D14: % | E14: GIẢ ĐỊNH, chỉ cộng ở cột "Tổng có hao hụt"
A15: L_GC | B15: Chiều dài 1 thanh hộp 40x60 gia cường tai neo | C15: 15 | D15: m | E15: Như Huổi Vanh (bản vẽ gia cường bè 1 Huổi Vanh 9 bè: 13,4–15,5 m)
A16: P_KEP | B16: Sức chịu 1 móc "几" (2 đai ốc thoi M10×30 trong rãnh C52) | C16: 7 | D16: kN | E16: GIẢ ĐỊNH — chưa có số liệu nhà sản xuất; quyết định số thanh xếp song song ở cụm chịu lực lớn. Bản vẽ vẽ số thanh theo giá trị mặc định này
A17: GAMMA | B17: Hệ số tải trọng cho lực dây | C17: 1.2 | E17: Như kiểm tra cọc (pileBendingLoadFactor)
A18: K_Y | B18: Phần lực dây vào MỘT bích (cáp 2 nhánh chữ Y) | C18: 0.7 | D18: × T | E18: Chia đều ở góc 60°: 0,58 T; lấy 0,7 T vì 2 nhánh có thể dài lệch nhau (cùng giả định với bảng vật tư neo, sheet KiemTra_Nhanh)
A19: K_XF | B19: Số chỗ dầm C52 vượt qua một hàng phao, trên 1 m dầm | C19: 0.5 | D19: điểm/m | E19: ĐO trên bản vẽ CAD khung: hàng phao đỡ pin cách nhau ~2,0 m
A20: B_C52 | B20: Khoảng cách trung bình giữa các dầm C52 (theo phương hộp) | C20: 1.207 | D20: m | E20: ĐO trên bản vẽ CAD khung 6 bè. Chỉ dùng ước lượng bulông M10×120 hộp kết cấu – dầm (1 bộ mỗi giao điểm); hộp gia cường đếm giao điểm trên bản vẽ

Sheet GhiChu
A1: GHI CHÚ, NGUỒN SỐ LIỆU VÀ CÁC ĐIỂM CẦN XÁC NHẬN
A3: 1 | B3: Nguồn: "BO TRI BE PIN HO BAN MONG.pdf" (Revit, Chủ đầu tư 30/10/2026: CT-BP-01…06 bố trí từng bè có bảng tấm pin, phao, inverter; MB-B01-01 mặt bằng tổng có bảng phao đỡ cáp) và 6 tờ khung kết cấu "CHUGIAP-HOBANMONG ver 2-Sheet - CT-KC-BE-01…06 - BỐ TRÍ KHUNG KẾT CẤU BÈ PIN 0n.dxf"; HD lắp Mibet MRac G5, tài liệu phụ kiện Mibet, datasheet G5G. Script: scripts/buildHuoiVanhRaftReinforcement.py --lake=ban-mong, scripts/buildBanMongRaftBOQ.py.
A4: 2 | B4: Số tấm pin, phao, inverter lấy NGUYÊN bảng Revit trên tờ CT-BP (script kiểm tổng từng bảng). Dầm C52, hộp 40x60 kết cấu ĐO từng thanh trên bản vẽ CAD khung có gia cường (sheet C52_TungThanh, Hop40x60_TungThanh); đối chiếu bảng trên tờ khung ở sheet DoiChieu_KhungThep.
A5: 3 | B5: Số tấm pin 16.912 tấm (BÈ 1: 2.912; BÈ 2: 4.200; BÈ 3: 700; BÈ 4: 2.100; BÈ 5: 2.800; BÈ 6: 4.200). Từ 30/10/2026 lực gió. lực dây. cáp. cọc. đế trên web và trong thuyết minh. bảng tính. bảng vật tư neo đều tính theo số tấm này (trước đó tạm 16.900 chia theo diện tích).
A6: 4 | B6: Hộp 40x60 gia cường tại vị trí neo: vẽ thêm vào bản vẽ khung (lớp GC-HOP 40x60 GIA CUONG, GC-BICH NEO, GC-DAY NEO, GC-GHI CHU; file "... BỐ TRÍ KHUNG KẾT CẤU BÈ PIN 0n - GIA CƯỜNG TẠI VỊ TRÍ NEO.dwg"). Cáp 2 nhánh chữ Y, 2 bích mỗi dây cách nhau 3,5 m, mỗi bích chịu K_Y × T; T là lực dây của bè trong bảng vật tư neo (engine, gió 20 m/s, bù mực nước liên tục + khóa bão). Với P_KEP = 7 kN GIẢ ĐỊNH, cụm chịu lực lớn cần 2–6 thanh trên các hàng phao kế nhau — cần số liệu sức chịu móc "几" của Mibet; chi tiết liên kết bích – hộp do nhà cung cấp bè lập.
A7: 5 | B7: Mặt bằng neo (số dây, vị trí bích) là của web (ưu tiên bờ, tầm dây bờ 80 m, 243 dây), tính trên mặt bằng bè CAD 30/10/2026. Bản vẽ khung là mặt bằng đó xoay quanh gốc tọa độ (BÈ 1 105°, BÈ 2 15°, BÈ 3 94°, BÈ 4 84,9°, BÈ 5 60,3°, BÈ 6 35°), khớp đường bao lệch trung bình 0,3–0,8 m; khung rộng hơn đường bao 1,3–2 m ở một cạnh nên vị trí bích có thể lệch ~1 m dọc mép (thanh 15 m vẫn phủ).
A8: 6 | B8: Khối lượng thép theo tiết diện GIẢ ĐỊNH (C52 ≈ 2,36 kg/m; hộp 40×60×2,0 ≈ 3,01 kg/m) vì chưa có catalogue tiết diện của nhà sản xuất.
A9: 7 | B9: Gá đỡ, kẹp tấm pin, bulông nối phao, bulông M8 / M10 của khung là ƯỚC LƯỢNG theo hệ số mỗi tấm / mỗi phao / mỗi mét (sheet GiaDinh) — phải thay bằng BOM của nhà sản xuất khi có. Kẹp tiếp địa: hỏi Mibet trước khi đặt.
A10: 8 | B10: Chưa gồm: cáp neo, phụ kiện đầu cáp, thiết bị bù mực nước, cọc khoan nhồi, đế neo (xem bảng thống kê vật tư neo Bản Mòng), cáp điện DC/AC, máng cáp, tủ điện, tấm lối đi, vận chuyển.
A11: 9 | B11: Hình minh họa ở cột C chép từ bảng vật tư bè pin Huổi Vanh trước đây (cắt từ tài liệu Mibet): chỉ để nhận dạng loại vật tư, không phải bản vẽ chế tạo.
