Workbook

Sheet 1.HUONG_DAN
B2: BẢNG TÍNH NEO BÈ PIN NỔI — HỒ HUỔI VÃNH (BẢN RÚT GỌN)
B3: 5 trang. Ô vàng = nhập. Ô xanh = công thức. Thay số ở trang 2 là toàn bộ tự tính lại.
B6: CÁC TRANG
B7: 2.THONG_SO | C7: Toàn bộ thông số đầu vào, gom về một trang.
B8: 3.BE_VA_NEO | C8: 13 bè, mỗi bè một dòng. Lực gió, số dây, cỡ cáp, mỏ neo, kiểm tra.
B9: 4.COC_DAN_HUONG | C9: Công cụ tính CHUNG cho mọi bè — cọc neo bờ (mục B) và cọc neo lòng hồ 2 cách (mục C, D). Có bảng tra sức chịu.
B10: 5.TOA_DO_NEO | C10: 299 mỏ neo với tọa độ X, Y, Z — dùng để vẽ lại bản vẽ.
B13: CÁCH VẼ LẠI BẢN VẼ
B14: Bước 1 | C14: Trang 5 cột X bè, Y bè: điểm nối cáp trên mép bè.
B15: Bước 2 | C15: Trang 5 cột X neo, Y neo: vị trí mỏ neo.
B16: Bước 3 | C16: Nối hai điểm bằng đường thẳng = dây neo.
B17: Bước 4 | C17: Cột Loại: NEO BỜ vẽ ký hiệu cọc trên bờ, NEO ĐÁY vẽ ký hiệu cọc đóng lòng hồ (KHÔNG dùng mỏ neo bản kéo).
C18: Toàn bộ tọa độ theo hệ của bản vẽ DXF gốc, đơn vị mét.
B20: MỰC NƯỚC THIẾT KẾ
C21: Không dùng MNC làm đầu vào. Mực nước thấp nhất = đáy hồ + độ sâu tối thiểu dưới bè.
C22: MNC chỉ dùng để KIỂM TRA khả thi: nếu MNC thấp hơn mức đó thì bè sẽ mắc cạn.
B24: GIỚI HẠN
C25: Tính sơ bộ. Mô hình tĩnh, tuyến tính, bè chỉ tịnh tiến không xoay.
C26: Không mô phỏng động lực học, dây chùng phi tuyến, mỏi.
C27: Thiết kế thi công phải do kỹ sư chuyên ngành lập và thẩm tra.
B29: GIẢI THÍCH CÔNG THỨC
B30: Cột E (bên phải công thức) | C30: Mọi ô công thức đều có ô liền kề bên phải ghi rõ tính từ đâu — ô nào, sheet nào, ý nghĩa gì.
B31: Di chuột vào tiêu đề cột | C31: Ở trang 3.BE_VA_NEO (dạng bảng), di chuột vào TIÊU ĐỀ mỗi cột để xem chú thích công thức của cả cột.
B32: Ký hiệu tham chiếu | C32: "Ô C29" = ô C29 trong CÙNG sheet. "2.THONG_SO ô C31" = ô C31 ở SHEET KHÁC.
B33: Không sửa ô có nền xanh | C33: Nền xanh nhạt là công thức tự tính. Chỉ sửa ô nền vàng (đầu vào).
B35: LOẠI NEO
B36: Chỉ dùng CỌC ĐÓNG | C36: Neo bờ: cọc trên đất bờ, tay đòn nhỏ. Neo đáy: cọc đóng vào lòng hồ (2 cách, xem sheet 4 và sheet 7). KHÔNG dùng mỏ neo bản kéo/neo xoắn.
B37: Bè 01 đã tính chi tiết | C37: Sheet 3 hàng BÈ 1 liên kết trực tiếp tới sheet 7. Các bè 2-13 còn để "Chưa tính chi tiết" — tính dần khi có bản vẽ, dùng sheet 4 làm công cụ.

Sheet 2.THONG_SO
B2: THÔNG SỐ ĐẦU VÀO
B4: A. MỰC NƯỚC VÀ LÒNG HỒ
B5: MNDBT | C5: 383 | D5: m | E5: Từ hồ sơ hồ
B6: MNCN (mực nước cao nhất) | C6: 384 | D6: m | E6: GIẢ ĐỊNH
B7: Độ sâu lớn nhất tại MNDBT | C7: 6.2 | D7: m | E7: Từ mặt cắt lòng hồ
B8: Cao trình đáy hồ | C8: =C5-C7 | D8: m | E8: → ô C5 (mndbt) − Ô C7 (độ sâu lớn nhất)
B9: Độ sâu tối thiểu cần có dưới bè | C9: 1.5 | D9: m | E9: Mớn nước phao + mỏ neo + bùn + dự phòng
B10: MỰC NƯỚC THẤP NHẤT THIẾT KẾ | C10: =C8+C9 | D10: m | E10: Đáy hồ + độ sâu tối thiểu
B11: Biên độ làm việc của hệ neo | C11: =C5-C10 | D11: m | E11: → ô C5 (mndbt) − Ô C10 (mực nước thấp nhất thiết kế)
B12: Độ dốc bờ 1:m | C12: 3.1 | D12: - | E12: Đo từ đường đồng mức 0,5 m
B13: Bờ lùi khi rút nước | C13: =C11*C12 | D13: m | E13: → ô C11 (biên độ) × Ô C12 (độ dốc bờ 1:m)
B14: MNC theo hồ sơ (chỉ để kiểm tra) | D14: m | E14: Để trống nếu chưa có
B15: KIỂM TRA KHẢ THI | C15: =IF(C14="","Chưa có MNC — chưa kiểm tra được",IF(C14>=C10,"KHẢ THI","KHÔNG KHẢ THI — bè sẽ mắc cạn")) | E15: So sánh Ô C14 (MNC hồ sơ, nhập tay) với Ô C10. Để trống C14 thì chưa kiểm tra được
B17: B. TẢI TRỌNG
B18: Vận tốc gió thiết kế V | C18: 30 | D18: m/s | E18: GIẢ ĐỊNH — cần QCVN 02
B19: Khối lượng riêng không khí | C19: 1.25 | D19: kg/m3
B20: Hệ số lực cản tấm pin | C20: 1.3 | D20: - | E20: GIẢ ĐỊNH
B21: Hệ số che chắn giữa các hàng | C21: 0.55 | D21: - | E21: GIẢ ĐỊNH
B22: Hệ số lực cản phao | C22: 1.1 | D22: - | E22: GIẢ ĐỊNH
B23: Chiều cao phần nổi của phao | C23: 0.35 | D23: m | E23: GIẢ ĐỊNH
B24: Góc nghiêng tấm pin | C24: 12 | D24: độ
B25: Diện tích một tấm pin | C25: 2.701 | D25: m2 | E25: 2382 x 1134 mm
B26: Tổng số tấm pin toàn dự án | C26: 17367 | D26: tấm | E26: Từ bản vẽ
B27: Tổng diện tích bè toàn dự án | C27: 81115 | D27: m2 | E27: Từ bản vẽ
B28: Cộng thêm cho dòng chảy và sóng | C28: 1.05 | D28: - | E28: Hồ gần như không sóng
B30: C. DÂY CÁP
B31: Hệ số an toàn cho cáp | C31: 3 | D31: - | E31: GIẢ ĐỊNH
B32: Lực căng trước T0 | C32: 5 | D32: kN | E32: GIẢ ĐỊNH
B33: Khoảng cách dây tối đa | C33: 15 | D33: m | E33: Theo cấu tạo
B35: D. ĐẤT NỀN VÀ MỎ NEO
B36: cu tại LÒNG HỒ (đáy hồ) — dùng cho cọc neo đáy | C36: 20 | D36: kPa | E36: NHẬP: lực dính bùn đáy hồ. Dùng cho MỌI cọc đóng dưới nước
B37: Hệ số an toàn cọc (Broms) | C37: 2.5 | D37: - | E37: GIẢ ĐỊNH
B41: cu tại ĐẤT BỜ — dùng cho cọc neo bờ | C41: 40 | D41: kPa | E41: NHẬP: lực dính đất bờ, thường CAO HƠN bùn đáy hồ. CẦN KHẢO SÁT
B42: E. CỌC LÒNG HỒ — CÁCH 2 (đỉnh cọc trên MNCN, qua vòng trượt)
B43: Cao trình chân cọc | C43: =C10 | D43: m | E43: Cách 2 chỉ dùng khi bắt buộc tránh thợ lặn. Xem so sánh 2 cách ở sheet 4 và sheet 7
B44: Cao trình đỉnh cọc | C44: =C6+0.8 | D44: m | E44: MNCN + 0,8 m chống tuột vòng
B45: Tay đòn e khi hồ đầy | C45: =C5+C23-C43 | D45: m | E45: TRƯỜNG HỢP BẤT LỢI NHẤT
B46: Đường kính ống thép D | C46: 0.8 | D46: m
B47: Chiều dày thành t | C47: 0.016 | D47: m
B48: Chiều sâu ngàm L | C48: 13 | D48: m
...

Sheet 3.BE_VA_NEO
B2: TÍNH TOÁN 13 BÈ — MỖI BÈ MỘT DÒNG
B3: Ô vàng là nhập (hình học đọc từ bản vẽ + hệ số tập trung lực). Còn lại tự tính.
B5: Bè | C5: Diện tích (m²) | D5: Chu vi (m) | E5: Dài (m) | F5: Rộng (m) | G5: Góc bè (°) | H5: Số tấm pin | I5: A chiếu pin (m²) | J5: A chiếu phao (m²) | K5: LỰC MÔI TRƯỜNG F (kN) | L5: Hệ số tập trung | M5: T max (kN) | N5: Số dây | O5: Số neo bờ | P5: Số neo đáy | Q5: MBL cáp yêu cầu (kN) | R5: Cáp chọn | S5: MBL cáp (kN) | T5: HS cáp | U5: KT CÁP | V5: Loại neo đáy | W5: Sức chịu (kN) | X5: HS neo đáy | Y5: KT NEO ĐÁY | Z5: Độ sâu nước tại bè (m) | AA5: K.cách bè→cọc NEO ĐÁY (m) | AB5: Góc dây tại cọc (°) | AC5: Th - Lực ngang (kN) | AD5: Tv - Lực nhổ (kN) | AE5: Sức chịu NGANG cọc (kN) | AF5: Sức chịu NHỔ cọc (kN) | AG5: HS ngang | AH5: HS nhổ | AI5: KT NEO ĐÁY (theo k.cách) | AJ5: Dài 1 dây NEO ĐÁY (m) | AK5: Tổng dài dây NEO ĐÁY (m) | AL5: K.cách bè→cọc NEO BỜ (m) | AM5: Dài 1 dây NEO BỜ (m) | AN5: Tổng dài dây NEO BỜ (m) | AO5: TỔNG DÀI DÂY NEO (m)
B6: BÈ 1 | C6: 3600 | D6: 263.2 | E6: 90.6 | F6: 41 | G6: 144 | H6: =ROUND(C6/'2.THONG_SO'!$C$27*'2.THONG_SO'!$C$26,0) | I6: =H6*'2.THONG_SO'!$C$25*SIN(RADIANS('2.THONG_SO'!$C$24)) | J6: =(E6+F6)/2*'2.THONG_SO'!$C$23 | K6: =0.5*'2.THONG_SO'!$C$19*('2.THONG_SO'!$C$20*I6*'2.THONG_SO'!$C$21+'2.THONG_SO'!$C$22*J6)*'2.THONG_SO'!$C$18^2/1000*'2.THONG_SO'!$C$28 | L6: ='7.BE01_CHI_TIET'!C28 | M6: =K6*L6+'2.THONG_SO'!$C$32 | N6: ='7.BE01_CHI_TIET'!C24 | O6: ='7.BE01_CHI_TIET'!C25 | P6: ='7.BE01_CHI_TIET'!C26 | Q6: =M6*'2.THONG_SO'!$C$31 | R6: PES-28 | S6: =IFERROR(LOOKUP(R6,{"PES-20";"PES-24";"PES-28";"PES-32";"PES-36";"PES-40";"PES-44"},{120;175;235;310;390;480;580}),"") | T6: =IFERROR(Q6/S6,"") | U6: =IF(T6="","THIẾU DỮ LIỆU",IF(T6<=1,"ĐẠT","KHÔNG ĐẠT")) | V6: Cọc đóng lòng hồ | W6: =IF('7.BE01_CHI_TIET'!C112="Cách 1 — đỉnh ở đáy hồ",'7.BE01_CHI_TIET'!C75,'7.BE01_CHI_TIET'!C100) | X6: =IFERROR(P6*'2.THONG_SO'!$C$37/W6,"") | Y6: ='7.BE01_CHI_TIET'!C113 | Z6: 6 | AA6: 13.5 | AB6: =IFERROR(DEGREES(ATAN(Z6/AA6)),"") | AC6: =M6*COS(RADIANS(AB6)) | AD6: =M6*SIN(RADIANS(AB6)) | AE6: ='4.COC_DAN_HUONG'!$C$38 | AF6: ='4.COC_DAN_HUONG'!$C$39 | AG6: =IFERROR(AC6/AE6,"") | AH6: =IFERROR(AD6/AF6,"") | AI6: =IF(P6=0,"KHÔNG CÓ NEO ĐÁY",IF(AND(AG6<=1,AH6<=1),"ĐẠT","KHÔNG ĐẠT — rút ngắn k.cách hoặc tăng D/L cọc")) | AJ6: =SQRT(Z6^2+AA6^2) | AK6: =P6*AJ6 | AL6: 20 | AM6: =AL6 | AN6: =O6*AM6 | AO6: =AK6+AN6
B7: BÈ 2 | C7: 4125 | D7: 288.9 | E7: 88.7 | F7: 56 | G7: 140.7 | H7: =ROUND(C7/'2.THONG_SO'!$C$27*'2.THONG_SO'!$C$26,0) | I7: =H7*'2.THONG_SO'!$C$25*SIN(RADIANS('2.THONG_SO'!$C$24)) | J7: =(E7+F7)/2*'2.THONG_SO'!$C$23 | K7: =0.5*'2.THONG_SO'!$C$19*('2.THONG_SO'!$C$20*I7*'2.THONG_SO'!$C$21+'2.THONG_SO'!$C$22*J7)*'2.THONG_SO'!$C$18^2/1000*'2.THONG_SO'!$C$28 | L7: 0.282 | M7: =K7*L7+'2.THONG_SO'!$C$32 | N7: =MAX(CEILING(D7/'2.THONG_SO'!$C$33,1),3) | O7: 10 | P7: 10 | Q7: =M7*'2.THONG_SO'!$C$31 | R7: PES-28 | S7: =IFERROR(LOOKUP(R7,{"PES-20";"PES-24";"PES-28";"PES-32";"PES-36";"PES-40";"PES-44"},{120;175;235;310;390;480;580}),"") | T7: =IFERROR(Q7/S7,"") | U7: =IF(T7="","THIẾU DỮ LIỆU",IF(T7<=1,"ĐẠT","KHÔNG ĐẠT")) | V7: Chưa tính chi tiết | W7: =IF(V7="BAN-1.0",'2.THONG_SO'!$C$38,IF(V7="BAN-1.4",'2.THONG_SO'!$C$39,IF(V7="BAN-1.8",'2.THONG_SO'!$C$40,""))) | X7: =IFERROR(M7*'2.THONG_SO'!$C$37/W7,"") | Y7: =IF(V7="Chưa tính chi tiết","CHƯA TÍNH",IF(X7="","CHƯA TÍNH",IF(X7<=1,"ĐẠT","KHÔNG ĐẠT"))) | Z7: 6.2 | AA7: 15 | AB7: =IFERROR(DEGREES(ATAN(Z7/AA7)),"") | AC7: =M7*COS(RADIANS(AB7)) | AD7: =M7*SIN(RADIANS(AB7)) | AE7: ='4.COC_DAN_HUONG'!$C$38 | AF7: ='4.COC_DAN_HUONG'!$C$39 | AG7: =IFERROR(AC7/AE7,"") | AH7: =IFERROR(AD7/AF7,"") | AI7: =IF(P7=0,"KHÔNG CÓ NEO ĐÁY",IF(AND(AG7<=1,AH7<=1),"ĐẠT","KHÔNG ĐẠT — rút ngắn k.cách hoặc tăng D/L cọc")) | AJ7: =SQRT(Z7^2+AA7^2) | AK7: =P7*AJ7 | AL7: 20 | AM7: =AL7 | AN7: =O7*AM7 | AO7: =AK7+AN7
B8: BÈ 3 | C8: 4800 | D8: 297.8 | E8: 88.7 | F8: 60.3 | G8: 113 | H8: =ROUND(C8/'2.THONG_SO'!$C$27*'2.THONG_SO'!$C$26,0) | I8: =H8*'2.THONG_SO'!$C$25*SIN(RADIANS('2.THONG_SO'!$C$24)) | J8: =(E8+F8)/2*'2.THONG_SO'!$C$23 | K8: =0.5*'2.THONG_SO'!$C$19*('2.THONG_SO'!$C$20*I8*'2.THONG_SO'!$C$21+'2.THONG_SO'!$C$22*J8)*'2.THONG_SO'!$C$18^2/1000*'2.THONG_SO'!$C$28 | L8: 0.327 | M8: =K8*L8+'2.THONG_SO'!$C$32 | N8: =MAX(CEILING(D8/'2.THONG_SO'!$C$33,1),3) | O8: 11 | P8: 9 | Q8: =M8*'2.THONG_SO'!$C$31 | R8: PES-32 | S8: =IFERROR(LOOKUP(R8,{"PES-20";"PES-24";"PES-28";"PES-32";"PES-36";"PES-40";"PES-44"},{120;175;235;310;390;480;580}),"") | T8: =IFERROR(Q8/S8,"") | U8: =IF(T8="","THIẾU DỮ LIỆU",IF(T8<=1,"ĐẠT","KHÔNG ĐẠT")) | V8: Chưa tính chi tiết | W8: =IF(V8="BAN-1.0",'2.THONG_SO'!$C$38,IF(V8="BAN-1.4",'2.THONG_SO'!$C$39,IF(V8="BAN-1.8",'2.THONG_SO'!$C$40,""))) | X8: =IFERROR(M8*'2.THONG_SO'!$C$37/W8,"") | Y8: =IF(V8="Chưa tính chi tiết","CHƯA TÍNH",IF(X8="","CHƯA TÍNH",IF(X8<=1,"ĐẠT","KHÔNG ĐẠT"))) | Z8: 6.2 | AA8: 15 | AB8: =IFERROR(DEGREES(ATAN(Z8/AA8)),"") | AC8: =M8*COS(RADIANS(AB8)) | AD8: =M8*SIN(RADIANS(AB8)) | AE8: ='4.COC_DAN_HUONG'!$C$38 | AF8: ='4.COC_DAN_HUONG'!$C$39 | AG8: =IFERROR(AC8/AE8,"") | AH8: =IFERROR(AD8/AF8,"") | AI8: =IF(P8=0,"KHÔNG CÓ NEO ĐÁY",IF(AND(AG8<=1,AH8<=1),"ĐẠT","KHÔNG ĐẠT — rút ngắn k.cách hoặc tăng D/L cọc")) | AJ8: =SQRT(Z8^2+AA8^2) | AK8: =P8*AJ8 | AL8: 20 | AM8: =AL8 | AN8: =O8*AM8 | AO8: =AK8+AN8
B9: BÈ 4 | C9: 4860 | D9: 330.2 | E9: 100.1 | F9: 65.1 | G9: 90 | H9: =ROUND(C9/'2.THONG_SO'!$C$27*'2.THONG_SO'!$C$26,0) | I9: =H9*'2.THONG_SO'!$C$25*SIN(RADIANS('2.THONG_SO'!$C$24)) | J9: =(E9+F9)/2*'2.THONG_SO'!$C$23 | K9: =0.5*'2.THONG_SO'!$C$19*('2.THONG_SO'!$C$20*I9*'2.THONG_SO'!$C$21+'2.THONG_SO'!$C$22*J9)*'2.THONG_SO'!$C$18^2/1000*'2.THONG_SO'!$C$28 | L9: 0.34 | M9: =K9*L9+'2.THONG_SO'!$C$32 | N9: =MAX(CEILING(D9/'2.THONG_SO'!$C$33,1),3) | O9: 6 | P9: 17 | Q9: =M9*'2.THONG_SO'!$C$31 | R9: PES-32 | S9: =IFERROR(LOOKUP(R9,{"PES-20";"PES-24";"PES-28";"PES-32";"PES-36";"PES-40";"PES-44"},{120;175;235;310;390;480;580}),"") | T9: =IFERROR(Q9/S9,"") | U9: =IF(T9="","THIẾU DỮ LIỆU",IF(T9<=1,"ĐẠT","KHÔNG ĐẠT")) | V9: Chưa tính chi tiết | W9: =IF(V9="BAN-1.0",'2.THONG_SO'!$C$38,IF(V9="BAN-1.4",'2.THONG_SO'!$C$39,IF(V9="BAN-1.8",'2.THONG_SO'!$C$40,""))) | X9: =IFERROR(M9*'2.THONG_SO'!$C$37/W9,"") | Y9: =IF(V9="Chưa tính chi tiết","CHƯA TÍNH",IF(X9="","CHƯA TÍNH",IF(X9<=1,"ĐẠT","KHÔNG ĐẠT"))) | Z9: 6.2 | AA9: 15 | AB9: =IFERROR(DEGREES(ATAN(Z9/AA9)),"") | AC9: =M9*COS(RADIANS(AB9)) | AD9: =M9*SIN(RADIANS(AB9)) | AE9: ='4.COC_DAN_HUONG'!$C$38 | AF9: ='4.COC_DAN_HUONG'!$C$39 | AG9: =IFERROR(AC9/AE9,"") | AH9: =IFERROR(AD9/AF9,"") | AI9: =IF(P9=0,"KHÔNG CÓ NEO ĐÁY",IF(AND(AG9<=1,AH9<=1),"ĐẠT","KHÔNG ĐẠT — rút ngắn k.cách hoặc tăng D/L cọc")) | AJ9: =SQRT(Z9^2+AA9^2) | AK9: =P9*AJ9 | AL9: 20 | AM9: =AL9 | AN9: =O9*AM9 | AO9: =AK9+AN9
B10: BÈ 5 | C10: 19200 | D10: 547.6 | E10: 156.9 | F10: 117 | G10: 90 | H10: =ROUND(C10/'2.THONG_SO'!$C$27*'2.THONG_SO'!$C$26,0) | I10: =H10*'2.THONG_SO'!$C$25*SIN(RADIANS('2.THONG_SO'!$C$24)) | J10: =(E10+F10)/2*'2.THONG_SO'!$C$23 | K10: =0.5*'2.THONG_SO'!$C$19*('2.THONG_SO'!$C$20*I10*'2.THONG_SO'!$C$21+'2.THONG_SO'!$C$22*J10)*'2.THONG_SO'!$C$18^2/1000*'2.THONG_SO'!$C$28 | L10: 0.102 | M10: =K10*L10+'2.THONG_SO'!$C$32 | N10: =MAX(CEILING(D10/'2.THONG_SO'!$C$33,1),3) | O10: 12 | P10: 38 | Q10: =M10*'2.THONG_SO'!$C$31 | R10: PES-36 | S10: =IFERROR(LOOKUP(R10,{"PES-20";"PES-24";"PES-28";"PES-32";"PES-36";"PES-40";"PES-44"},{120;175;235;310;390;480;580}),"") | T10: =IFERROR(Q10/S10,"") | U10: =IF(T10="","THIẾU DỮ LIỆU",IF(T10<=1,"ĐẠT","KHÔNG ĐẠT")) | V10: Chưa tính chi tiết | W10: =IF(V10="BAN-1.0",'2.THONG_SO'!$C$38,IF(V10="BAN-1.4",'2.THONG_SO'!$C$39,IF(V10="BAN-1.8",'2.THONG_SO'!$C$40,""))) | X10: =IFERROR(M10*'2.THONG_SO'!$C$37/W10,"") | Y10: =IF(V10="Chưa tính chi tiết","CHƯA TÍNH",IF(X10="","CHƯA TÍNH",IF(X10<=1,"ĐẠT","KHÔNG ĐẠT"))) | Z10: 6.2 | AA10: 15 | AB10: =IFERROR(DEGREES(ATAN(Z10/AA10)),"") | AC10: =M10*COS(RADIANS(AB10)) | AD10: =M10*SIN(RADIANS(AB10)) | AE10: ='4.COC_DAN_HUONG'!$C$38 | AF10: ='4.COC_DAN_HUONG'!$C$39 | AG10: =IFERROR(AC10/AE10,"") | AH10: =IFERROR(AD10/AF10,"") | AI10: =IF(P10=0,"KHÔNG CÓ NEO ĐÁY",IF(AND(AG10<=1,AH10<=1),"ĐẠT","KHÔNG ĐẠT — rút ngắn k.cách hoặc tăng D/L cọc")) | AJ10: =SQRT(Z10^2+AA10^2) | AK10: =P10*AJ10 | AL10: 20 | AM10: =AL10 | AN10: =O10*AM10 | AO10: =AK10+AN10
B11: BÈ 6 | C11: 9031 | D11: 409.5 | E11: 108.6 | F11: 96.3 | G11: 0 | H11: =ROUND(C11/'2.THONG_SO'!$C$27*'2.THONG_SO'!$C$26,0) | I11: =H11*'2.THONG_SO'!$C$25*SIN(RADIANS('2.THONG_SO'!$C$24)) | J11: =(E11+F11)/2*'2.THONG_SO'!$C$23 | K11: =0.5*'2.THONG_SO'!$C$19*('2.THONG_SO'!$C$20*I11*'2.THONG_SO'!$C$21+'2.THONG_SO'!$C$22*J11)*'2.THONG_SO'!$C$18^2/1000*'2.THONG_SO'!$C$28 | L11: 0.206 | M11: =K11*L11+'2.THONG_SO'!$C$32 | N11: =MAX(CEILING(D11/'2.THONG_SO'!$C$33,1),3) | O11: 4 | P11: 24 | Q11: =M11*'2.THONG_SO'!$C$31 | R11: PES-36 | S11: =IFERROR(LOOKUP(R11,{"PES-20";"PES-24";"PES-28";"PES-32";"PES-36";"PES-40";"PES-44"},{120;175;235;310;390;480;580}),"") | T11: =IFERROR(Q11/S11,"") | U11: =IF(T11="","THIẾU DỮ LIỆU",IF(T11<=1,"ĐẠT","KHÔNG ĐẠT")) | V11: Chưa tính chi tiết | W11: =IF(V11="BAN-1.0",'2.THONG_SO'!$C$38,IF(V11="BAN-1.4",'2.THONG_SO'!$C$39,IF(V11="BAN-1.8",'2.THONG_SO'!$C$40,""))) | X11: =IFERROR(M11*'2.THONG_SO'!$C$37/W11,"") | Y11: =IF(V11="Chưa tính chi tiết","CHƯA TÍNH",IF(X11="","CHƯA TÍNH",IF(X11<=1,"ĐẠT","KHÔNG ĐẠT"))) | Z11: 6.2 | AA11: 15 | AB11: =IFERROR(DEGREES(ATAN(Z11/AA11)),"") | AC11: =M11*COS(RADIANS(AB11)) | AD11: =M11*SIN(RADIANS(AB11)) | AE11: ='4.COC_DAN_HUONG'!$C$38 | AF11: ='4.COC_DAN_HUONG'!$C$39 | AG11: =IFERROR(AC11/AE11,"") | AH11: =IFERROR(AD11/AF11,"") | AI11: =IF(P11=0,"KHÔNG CÓ NEO ĐÁY",IF(AND(AG11<=1,AH11<=1),"ĐẠT","KHÔNG ĐẠT — rút ngắn k.cách hoặc tăng D/L cọc")) | AJ11: =SQRT(Z11^2+AA11^2) | AK11: =P11*AJ11 | AL11: 20 | AM11: =AL11 | AN11: =O11*AM11 | AO11: =AK11+AN11
B12: BÈ 7 | C12: 2575 | D12: 230.2 | E12: 62.7 | F12: 52.6 | G12: 0 | H12: =ROUND(C12/'2.THONG_SO'!$C$27*'2.THONG_SO'!$C$26,0) | I12: =H12*'2.THONG_SO'!$C$25*SIN(RADIANS('2.THONG_SO'!$C$24)) | J12: =(E12+F12)/2*'2.THONG_SO'!$C$23 | K12: =0.5*'2.THONG_SO'!$C$19*('2.THONG_SO'!$C$20*I12*'2.THONG_SO'!$C$21+'2.THONG_SO'!$C$22*J12)*'2.THONG_SO'!$C$18^2/1000*'2.THONG_SO'!$C$28 | L12: 0.341 | M12: =K12*L12+'2.THONG_SO'!$C$32 | N12: =MAX(CEILING(D12/'2.THONG_SO'!$C$33,1),3) | O12: 4 | P12: 12 | Q12: =M12*'2.THONG_SO'!$C$31 | R12: PES-24 | S12: =IFERROR(LOOKUP(R12,{"PES-20";"PES-24";"PES-28";"PES-32";"PES-36";"PES-40";"PES-44"},{120;175;235;310;390;480;580}),"") | T12: =IFERROR(Q12/S12,"") | U12: =IF(T12="","THIẾU DỮ LIỆU",IF(T12<=1,"ĐẠT","KHÔNG ĐẠT")) | V12: Chưa tính chi tiết | W12: =IF(V12="BAN-1.0",'2.THONG_SO'!$C$38,IF(V12="BAN-1.4",'2.THONG_SO'!$C$39,IF(V12="BAN-1.8",'2.THONG_SO'!$C$40,""))) | X12: =IFERROR(M12*'2.THONG_SO'!$C$37/W12,"") | Y12: =IF(V12="Chưa tính chi tiết","CHƯA TÍNH",IF(X12="","CHƯA TÍNH",IF(X12<=1,"ĐẠT","KHÔNG ĐẠT"))) | Z12: 6.2 | AA12: 15 | AB12: =IFERROR(DEGREES(ATAN(Z12/AA12)),"") | AC12: =M12*COS(RADIANS(AB12)) | AD12: =M12*SIN(RADIANS(AB12)) | AE12: ='4.COC_DAN_HUONG'!$C$38 | AF12: ='4.COC_DAN_HUONG'!$C$39 | AG12: =IFERROR(AC12/AE12,"") | AH12: =IFERROR(AD12/AF12,"") | AI12: =IF(P12=0,"KHÔNG CÓ NEO ĐÁY",IF(AND(AG12<=1,AH12<=1),"ĐẠT","KHÔNG ĐẠT — rút ngắn k.cách hoặc tăng D/L cọc")) | AJ12: =SQRT(Z12^2+AA12^2) | AK12: =P12*AJ12 | AL12: 20 | AM12: =AL12 | AN12: =O12*AM12 | AO12: =AK12+AN12
B13: BÈ 8 | C13: 2118 | D13: 182.7 | E13: 48.2 | F13: 43.1 | G13: 16 | H13: =ROUND(C13/'2.THONG_SO'!$C$27*'2.THONG_SO'!$C$26,0) | I13: =H13*'2.THONG_SO'!$C$25*SIN(RADIANS('2.THONG_SO'!$C$24)) | J13: =(E13+F13)/2*'2.THONG_SO'!$C$23 | K13: =0.5*'2.THONG_SO'!$C$19*('2.THONG_SO'!$C$20*I13*'2.THONG_SO'!$C$21+'2.THONG_SO'!$C$22*J13)*'2.THONG_SO'!$C$18^2/1000*'2.THONG_SO'!$C$28 | L13: 0.348 | M13: =K13*L13+'2.THONG_SO'!$C$32 | N13: =MAX(CEILING(D13/'2.THONG_SO'!$C$33,1),3) | O13: 7 | P13: 6 | Q13: =M13*'2.THONG_SO'!$C$31 | R13: PES-24 | S13: =IFERROR(LOOKUP(R13,{"PES-20";"PES-24";"PES-28";"PES-32";"PES-36";"PES-40";"PES-44"},{120;175;235;310;390;480;580}),"") | T13: =IFERROR(Q13/S13,"") | U13: =IF(T13="","THIẾU DỮ LIỆU",IF(T13<=1,"ĐẠT","KHÔNG ĐẠT")) | V13: Chưa tính chi tiết | W13: =IF(V13="BAN-1.0",'2.THONG_SO'!$C$38,IF(V13="BAN-1.4",'2.THONG_SO'!$C$39,IF(V13="BAN-1.8",'2.THONG_SO'!$C$40,""))) | X13: =IFERROR(M13*'2.THONG_SO'!$C$37/W13,"") | Y13: =IF(V13="Chưa tính chi tiết","CHƯA TÍNH",IF(X13="","CHƯA TÍNH",IF(X13<=1,"ĐẠT","KHÔNG ĐẠT"))) | Z13: 6.2 | AA13: 15 | AB13: =IFERROR(DEGREES(ATAN(Z13/AA13)),"") | AC13: =M13*COS(RADIANS(AB13)) | AD13: =M13*SIN(RADIANS(AB13)) | AE13: ='4.COC_DAN_HUONG'!$C$38 | AF13: ='4.COC_DAN_HUONG'!$C$39 | AG13: =IFERROR(AC13/AE13,"") | AH13: =IFERROR(AD13/AF13,"") | AI13: =IF(P13=0,"KHÔNG CÓ NEO ĐÁY",IF(AND(AG13<=1,AH13<=1),"ĐẠT","KHÔNG ĐẠT — rút ngắn k.cách hoặc tăng D/L cọc")) | AJ13: =SQRT(Z13^2+AA13^2) | AK13: =P13*AJ13 | AL13: 20 | AM13: =AL13 | AN13: =O13*AM13 | AO13: =AK13+AN13
B14: BÈ 9 | C14: 2646 | D14: 215.3 | E14: 62.7 | F14: 45 | G14: 16 | H14: =ROUND(C14/'2.THONG_SO'!$C$27*'2.THONG_SO'!$C$26,0) | I14: =H14*'2.THONG_SO'!$C$25*SIN(RADIANS('2.THONG_SO'!$C$24)) | J14: =(E14+F14)/2*'2.THONG_SO'!$C$23 | K14: =0.5*'2.THONG_SO'!$C$19*('2.THONG_SO'!$C$20*I14*'2.THONG_SO'!$C$21+'2.THONG_SO'!$C$22*J14)*'2.THONG_SO'!$C$18^2/1000*'2.THONG_SO'!$C$28 | L14: 0.361 | M14: =K14*L14+'2.THONG_SO'!$C$32 | N14: =MAX(CEILING(D14/'2.THONG_SO'!$C$33,1),3) | O14: 9 | P14: 6 | Q14: =M14*'2.THONG_SO'!$C$31 | R14: PES-24 | S14: =IFERROR(LOOKUP(R14,{"PES-20";"PES-24";"PES-28";"PES-32";"PES-36";"PES-40";"PES-44"},{120;175;235;310;390;480;580}),"") | T14: =IFERROR(Q14/S14,"") | U14: =IF(T14="","THIẾU DỮ LIỆU",IF(T14<=1,"ĐẠT","KHÔNG ĐẠT")) | V14: Chưa tính chi tiết | W14: =IF(V14="BAN-1.0",'2.THONG_SO'!$C$38,IF(V14="BAN-1.4",'2.THONG_SO'!$C$39,IF(V14="BAN-1.8",'2.THONG_SO'!$C$40,""))) | X14: =IFERROR(M14*'2.THONG_SO'!$C$37/W14,"") | Y14: =IF(V14="Chưa tính chi tiết","CHƯA TÍNH",IF(X14="","CHƯA TÍNH",IF(X14<=1,"ĐẠT","KHÔNG ĐẠT"))) | Z14: 6.2 | AA14: 15 | AB14: =IFERROR(DEGREES(ATAN(Z14/AA14)),"") | AC14: =M14*COS(RADIANS(AB14)) | AD14: =M14*SIN(RADIANS(AB14)) | AE14: ='4.COC_DAN_HUONG'!$C$38 | AF14: ='4.COC_DAN_HUONG'!$C$39 | AG14: =IFERROR(AC14/AE14,"") | AH14: =IFERROR(AD14/AF14,"") | AI14: =IF(P14=0,"KHÔNG CÓ NEO ĐÁY",IF(AND(AG14<=1,AH14<=1),"ĐẠT","KHÔNG ĐẠT — rút ngắn k.cách hoặc tăng D/L cọc")) | AJ14: =SQRT(Z14^2+AA14^2) | AK14: =P14*AJ14 | AL14: 20 | AM14: =AL14 | AN14: =O14*AM14 | AO14: =AK14+AN14
B15: BÈ 10 | C15: 11630 | D15: 469.2 | E15: 145.5 | F15: 89.3 | G15: 90 | H15: =ROUND(C15/'2.THONG_SO'!$C$27*'2.THONG_SO'!$C$26,0) | I15: =H15*'2.THONG_SO'!$C$25*SIN(RADIANS('2.THONG_SO'!$C$24)) | J15: =(E15+F15)/2*'2.THONG_SO'!$C$23 | K15: =0.5*'2.THONG_SO'!$C$19*('2.THONG_SO'!$C$20*I15*'2.THONG_SO'!$C$21+'2.THONG_SO'!$C$22*J15)*'2.THONG_SO'!$C$18^2/1000*'2.THONG_SO'!$C$28 | L15: 0.169 | M15: =K15*L15+'2.THONG_SO'!$C$32 | N15: =MAX(CEILING(D15/'2.THONG_SO'!$C$33,1),3) | O15: 18 | P15: 14 | Q15: =M15*'2.THONG_SO'!$C$31 | R15: PES-36 | S15: =IFERROR(LOOKUP(R15,{"PES-20";"PES-24";"PES-28";"PES-32";"PES-36";"PES-40";"PES-44"},{120;175;235;310;390;480;580}),"") | T15: =IFERROR(Q15/S15,"") | U15: =IF(T15="","THIẾU DỮ LIỆU",IF(T15<=1,"ĐẠT","KHÔNG ĐẠT")) | V15: Chưa tính chi tiết | W15: =IF(V15="BAN-1.0",'2.THONG_SO'!$C$38,IF(V15="BAN-1.4",'2.THONG_SO'!$C$39,IF(V15="BAN-1.8",'2.THONG_SO'!$C$40,""))) | X15: =IFERROR(M15*'2.THONG_SO'!$C$37/W15,"") | Y15: =IF(V15="Chưa tính chi tiết","CHƯA TÍNH",IF(X15="","CHƯA TÍNH",IF(X15<=1,"ĐẠT","KHÔNG ĐẠT"))) | Z15: 6.2 | AA15: 15 | AB15: =IFERROR(DEGREES(ATAN(Z15/AA15)),"") | AC15: =M15*COS(RADIANS(AB15)) | AD15: =M15*SIN(RADIANS(AB15)) | AE15: ='4.COC_DAN_HUONG'!$C$38 | AF15: ='4.COC_DAN_HUONG'!$C$39 | AG15: =IFERROR(AC15/AE15,"") | AH15: =IFERROR(AD15/AF15,"") | AI15: =IF(P15=0,"KHÔNG CÓ NEO ĐÁY",IF(AND(AG15<=1,AH15<=1),"ĐẠT","KHÔNG ĐẠT — rút ngắn k.cách hoặc tăng D/L cọc")) | AJ15: =SQRT(Z15^2+AA15^2) | AK15: =P15*AJ15 | AL15: 20 | AM15: =AL15 | AN15: =O15*AM15 | AO15: =AK15+AN15
B16: BÈ 11 | C16: 8830 | D16: 401.1 | E16: 106.7 | F16: 94.1 | G16: 90 | H16: =ROUND(C16/'2.THONG_SO'!$C$27*'2.THONG_SO'!$C$26,0) | I16: =H16*'2.THONG_SO'!$C$25*SIN(RADIANS('2.THONG_SO'!$C$24)) | J16: =(E16+F16)/2*'2.THONG_SO'!$C$23 | K16: =0.5*'2.THONG_SO'!$C$19*('2.THONG_SO'!$C$20*I16*'2.THONG_SO'!$C$21+'2.THONG_SO'!$C$22*J16)*'2.THONG_SO'!$C$18^2/1000*'2.THONG_SO'!$C$28 | L16: 0.18 | M16: =K16*L16+'2.THONG_SO'!$C$32 | N16: =MAX(CEILING(D16/'2.THONG_SO'!$C$33,1),3) | O16: 11 | P16: 16 | Q16: =M16*'2.THONG_SO'!$C$31 | R16: PES-32 | S16: =IFERROR(LOOKUP(R16,{"PES-20";"PES-24";"PES-28";"PES-32";"PES-36";"PES-40";"PES-44"},{120;175;235;310;390;480;580}),"") | T16: =IFERROR(Q16/S16,"") | U16: =IF(T16="","THIẾU DỮ LIỆU",IF(T16<=1,"ĐẠT","KHÔNG ĐẠT")) | V16: Chưa tính chi tiết | W16: =IF(V16="BAN-1.0",'2.THONG_SO'!$C$38,IF(V16="BAN-1.4",'2.THONG_SO'!$C$39,IF(V16="BAN-1.8",'2.THONG_SO'!$C$40,""))) | X16: =IFERROR(M16*'2.THONG_SO'!$C$37/W16,"") | Y16: =IF(V16="Chưa tính chi tiết","CHƯA TÍNH",IF(X16="","CHƯA TÍNH",IF(X16<=1,"ĐẠT","KHÔNG ĐẠT"))) | Z16: 6.2 | AA16: 15 | AB16: =IFERROR(DEGREES(ATAN(Z16/AA16)),"") | AC16: =M16*COS(RADIANS(AB16)) | AD16: =M16*SIN(RADIANS(AB16)) | AE16: ='4.COC_DAN_HUONG'!$C$38 | AF16: ='4.COC_DAN_HUONG'!$C$39 | AG16: =IFERROR(AC16/AE16,"") | AH16: =IFERROR(AD16/AF16,"") | AI16: =IF(P16=0,"KHÔNG CÓ NEO ĐÁY",IF(AND(AG16<=1,AH16<=1),"ĐẠT","KHÔNG ĐẠT — rút ngắn k.cách hoặc tăng D/L cọc")) | AJ16: =SQRT(Z16^2+AA16^2) | AK16: =P16*AJ16 | AL16: 20 | AM16: =AL16 | AN16: =O16*AM16 | AO16: =AK16+AN16
B17: BÈ 12 | C17: 4200 | D17: 256.5 | E17: 70 | F17: 58.3 | G17: 0 | H17: =ROUND(C17/'2.THONG_SO'!$C$27*'2.THONG_SO'!$C$26,0) | I17: =H17*'2.THONG_SO'!$C$25*SIN(RADIANS('2.THONG_SO'!$C$24)) | J17: =(E17+F17)/2*'2.THONG_SO'!$C$23 | K17: =0.5*'2.THONG_SO'!$C$19*('2.THONG_SO'!$C$20*I17*'2.THONG_SO'!$C$21+'2.THONG_SO'!$C$22*J17)*'2.THONG_SO'!$C$18^2/1000*'2.THONG_SO'!$C$28 | L17: 0.3 | M17: =K17*L17+'2.THONG_SO'!$C$32 | N17: =MAX(CEILING(D17/'2.THONG_SO'!$C$33,1),3) | O17: 9 | P17: 9 | Q17: =M17*'2.THONG_SO'!$C$31 | R17: PES-28 | S17: =IFERROR(LOOKUP(R17,{"PES-20";"PES-24";"PES-28";"PES-32";"PES-36";"PES-40";"PES-44"},{120;175;235;310;390;480;580}),"") | T17: =IFERROR(Q17/S17,"") | U17: =IF(T17="","THIẾU DỮ LIỆU",IF(T17<=1,"ĐẠT","KHÔNG ĐẠT")) | V17: Chưa tính chi tiết | W17: =IF(V17="BAN-1.0",'2.THONG_SO'!$C$38,IF(V17="BAN-1.4",'2.THONG_SO'!$C$39,IF(V17="BAN-1.8",'2.THONG_SO'!$C$40,""))) | X17: =IFERROR(M17*'2.THONG_SO'!$C$37/W17,"") | Y17: =IF(V17="Chưa tính chi tiết","CHƯA TÍNH",IF(X17="","CHƯA TÍNH",IF(X17<=1,"ĐẠT","KHÔNG ĐẠT"))) | Z17: 6.2 | AA17: 15 | AB17: =IFERROR(DEGREES(ATAN(Z17/AA17)),"") | AC17: =M17*COS(RADIANS(AB17)) | AD17: =M17*SIN(RADIANS(AB17)) | AE17: ='4.COC_DAN_HUONG'!$C$38 | AF17: ='4.COC_DAN_HUONG'!$C$39 | AG17: =IFERROR(AC17/AE17,"") | AH17: =IFERROR(AD17/AF17,"") | AI17: =IF(P17=0,"KHÔNG CÓ NEO ĐÁY",IF(AND(AG17<=1,AH17<=1),"ĐẠT","KHÔNG ĐẠT — rút ngắn k.cách hoặc tăng D/L cọc")) | AJ17: =SQRT(Z17^2+AA17^2) | AK17: =P17*AJ17 | AL17: 20 | AM17: =AL17 | AN17: =O17*AM17 | AO17: =AK17+AN17
B18: BÈ 13 | C18: 3500 | D18: 272.5 | E18: 100.1 | F18: 36.2 | G18: 64 | H18: =ROUND(C18/'2.THONG_SO'!$C$27*'2.THONG_SO'!$C$26,0) | I18: =H18*'2.THONG_SO'!$C$25*SIN(RADIANS('2.THONG_SO'!$C$24)) | J18: =(E18+F18)/2*'2.THONG_SO'!$C$23 | K18: =0.5*'2.THONG_SO'!$C$19*('2.THONG_SO'!$C$20*I18*'2.THONG_SO'!$C$21+'2.THONG_SO'!$C$22*J18)*'2.THONG_SO'!$C$18^2/1000*'2.THONG_SO'!$C$28 | L18: 0.327 | M18: =K18*L18+'2.THONG_SO'!$C$32 | N18: =MAX(CEILING(D18/'2.THONG_SO'!$C$33,1),3) | O18: 14 | P18: 5 | Q18: =M18*'2.THONG_SO'!$C$31 | R18: PES-28 | S18: =IFERROR(LOOKUP(R18,{"PES-20";"PES-24";"PES-28";"PES-32";"PES-36";"PES-40";"PES-44"},{120;175;235;310;390;480;580}),"") | T18: =IFERROR(Q18/S18,"") | U18: =IF(T18="","THIẾU DỮ LIỆU",IF(T18<=1,"ĐẠT","KHÔNG ĐẠT")) | V18: Chưa tính chi tiết | W18: =IF(V18="BAN-1.0",'2.THONG_SO'!$C$38,IF(V18="BAN-1.4",'2.THONG_SO'!$C$39,IF(V18="BAN-1.8",'2.THONG_SO'!$C$40,""))) | X18: =IFERROR(M18*'2.THONG_SO'!$C$37/W18,"") | Y18: =IF(V18="Chưa tính chi tiết","CHƯA TÍNH",IF(X18="","CHƯA TÍNH",IF(X18<=1,"ĐẠT","KHÔNG ĐẠT"))) | Z18: 6.2 | AA18: 15 | AB18: =IFERROR(DEGREES(ATAN(Z18/AA18)),"") | AC18: =M18*COS(RADIANS(AB18)) | AD18: =M18*SIN(RADIANS(AB18)) | AE18: ='4.COC_DAN_HUONG'!$C$38 | AF18: ='4.COC_DAN_HUONG'!$C$39 | AG18: =IFERROR(AC18/AE18,"") | AH18: =IFERROR(AD18/AF18,"") | AI18: =IF(P18=0,"KHÔNG CÓ NEO ĐÁY",IF(AND(AG18<=1,AH18<=1),"ĐẠT","KHÔNG ĐẠT — rút ngắn k.cách hoặc tăng D/L cọc")) | AJ18: =SQRT(Z18^2+AA18^2) | AK18: =P18*AJ18 | AL18: 20 | AM18: =AL18 | AN18: =O18*AM18 | AO18: =AK18+AN18
B19: TỔNG | C19: =SUM(C6:C18) | N19: =SUM(N6:N18) | O19: =SUM(O6:O18) | P19: =SUM(P6:P18) | AK19: =SUM(AK6:AK18) | AN19: =SUM(AN6:AN18) | AO19: =SUM(AO6:AO18)
B21: Hệ số tập trung = T max / F, lấy từ mô hình phân bố lực chi tiết. Bè có ít dây chịu tải thì hệ số cao.
B22: A chiếu phao dùng bề rộng trung bình (Dài + Rộng)/2 — đơn giản hóa so với bản chi tiết.
B24: GHI CHÚ (cột Z→AO — thêm để tùy biến khoảng cách bè↔cọc và kiểm tra neo đáy):
B25: - Cột AA (vàng) = khoảng cách bè→cọc NEO ĐÁY do bạn tự bố trí. Đổi số này để dò khoảng cách gần nhất mà cột AI vẫn ra ĐẠT.
B26: - Góc dây (AB) = arctan(Độ sâu nước Z / khoảng cách AA) → khoảng cách càng ngắn, góc càng dốc, lực nhổ Tv (AD) càng lớn.
B27: - Sức chịu cọc (AE, AF) lấy cố định từ sheet 4 (Cách 1, D=0,35m, L=8m dùng chung). Nếu đổi tiết diện/chiều dài cọc thì sửa ở sheet 4 mục C.
B28: - Cột AJ, AK, AN, AO dùng để lấy tổng mét dây neo cần đặt hàng theo khoảng cách bạn đã chọn (không cộng hao phí buộc đầu/tăng đơ).
B29: - Bè 1 (dòng 6): công thức Y6 (KT NEO ĐÁY gốc) vẫn lấy từ sheet 7.BE01_CHI_TIET (khoảng cách thực 13,5 m theo bản vẽ). Cột AI ở đây là công cụ thử khoảng cách khác, độc lập với sheet 7.

Sheet 4.COC_DAN_HUONG
B2: CỌC ĐÓNG — CÔNG CỤ TÍNH CHUNG (dùng cho MỌI bè)
B3: Toàn bộ hệ neo dùng CỌC ĐÓNG. Nhập T max của bè đang tính vào ô C6, đổi kích thước cọc để tìm phương án đạt.
B5: A. TẢI TRỌNG ĐẦU VÀO
B6: Lực dây lớn nhất T (nhập cho bè đang xét) | C6: 59.3 | D6: kN | E6: VD: lấy từ sheet 3 cột M hoặc sheet chi tiết bè
B7: Hệ số an toàn cọc | C7: ='2.THONG_SO'!C37 | D7: -
B9: B. CỌC NEO BỜ (đóng trên đất bờ, tay đòn nhỏ)
B10: Cọc trên bờ không di chuyển theo mực nước. Cáp buộc gần sát mặt đất — tay đòn nhỏ, không cần vòng trượt.
B11: cu ĐẤT BỜ | C11: ='2.THONG_SO'!C41 | D11: kPa
B12: Tay đòn e | C12: 0.5 | D12: m
B13: Cạnh cọc D | C13: 0.45 | D13: m
B14: Chiều sâu ngàm L | C14: 6.5 | D14: m
B15: g = L − 1,5D | C15: =C14-1.5*C13 | D15: m
B16: A | C16: =0.02778/(C11*C13) | D16: -
B17: B | C17: =C12+1.5*C13+0.5*C15 | D17: -
B18: C | C18: =-2.25*C13*C11*C15^2 | D18: -
B19: Hu (sức chịu cực hạn) | C19: =(-C17+SQRT(C17^2-4*C16*C18))/(2*C16) | D19: kN
B20: Sức chịu cho phép | C20: =C19/C7 | D20: kN
B21: Hệ số sử dụng | C21: =C6/C20 | D21: -
B22: KIỂM TRA NGANG | C22: =IF(C21<=1,"ĐẠT","KHÔNG ĐẠT — tăng L hoặc D")
B23: Mômen lớn nhất | C23: =C6*(C12+1.5*C13+0.5*C6/(9*C11*C13)) | D23: kNm
B24: Kiểm tra tiết diện | C24: =C23/(0.9*14500*C13^3/6) | D24: -
B25: KIỂM TRA TIẾT DIỆN | C25: =IF(C24<=1,"ĐẠT","KHÔNG ĐẠT — tăng D")
B26: Chiều dài cọc đặt hàng | C26: =C14+1.5 | D26: m
B28: C. CỌC NEO LÒNG HỒ — CÁCH 1 (đỉnh cọc ở đáy hồ, cần thợ lặn)
B29: Cáp nối ngay đỉnh cọc dưới nước, tay đòn xấp xỉ 0. Cọc nhỏ nhất nhưng phải có thợ lặn khi thi công và bảo trì.
B30: cu ĐÁY HỒ | C30: ='2.THONG_SO'!C36 | D30: kPa
B31: Cạnh cọc D | C31: 0.35 | D31: m
B32: Chiều sâu ngàm L | C32: 8 | D32: m
B33: g = L − 1,5D | C33: =C32-1.5*C31 | D33: m
B34: A | C34: =0.02778/(C30*C31) | D34: -
B35: B | C35: =1.5*C31+0.5*C33 | D35: - | E35: tay đòn e = 0
B36: C | C36: =-2.25*C31*C30*C33^2 | D36: -
B37: Hu | C37: =(-C35+SQRT(C35^2-4*C34*C36))/(2*C34) | D37: kN
B38: Sức chịu NGANG cho phép | C38: =C37/C7 | D38: kN
B39: Sức chịu NHỔ cho phép | C39: =0.7*C30*4*C31*C32/2 | D39: kN | E39: ma sát thân cọc, FS=2,0
B40: Hệ số sử dụng (giả thiết cáp ~ngang) | C40: =C6/C38 | D40: -
B41: KIỂM TRA CÁCH 1 | C41: =IF(C40<=1,"ĐẠT","KHÔNG ĐẠT — tăng D hoặc L")
B42: Chiều dài cọc (nhô 1,0 m) | C42: =C32+1 | D42: m
B44: D. CỌC NEO LÒNG HỒ — CÁCH 2 (đỉnh cọc trên MNCN, qua vòng trượt)
B45: Không cần thợ lặn nhưng tay đòn lớn — cọc to và dài hơn nhiều. Chỉ chọn khi bắt buộc tránh thợ lặn.
...

Sheet 5.TOA_DO_NEO
B2: TỌA ĐỘ MỎ NEO — DÙNG ĐỂ VẼ LẠI BẢN VẼ
B3: Nối (X bè, Y bè) với (X neo, Y neo) bằng đường thẳng = dây neo. Đơn vị mét, hệ tọa độ bản vẽ gốc.
B5: Bè | C5: Mã neo | D5: Loại | E5: X bè | F5: Y bè | G5: X neo | H5: Y neo | I5: Z neo | J5: Nhịp (m) | K5: Phương vị (°)
B6: BÈ 1 | C6: N1-01 | D6: NEO ĐÁY | E6: -226.12 | F6: 91.42 | G6: -211.93 | H6: 81.12 | I6: 376.8 | J6: =SQRT((G6-E6)^2+(H6-F6)^2) | K6: =MOD(DEGREES(ATAN2(G6-E6,H6-F6)),360)
B7: BÈ 1 | C7: N1-02 | D7: NEO BỜ | E7: -217.52 | F7: 103.25 | G7: -236.81 | H7: 75.64 | I7: 384.5 | J7: =SQRT((G7-E7)^2+(H7-F7)^2) | K7: =MOD(DEGREES(ATAN2(G7-E7,H7-F7)),360)
B8: BÈ 1 | C8: N1-03 | D8: NEO BỜ | E8: -208.93 | F8: 115.08 | G8: -242.11 | H8: 141.14 | I8: 384.5 | J8: =SQRT((G8-E8)^2+(H8-F8)^2) | K8: =MOD(DEGREES(ATAN2(G8-E8,H8-F8)),360)
B9: BÈ 1 | C9: N1-04 | D9: NEO BỜ | E9: -199.7 | F9: 122.92 | G9: -177.5 | H9: 146.69 | I9: 384.5 | J9: =SQRT((G9-E9)^2+(H9-F9)^2) | K9: =MOD(DEGREES(ATAN2(G9-E9,H9-F9)),360)
B10: BÈ 1 | C10: N1-05 | D10: NEO BỜ | E10: -187.88 | F10: 114.33 | G10: -170.74 | H10: 140.52 | I10: 384.5 | J10: =SQRT((G10-E10)^2+(H10-F10)^2) | K10: =MOD(DEGREES(ATAN2(G10-E10,H10-F10)),360)
B11: BÈ 1 | C11: N1-06 | D11: NEO BỜ | E11: -176.05 | F11: 105.73 | G11: -162.49 | H11: 134.77 | I11: 384.5 | J11: =SQRT((G11-E11)^2+(H11-F11)^2) | K11: =MOD(DEGREES(ATAN2(G11-E11,H11-F11)),360)
B12: BÈ 1 | C12: N1-07 | D12: NEO BỜ | E12: -164.22 | F12: 97.14 | G12: -141.23 | H12: 99.78 | I12: 384.5 | J12: =SQRT((G12-E12)^2+(H12-F12)^2) | K12: =MOD(DEGREES(ATAN2(G12-E12,H12-F12)),360)
B13: BÈ 1 | C13: N1-08 | D13: NEO BỜ | E13: -152.39 | F13: 88.55 | G13: -140.05 | H13: 95.47 | I13: 384.5 | J13: =SQRT((G13-E13)^2+(H13-F13)^2) | K13: =MOD(DEGREES(ATAN2(G13-E13,H13-F13)),360)
B14: BÈ 1 | C14: N1-09 | D14: NEO BỜ | E14: -140.56 | F14: 79.95 | G14: -134.99 | H14: 90.48 | I14: 384.5 | J14: =SQRT((G14-E14)^2+(H14-F14)^2) | K14: =MOD(DEGREES(ATAN2(G14-E14,H14-F14)),360)
B15: BÈ 1 | C15: N1-10 | D15: NEO ĐÁY | E15: -128.73 | F15: 71.36 | G15: -114.55 | H15: 61.05 | I15: 376.8 | J15: =SQRT((G15-E15)^2+(H15-F15)^2) | K15: =MOD(DEGREES(ATAN2(G15-E15,H15-F15)),360)
B16: BÈ 1 | C16: N1-11 | D16: NEO ĐÁY | E16: -137.33 | F16: 59.53 | G16: -123.14 | H16: 49.22 | I16: 376.8 | J16: =SQRT((G16-E16)^2+(H16-F16)^2) | K16: =MOD(DEGREES(ATAN2(G16-E16,H16-F16)),360)
B17: BÈ 1 | C17: N1-12 | D17: NEO ĐÁY | E17: -145.92 | F17: 47.7 | G17: -131.73 | H17: 37.39 | I17: 376.8 | J17: =SQRT((G17-E17)^2+(H17-F17)^2) | K17: =MOD(DEGREES(ATAN2(G17-E17,H17-F17)),360)
... B304: BÈ 13 | C304: N13-19 | D304: NEO ĐÁY | E304: 120.63 | F304: 306.9 | G304: 112.94 | H304: 291.14 | I304: 376.8 | J304: =SQRT((G304-E304)^2+(H304-F304)^2) | K304: =MOD(DEGREES(ATAN2(G304-E304,H304-F304)),360)
C306: TỔNG | D306: =COUNTA(C6:C304)
C307: NEO BỜ | D307: =COUNTIF(D6:D304,"NEO BỜ")
C308: NEO ĐÁY | D308: =COUNTIF(D6:D304,"NEO ĐÁY")

Sheet 7.BE01_CHI_TIET
B2: BÈ 01 — TÍNH THEO BẢN VẼ CHI TIẾT CT-BP01
B3: Số liệu đo trực tiếp từ mặt cắt trên bản vẽ, thay cho số suy từ mặt bằng tổng thể.
B5: A. HÌNH HỌC (đo từ bản vẽ) | H5: HÌNH A — MẶT BẰNG HỆ NEO BÈ 01
B6: Chiều dài L | C6: 90 | D6: m | E6: Bản vẽ CT-BP01
B7: Chiều rộng W | C7: 41 | D7: m | E7: Bản vẽ CT-BP01
B8: Diện tích | C8: =C6*C7 | D8: m2 | E8: → ô C6 (chiều dài l) x ô C7 (chiều rộng w) — đọc từ bản vẽ CT-BP01
B9: Chu vi | C9: =2*(C6+C7) | D9: m | E9: → 2 x (ô C6 + ô C7) — chu vi hình chữ nhật
B10: Số tấm pin | C10: 790 | D10: tấm | E10: Đọc từ bảng kê số lượng tấm pin trên bản vẽ CT-BP01
B11: Độ sâu nước dưới bè | C11: 6 | D11: m | E11: Mặt cắt 1 và 2
B12: Cao trình đáy tại bè | C12: ='2.THONG_SO'!C5-C11 | D12: m | E12: → 2.thong_so ô C5 (mndbt) − Ô C11 (độ sâu nước tại bè)
B13: MN thấp nhất cho bè này | C13: =C12+'2.THONG_SO'!C9 | D13: m | E13: Đáy + độ sâu tối thiểu
B15: B. BỐN CẠNH — ĐỐI TƯỢNG VÀ KHOẢNG CÁCH
B16: Cạnh dài Nam (90 m) | C16: 17.1 | D16: m | E16: BỜ | F16: =IF(E16="BỜ",IF(C16<=50,"NEO BỜ","NEO ĐÁY"),"NEO ĐÁY")
B17: Cạnh dài Bắc (90 m) | C17: 33.2 | D17: m | E17: BỜ | F17: =IF(E17="BỜ",IF(C17<=50,"NEO BỜ","NEO ĐÁY"),"NEO ĐÁY")
B18: Cạnh ngắn Đông (41 m) | C18: 44.2 | D18: m | E18: BỜ | F18: =IF(E18="BỜ",IF(C18<=50,"NEO BỜ","NEO ĐÁY"),"NEO ĐÁY")
B19: Cạnh ngắn Tây (41 m) | C19: 27 | D19: m | E19: BÈ 02 | F19: =IF(E19="BỜ",IF(C19<=50,"NEO BỜ","NEO ĐÁY"),"NEO ĐÁY")
B21: C. SỐ DÂY VÀ CÁP
B22: Số dây mỗi cạnh dài | C22: 6 | D22: dây | E22: NHẬP theo kết quả dò tối ưu (không phải công thức Excel). Đã thử 4-2, 5-3, 6-3, 6-4, 7-4, 8-4 dây/cạnh, tính T max qua 24 hướng gió cho từng phương án: 4-2 dây→T=114 kN cần PES-36; 5-3→T=77 kN cần PES-28; 6-4→T=59 kN, PES-28 vừa đủ, thêm dây nữa (7-4, 8-4) T không giảm thêm. Chọn 6-4 vì ít dây nhất mà vẫn dùng PES-28.
B23: Số dây mỗi cạnh ngắn | C23: 4 | D23: dây | E23: NHẬP theo kết quả dò tối ưu (không phải công thức Excel). Đã thử 4-2, 5-3, 6-3, 6-4, 7-4, 8-4 dây/cạnh, tính T max qua 24 hướng gió cho từng phương án: 4-2 dây→T=114 kN cần PES-36; 5-3→T=77 kN cần PES-28; 6-4→T=59 kN, PES-28 vừa đủ, thêm dây nữa (7-4, 8-4) T không giảm thêm. Chọn 6-4 vì ít dây nhất mà vẫn dùng PES-28.
B24: Tổng số dây | C24: =2*C22+2*C23 | D24: dây | E24: → 2 x ô C22 (dây/cạnh dài) + 2 x ô C23 (dây/cạnh ngắn)
B25: Số dây NEO BỜ | C25: =2*C22+C23 | D25: dây | E25: 3 cạnh neo bờ: 2 cạnh dài + 1 cạnh ngắn Đông = 2xC22 + C23
B26: Số dây NEO ĐÁY | C26: =C23 | D26: dây | E26: Cạnh ngắn Tây (giáp bè 02) toàn bộ là neo đáy = Ô C23
B27: Lực môi trường lớn nhất | C27: 196.7 | D27: kN | E27: Tính qua 24 hướng
B28: Hệ số tập trung lực | C28: 0.276 | D28: - | E28: T max / F, từ mô hình phân bố
B29: T max | C29: =C27*C28+'2.THONG_SO'!C32 | D29: kN | E29: → ô C27 (lực môi trường max) x ô C28 (hệ số tập trung) + 2.thong_so ô C32 (lực căng trước t0)
B30: MBL yêu cầu | C30: =C29*'2.THONG_SO'!C31 | D30: kN | E30: → ô C29 (t max) x 2.thong_so ô C31 (hệ số an toàn cáp fs=3,0)
B31: Cáp chọn | C31: PES-28 | D31: - | E31: MBL 235 kN
B32: MBL cáp | C32: 235 | D32: kN | E32: Tra theo mã cáp đã chọn ở ô C31 (PES-28 → MBL 235 kN), không phải công thức tự động
B33: Hệ số sử dụng cáp | C33: =C30/C32 | D33: - | E33: → ô C30 (mbl yêu cầu) chia ô C32 (mbl cáp đã chọn)
B34: KIỂM TRA CÁP | C34: =IF(C33<=1,"ĐẠT","KHÔNG ĐẠT") | E34: ĐẠT khi Ô C33 (hệ số sử dụng cáp) ≤ 1
B35: Chuyển vị bè | C35: 0.254 | D35: m | E35: NHẬP — cùng nguồn với ô C28 (Hệ số tập trung lực), từ mô hình phân bố lực chi tiết ngoài Excel (20 dây, 24 hướng gió). Công thức gốc: u = F_bất_lợi / SUM(ki x cosi^2), voi ki = EA/Li (do cung tung day, A tiet dien day, Li chieu dai day), cosi = hinh chieu goc day so voi huong gio bat loi. Sheet rut gon nay KHONG liet ke tung day nen KHONG tinh lai duoc bang cong thuc Excel — phai chay lai mo hinh (Python hoac ky su) neu doi so day/vi tri.
B37: D. CỌC NEO BỜ
B38: Cao trình đỉnh cọc | C38: ='2.THONG_SO'!C6+0.5 | D38: m | E38: MNCN + 0,5 m
B39: Cọc lùi vào bờ so với mép MNDBT | C39: =('2.THONG_SO'!C6+0.5-'2.THONG_SO'!C5)*'2.THONG_SO'!C12 | D39: m | E39: → (cao trình đỉnh cọc − MNDBT) x độ dốc bờ — cả hai lấy từ 2.THONG_SO))
B40: Tay đòn e | C40: 0.5 | D40: m | E40: Cáp buộc sát mặt đất
B41: Lực ngang mỗi cọc H | C41: =C29 | D41: kN | E41: Cáp gần như nằm ngang
B42: Cạnh cọc D | C42: 0.45 | D42: m
B43: Chiều sâu ngàm L | C43: 6.5 | D43: m
B44: g = L − 1,5D | C44: =C43-1.5*C42 | D44: m | E44: → ô C43 (ngàm l) − 1,5 x Ô C42 (cạnh D) — biến trung gian Broms
B45: A | C45: =0.02778/('2.THONG_SO'!C41*C42) | D45: - | E45: SỬA: trước dùng nhầm cu đáy hồ (C36). Nay dùng cu ĐẤT BỜ (2.THONG_SO ô C41 = 40 kPa) | H45: HÌNH B — HAI CÁCH ĐẶT ĐỈNH CỌC LÒNG HỒ
...
