Workbook

Sheet ThuyetMinh
A1: THUYẾT MINH TÍNH TOÁN HỆ NEO: CỌC KHOAN NHỒI VEN BỜ + ĐẾ BTCT VÍT XOẮN — HV-FPV-2026
A2: Dự án: Dự án Điện Mặt Trời Nổi Hồ Huổi Vanh
A4: File này có hai phần: 9 sheet đầu là KẾT QUẢ do web tính (dạng số); 4 sheet CT_… ở cuối là cùng phép tính đó dưới dạng CÔNG THỨC Excel — đổi ô nhập (tô vàng / ghi chữ NHẬP) là tự tính lại.
A6: 1. Phương án chốt
A7: Chủ đầu tư chốt ngày 12/10/2026: Cọc khoan nhồi D350 ven bờ + đế BTCT giữ bằng vít xoắn dưới đáy hồ.
A8: Hệ neo: 295 tuyến cáp tại 263 điểm neo = 231 cọc khoan nhồi ven bờ + 32 đế đáy hồ (cả 32 đế dùng chung cho hai dây của hai bè đối diện).
A9: Gió tính toán V = 20 m/s là cấp gió vận hành, THẤP HƠN gió tiêu chuẩn TCVN 2737:2023 vùng II-B (V ≈ 29,7 m/s, q0 = 0,54 kN/m²): áp lực gió chỉ bằng 45% mức tiêu chuẩn. Cáp, cọc và đế neo định cỡ ở cấp gió này CHƯA được kiểm tra với bão thiết kế; nhập V = 30 m/s ở Tab 2 để kiểm tra.
A10: Kết quả: 9/9 bè đạt; 231/231 cọc bờ đạt; 32/32 đế đạt.
A12: 2. Số liệu đầu vào và giả định
A13: Mực nước hồ: MNC 380,0 m; MNDB 384,5 m; MNLKT 386,0 m.
A14: Tấm pin: 2,701 m²/tấm, nghiêng 12°, hệ số cản 1,15, hệ số che chắn giữa các hàng 0,55; sóng và dòng chảy gộp bằng hệ số 1,05.
A15: Đất bờ (GIẢ ĐỊNH, chưa khảo sát): sét, c_u = 40 kPa. Bùn đáy hồ (GIẢ ĐỊNH): c_u = 20 kPa, γ' = 6 kN/m³.
... A61: Lớp bê tông bảo vệ cọc bờ tới đai chỉ 26–30 mm (tính với 50 mm tới tim thép chủ).

Sheet ThongSo
A1: THÔNG SỐ ĐẦU VÀO VÀ GIẢ ĐỊNH — HV-FPV-2026
A2: CHÚ Ý: Gió tính toán V = 20 m/s là cấp gió vận hành, THẤP HƠN gió tiêu chuẩn TCVN 2737:2023 vùng II-B (V ≈ 29,7 m/s, q0 = 0,54 kN/m²): áp lực gió chỉ bằng 45% mức tiêu chuẩn. Cáp, cọc và đế neo định cỡ ở cấp gió này CHƯA được kiểm tra với bão thiết kế; nhập V = 30 m/s ở Tab 2 để kiểm tra.
A4: NHÓM | B4: THÔNG SỐ | C4: GIÁ TRỊ | D4: ĐƠN VỊ | E4: NGUỒN / GHI CHÚ
A5: Gió | B5: Vận tốc gió tính toán V | C5: 20 | D5: m/s | E5: Chủ đầu tư chốt 08/10/2026
A6: Gió | B6: Khối lượng riêng không khí ρ | C6: 1.25 | D6: kg/m³
A7: Gió | B7: Áp lực gió q = 0,5ρV² | C7: 250 | D7: N/m²
A8: Gió | B8: Diện tích một tấm pin | C8: 2.701 | D8: m²
A9: Gió | B9: Góc nghiêng tấm pin | C9: 12 | D9: °
A10: Gió | B10: Hệ số cản tấm pin C_d | C10: 1.15
A11: Gió | B11: Hệ số che chắn giữa các hàng | C11: 0.55 | E11: GIẢ ĐỊNH
A12: Gió | B12: Hệ số gộp sóng + dòng chảy | C12: 1.05 | E12: DNV-ST-0119, TCVN 6170-3
A13: Mực nước | B13: MNC | C13: 380 | D13: m
A14: Mực nước | B14: MNDB | C14: 384.5 | D14: m
A15: Mực nước | B15: MNLKT | C15: 386 | D15: m
A16: Dây neo | B16: Số dây làm việc n | C16: 6 | D16: dây | E16: GIẢ ĐỊNH, như nhau cho mọi bè
A17: Dây neo | B17: Góc dây so với phương ngang α | C17: 30 | D17: ° | E17: GIẢ ĐỊNH
A18: Dây neo | B18: Lực căng trước T_0 | C18: 5 | D18: kN
A19: Dây neo | B19: Hệ số an toàn cáp (nguyên vẹn / đứt một dây) | C19: 3 / 2
A20: Cọc bờ | B20: Loại cọc | C20: Cọc khoan nhồi tròn, đổ tại chỗ
A21: Cọc bờ | B21: Đường kính D | C21: 0.35 | D21: m
A22: Cọc bờ | B22: Chiều sâu ngàm thiết kế L_tk | C22: 6.5 | D22: m
A23: Cọc bờ | B23: Điểm móc cáp cách mặt đất e | C23: 0.1 | D23: m | E23: Yêu cầu thi công
A24: Cọc bờ | B24: c_u đất bờ | C24: 40 | D24: kPa | E24: GIẢ ĐỊNH, chưa khảo sát
A25: Cọc bờ | B25: Hệ số an toàn chịu ngang (Broms) | C25: 2.5
A26: Cọc bờ | B26: Hệ số tải trọng khi kiểm tra uốn | C26: 1.2 | E26: TCVN 2737
A27: Cọc bờ | B27: Cường độ bê tông R_b | C27: 14.5 | D27: MPa
A28: Đế BTCT | B28: Chiều dày đế t (nhỏ nhất) | C28: 0.4 | D28: m | E28: Cạnh B tự tăng 0,25 m cho tới khi đạt
A29: Đế BTCT | B29: Trọng lượng riêng bê tông / nước | C29: 25 / 10 | D29: kN/m³ | E29: W' = V × (γ_bt − γ_n): đã trừ đẩy nổi
A30: Đế BTCT | B30: Hệ số trọng lượng khi chống nhổ | C30: 0.9 | E30: GIẢ ĐỊNH
A31: Đế BTCT | B31: Chiều cao tai neo trên mặt đế | C31: 0.15 | D31: m
A32: Đế BTCT | B32: Chiều cao bích bè trên mặt nước | C32: 0.35 | D32: m | E32: Mạn khô của phao
A33: Đế BTCT | B33: Gờ chống trượt dưới đế | C33: 0.15 | D33: m
A34: Đế BTCT | B34: c_u bùn đáy hồ | C34: 20 | D34: kPa | E34: GIẢ ĐỊNH, chưa khảo sát
A35: Đế BTCT | B35: γ' bùn | C35: 6 | D35: kN/m³ | E35: GIẢ ĐỊNH
A36: Đế BTCT | B36: Hệ số bám dính đáy đế α | C36: 0.5 | E36: GIẢ ĐỊNH
A37: Đế BTCT | B37: Hệ số an toàn trượt / lật / nền | C37: 1.5 / 1.5 / 2.5
A38: Vít xoắn | B38: Số vít mỗi đế | C38: 4 | D38: cây
A39: Vít xoắn | B39: Ống thép Ø × dày | C39: Ø89 × 5 | D39: mm
A40: Vít xoắn | B40: Đường kính ren | C40: 105 | D40: mm
A41: Vít xoắn | B41: Chiều dài ngàm trong bùn | C41: 3 | D41: m
...

Sheet LucDay
A1: LỰC GIÓ VÀ LỰC CĂNG DÂY TỪNG BÈ — HV-FPV-2026
A2: CHÚ Ý: Gió tính toán V = 20 m/s là cấp gió vận hành, THẤP HƠN gió tiêu chuẩn TCVN 2737:2023 vùng II-B (V ≈ 29,7 m/s, q0 = 0,54 kN/m²): áp lực gió chỉ bằng 45% mức tiêu chuẩn. Cáp, cọc và đế neo định cỡ ở cấp gió này CHƯA được kiểm tra với bão thiết kế; nhập V = 30 m/s ở Tab 2 để kiểm tra.
A3: F_pin = q × C_d × (số tấm × A_tấm × sin nghiêng) × che chắn | F = (F_pin + F_phao) × hệ số sóng, dòng chảy | T = max(F × k + T_0 ; F / (n × cos α) + T_0)
A5: BÈ | B5: Diện tích (m²) | C5: Chu vi (m) | D5: Số dây | E5: Dây bờ | F5: Dây đáy | G5: Số tấm pin | H5: A đón gió (m²) | I5: q (N/m²) | J5: F pin (kN) | K5: F phao (kN) | L5: F gió (kN) | M5: F tổng (kN) | N5: Hệ số tập trung k | O5: T cách k (kN) | P5: T cách n dây (kN) | Q5: Cách chi phối | R5: T dây (kN) | S5: T khi đứt 1 dây (kN) | T5: Cáp | U5: Lực đứt (kN) | V5: HSAT cáp | W5: HSAT khi đứt 1 dây | X5: KẾT LUẬN BÈ
A6: BÈ 1 | B6: 4222 | C6: 280.7 | D6: 19 | E6: 17 | F6: 2 | G6: 808 | H6: 453.7 | I6: 250 | J6: 71.8 | K6: 6.8 | L6: 78.5 | M6: 82.4 | N6: 0.306 | O6: 30.2 | P6: 20.9 | Q6: Hệ số tập trung | R6: 30.2 | S6: 38.5 | T6: PES-28 | U6: 235 | V6: 7.77 | W6: 6.1 | X6: ĐẠT
A7: BÈ 2 | B7: 4115 | C7: 287.5 | D7: 20 | E7: 15 | F7: 5 | G7: 788 | H7: 442.5 | I7: 250 | J7: 70 | K7: 6.9 | L7: 76.9 | M7: 80.7 | N7: 0.282 | O7: 27.8 | P7: 20.5 | Q7: Hệ số tập trung | R7: 27.8 | S7: 35.3 | T7: PES-28 | U7: 235 | V7: 8.46 | W7: 6.66 | X7: ĐẠT
A8: BÈ 3 | B8: 5575 | C8: 312 | D8: 22 | E8: 15 | F8: 7 | G8: 1068 | H8: 599.8 | I8: 250 | J8: 94.8 | K8: 7.5 | L8: 102.3 | M8: 107.5 | N8: 0.313 | O8: 38.6 | P8: 25.7 | Q8: Hệ số tập trung | R8: 38.6 | S8: 49.7 | T8: PES-28 | U8: 235 | V8: 6.08 | W8: 4.72 | X8: ĐẠT
A9: BÈ 3A | B9: 19103 | C9: 625.1 | D9: 50 | E9: 31 | F9: 19 | G9: 3657 | H9: 2053.7 | I9: 250 | J9: 324.7 | K9: 15 | L9: 339.8 | M9: 356.8 | N9: 0.155 | O9: 60.3 | P9: 73.7 | Q9: Chia n dây | R9: 73.7 | S9: 87.4 | T9: PES-28 | U9: 235 | V9: 3.19 | W9: 2.69 | X9: ĐẠT
A10: BÈ 5A | B10: 23037 | C10: 660.2 | D10: 49 | E10: 36 | F10: 13 | G10: 4410 | H10: 2476.5 | I10: 250 | J10: 391.6 | K10: 15.9 | L10: 407.5 | M10: 427.9 | N10: 0.144 | O10: 66.6 | P10: 87.3 | Q10: Chia n dây | R10: 87.3 | S10: 103.8 | T10: PES-32 | U10: 305 | V10: 3.49 | W10: 2.94 | X10: ĐẠT
A11: BÈ 6 | B11: 9714 | C11: 442.7 | D11: 31 | E11: 28 | F11: 3 | G11: 1860 | H11: 1044.5 | I11: 250 | J11: 165.2 | K11: 10.7 | L11: 175.8 | M11: 184.6 | N11: 0.194 | O11: 40.8 | P11: 40.5 | Q11: Hệ số tập trung | R11: 40.8 | S11: 52.6 | T11: PES-28 | U11: 235 | V11: 5.76 | W11: 4.47 | X11: ĐẠT
A12: BÈ 7 | B12: 11143 | C12: 474.4 | D12: 33 | E12: 24 | F12: 9 | G12: 2133 | H12: 1197.8 | I12: 250 | J12: 189.4 | K12: 11.4 | L12: 200.8 | M12: 210.9 | N12: 0.164 | O12: 39.6 | P12: 45.6 | Q12: Chia n dây | R12: 45.6 | S12: 53.7 | T12: PES-28 | U12: 235 | V12: 5.16 | W12: 4.38 | X12: ĐẠT
A13: BÈ 8 | B13: 14946 | C13: 573.6 | D13: 51 | E13: 46 | F13: 5 | G13: 2861 | H13: 1606.7 | I13: 250 | J13: 254.1 | K13: 13.8 | L13: 267.9 | M13: 281.3 | N13: 0.106 | O13: 34.8 | P13: 59.1 | Q13: Chia n dây | R13: 59.1 | S13: 70 | T13: PES-28 | U13: 235 | V13: 3.97 | W13: 3.36 | X13: ĐẠT
A14: BÈ 9 | B14: 4018 | C14: 293 | D14: 20 | E14: 19 | F14: 1 | G14: 769 | H14: 431.8 | I14: 250 | J14: 68.3 | K14: 7.1 | L14: 75.3 | M14: 79.1 | N14: 0.327 | O14: 30.9 | P14: 20.2 | Q14: Hệ số tập trung | R14: 30.9 | S14: 39.4 | T14: PES-28 | U14: 235 | V14: 7.61 | W14: 5.96 | X14: ĐẠT

Sheet CocKhoanNhoi_TheoBe
A1: TÍNH TOÁN CỌC KHOAN NHỒI VEN BỜ THEO BÈ — HV-FPV-2026
A2: CHÚ Ý: Gió tính toán V = 20 m/s là cấp gió vận hành, THẤP HƠN gió tiêu chuẩn TCVN 2737:2023 vùng II-B (V ≈ 29,7 m/s, q0 = 0,54 kN/m²): áp lực gió chỉ bằng 45% mức tiêu chuẩn. Cáp, cọc và đế neo định cỡ ở cấp gió này CHƯA được kiểm tra với bão thiết kế; nhập V = 30 m/s ở Tab 2 để kiểm tra.
A3: BP-1 (Broms, đất sét c_u = 40 kPa): H_cho phép = H_u / 2.5 ≥ T | BP-2 (TCVN 5574:2018): γ × M_max ≤ M_rd | P_max: lực dây lớn nhất cọc chịu được ở L_tk. Thông số đất là GIẢ ĐỊNH.
A5: BÈ | B5: Số cọc | C5: D (m) | D5: L_tk (m) | E5: L cả cọc (m) | F5: Thép chủ | G5: Mác thép | H5: Cốt đai | I5: T dây (kN) | J5: H_u (kN) | K5: H cho phép (kN) | L5: BP-1 ngang | M5: M_max (kNm) | N5: γ × M_max (kNm) | O5: M_rd (kNm) | P5: BP-2 uốn | Q5: P_max (kN) | R5: Bê tông 1 cọc (m³) | S5: Thép 1 cọc (kg) | T5: Tổng dài (m) | U5: Tổng bê tông (m³) | V5: Tổng thép (kg) | W5: KẾT LUẬN
A6: BÈ 1 | B6: 17 | C6: 0.35 | D6: 6.5 | E6: 6.6 | F6: 4Φ25 | G6: CB400-V | H6: Đai xoắn Φ8 a150 | I6: 30.2 | J6: 290.2 | K6: 116.1 | L6: 0.26 | M6: 22.5 | N6: 27 | O6: 43 | P6: 0.63 | Q6: 44.6 | R6: 0.635 | S6: 117.9 | T6: 112.2 | U6: 10.8 | V6: 2005 | W6: ĐẠT
A7: BÈ 2 | B7: 15 | C7: 0.35 | D7: 6.5 | E7: 6.6 | F7: 4Φ25 | G7: CB400-V | H7: Đai xoắn Φ8 a150 | I7: 27.8 | J7: 290.2 | K7: 116.1 | L7: 0.24 | M7: 20.4 | N7: 24.5 | O7: 43 | P7: 0.57 | Q7: 44.6 | R7: 0.635 | S7: 117.9 | T7: 99 | U7: 9.5 | V7: 1769 | W7: ĐẠT
A8: BÈ 3 | B8: 15 | C8: 0.35 | D8: 6.5 | E8: 6.6 | F8: 4Φ25 | G8: CB400-V | H8: Đai xoắn Φ8 a150 | I8: 38.6 | J8: 290.2 | K8: 116.1 | L8: 0.33 | M8: 30.1 | N8: 36.1 | O8: 43 | P8: 0.84 | Q8: 44.6 | R8: 0.635 | S8: 117.9 | T8: 99 | U8: 9.5 | V8: 1769 | W8: ĐẠT
A9: BÈ 3A | B9: 31 | C9: 0.35 | D9: 6.5 | E9: 6.6 | F9: 6Φ28 | G9: CB400-V | H9: Đai xoắn Φ8 a150 | I9: 73.7 | J9: 290.2 | K9: 116.1 | L9: 0.64 | M9: 67.6 | N9: 81.1 | O9: 93.3 | P9: 0.87 | Q9: 81.9 | R9: 0.635 | S9: 207.6 | T9: 204.6 | U9: 19.7 | V9: 6436 | W9: ĐẠT
A10: BÈ 5A | B10: 36 | C10: 0.35 | D10: 6.5 | E10: 6.6 | F10: 6Φ32 | G10: CB400-V | H10: Đai xoắn Φ8 a150 | I10: 87.3 | J10: 290.2 | K10: 116.1 | L10: 0.75 | M10: 84.9 | N10: 101.8 | O10: 121.9 | P10: 0.83 | Q10: 99.6 | R10: 0.635 | S10: 266.2 | T10: 237.6 | U10: 22.9 | V10: 9583 | W10: ĐẠT
A11: BÈ 6 | B11: 28 | C11: 0.35 | D11: 6.5 | E11: 6.6 | F11: 4Φ25 | G11: CB400-V | H11: Đai xoắn Φ8 a150 | I11: 40.8 | J11: 290.2 | K11: 116.1 | L11: 0.35 | M11: 32.1 | N11: 38.5 | O11: 43 | P11: 0.9 | Q11: 44.6 | R11: 0.635 | S11: 117.9 | T11: 184.8 | U11: 17.8 | V11: 3302 | W11: ĐẠT
A12: BÈ 7 | B12: 24 | C12: 0.35 | D12: 6.5 | E12: 6.6 | F12: 4Φ28 | G12: CB400-V | H12: Đai xoắn Φ8 a150 | I12: 45.6 | J12: 290.2 | K12: 116.1 | L12: 0.39 | M12: 36.7 | N12: 44.1 | O12: 53.9 | P12: 0.82 | Q12: 53.6 | R12: 0.635 | S12: 143.8 | T12: 158.4 | U12: 15.2 | V12: 3451 | W12: ĐẠT
A13: BÈ 8 | B13: 46 | C13: 0.35 | D13: 6.5 | E13: 6.6 | F13: 6Φ25 | G13: CB400-V | H13: Đai xoắn Φ8 a150 | I13: 59.1 | J13: 290.2 | K13: 116.1 | L13: 0.51 | M13: 50.8 | N13: 61 | O13: 74.4 | P13: 0.82 | Q13: 69 | R13: 0.635 | S13: 168.8 | T13: 303.6 | U13: 29.2 | V13: 7764 | W13: ĐẠT
A14: BÈ 9 | B14: 19 | C14: 0.35 | D14: 6.5 | E14: 6.6 | F14: 4Φ25 | G14: CB400-V | H14: Đai xoắn Φ8 a150 | I14: 30.9 | J14: 290.2 | K14: 116.1 | L14: 0.27 | M14: 23.1 | N14: 27.7 | O14: 43 | P14: 0.65 | Q14: 44.6 | R14: 0.635 | S14: 117.9 | T14: 125.4 | U14: 12.1 | V14: 2241 | W14: ĐẠT
A15: TỔNG | B15: 231 | T15: 1524.6 | U15: 146.7 | V15: 38320

Sheet CocKhoanNhoi_TungCoc
A1: THỐNG KÊ VÀ TÍNH TOÁN TỪNG CỌC KHOAN NHỒI VEN BỜ (231 CỌC) — HV-FPV-2026
A2: CHÚ Ý: Gió tính toán V = 20 m/s là cấp gió vận hành, THẤP HƠN gió tiêu chuẩn TCVN 2737:2023 vùng II-B (V ≈ 29,7 m/s, q0 = 0,54 kN/m²): áp lực gió chỉ bằng 45% mức tiêu chuẩn. Cáp, cọc và đế neo định cỡ ở cấp gió này CHƯA được kiểm tra với bão thiết kế; nhập V = 30 m/s ở Tab 2 để kiểm tra.
A3: Sức chịu của cọc không phụ thuộc vị trí (cùng giả định đất) nên BP-1, BP-2 lặp lại theo bè; riêng từng cọc là tọa độ, cao độ mặt đất (địa hình IFC), chiều dài dây và góc cáp ở hai mực nước.
A5: STT | B5: MÃ CỌC | C5: DÂY NEO | D5: BÈ | E5: NGUỒN GỐC | F5: X (m) | G5: Y (m) | H5: Cao độ mặt đất (m) | I5: D (m) | J5: L_tk (m) | K5: L cả cọc (m) | L5: Thép chủ | M5: Mác thép | N5: Cốt đai | O5: Bê tông (m³) | P5: Thép (kg) | Q5: Dây dài (m) | R5: Phương vị (°) | S5: T dây (kN) | T5: P_max (kN) | U5: BP-1 ngang | V5: BP-2 uốn | W5: Đầu cọc | X5: Góc cáp MNC (°) | Y5: Góc cáp MNLKT (°) | Z5: Mặt đất thấp hơn MNDB | AA5: KẾT LUẬN | AB5: GHI CHÚ
A6: 1 | B6: HV-P001 | C6: B1-D01 | D6: BÈ 1 | E6: Cọc đã định vị | F6: -134.99 | G6: 90.48 | H6: 384.29 | I6: 0.35 | J6: 6.5 | K6: 6.6 | L6: 4Φ25 | M6: CB400-V | N6: Đai xoắn Φ8 a150 | O6: 0.635 | P6: 117.9 | Q6: 12.64 | R6: 36 | S6: 30.2 | T6: 44.6 | U6: 0.26 | V6: 0.63 | W6: 1 | X6: -17.7 | Y6: 8.8 | Z6: CÓ | AA6: ĐẠT | AB6: Mặt đất tại cọc thấp hơn MNDB: thi công mùa nước thấp, có ống vách; Đầu cọc ngập khi hồ ở MNLKT: bản mã, tai neo cần chống gỉ
A7: 2 | B7: HV-P002 | C7: B1-D02 | D7: BÈ 1 | E7: Cọc đã định vị | F7: -140.05 | G7: 95.47 | H7: 384.37 | I7: 0.35 | J7: 6.5 | K7: 6.6 | L7: 4Φ25 | M7: CB400-V | N7: Đai xoắn Φ8 a150 | O7: 0.635 | P7: 117.9 | Q7: 13.7 | R7: 36 | S7: 30.2 | T7: 44.6 | U7: 0.26 | V7: 0.63 | W7: 1 | X7: -16.8 | Y7: 7.8 | Z7: CÓ | AA7: ĐẠT | AB7: Mặt đất tại cọc thấp hơn MNDB: thi công mùa nước thấp, có ống vách; Đầu cọc ngập khi hồ ở MNLKT: bản mã, tai neo cần chống gỉ
A8: 3 | B8: HV-P003 | C8: B1-D03 | D8: BÈ 1 | E8: Cọc đã định vị | F8: -141.23 | G8: 99.78 | H8: 384.33 | I8: 0.35 | J8: 6.5 | K8: 6.6 | L8: 4Φ25 | M8: CB400-V | N8: Đai xoắn Φ8 a150 | O8: 0.635 | P8: 117.9 | Q8: 16.49 | R8: 36 | S8: 30.2 | T8: 44.6 | U8: 0.26 | V8: 0.63 | W8: 1 | X8: -13.9 | Y8: 6.6 | Z8: CÓ | AA8: ĐẠT | AB8: Mặt đất tại cọc thấp hơn MNDB: thi công mùa nước thấp, có ống vách; Đầu cọc ngập khi hồ ở MNLKT: bản mã, tai neo cần chống gỉ
A9: 4 | B9: HV-P004 | C9: B1-D04 | D9: BÈ 1 | E9: Cọc đã định vị | F9: -162.49 | G9: 134.77 | H9: 384.41 | I9: 0.35 | J9: 6.5 | K9: 6.6 | L9: 4Φ25 | M9: CB400-V | N9: Đai xoắn Φ8 a150 | O9: 0.635 | P9: 117.9 | Q9: 32.3 | R9: 36 | S9: 30.2 | T9: 44.6 | U9: 0.26 | V9: 0.63 | W9: 1 | X9: -7.3 | Y9: 3.3 | Z9: CÓ | AA9: ĐẠT | AB9: Mặt đất tại cọc thấp hơn MNDB: thi công mùa nước thấp, có ống vách; Đầu cọc ngập khi hồ ở MNLKT: bản mã, tai neo cần chống gỉ
A10: 5 | B10: HV-P005 | C10: B1-D05 | D10: BÈ 1 | E10: Cọc đã định vị | F10: -170.74 | G10: 140.52 | H10: 384.59 | I10: 0.35 | J10: 6.5 | K10: 6.6 | L10: 4Φ25 | M10: CB400-V | N10: Đai xoắn Φ8 a150 | O10: 0.635 | P10: 117.9 | Q10: 32.11 | R10: 36 | S10: 30.2 | T10: 44.6 | U10: 0.26 | V10: 0.63 | W10: 1 | X10: -7.7 | Y10: 3 | Z10: không | AA10: ĐẠT | AB10: Đầu cọc ngập khi hồ ở MNLKT: bản mã, tai neo cần chống gỉ
A11: 6 | B11: HV-P006 | C11: B1-D06 | D11: BÈ 1 | E11: Cọc đã định vị | F11: -177.5 | G11: 146.69 | H11: 384.63 | I11: 0.35 | J11: 6.5 | K11: 6.6 | L11: 4Φ25 | M11: CB400-V | N11: Đai xoắn Φ8 a150 | O11: 0.635 | P11: 117.9 | Q11: 33.12 | R11: 36 | S11: 30.2 | T11: 44.6 | U11: 0.26 | V11: 0.63 | W11: 1 | X11: -7.5 | Y11: 2.8 | Z11: không | AA11: ĐẠT | AB11: Đầu cọc ngập khi hồ ở MNLKT: bản mã, tai neo cần chống gỉ
A12: 7 | B12: HV-P007 | C12: B1-D07 | D12: BÈ 1 | E12: Cọc đã định vị | F12: -224.88 | G12: 67.52 | H12: 384.25 | I12: 0.35 | J12: 6.5 | K12: 6.6 | L12: 4Φ25 | M12: CB400-V | N12: Đai xoắn Φ8 a150 | O12: 0.635 | P12: 117.9 | Q12: 12.78 | R12: 216 | S12: 30.2 | T12: 44.6 | U12: 0.26 | V12: 0.63 | W12: 1 | X12: -17.4 | Y12: 8.9 | Z12: CÓ | AA12: ĐẠT | AB12: Mặt đất tại cọc thấp hơn MNDB: thi công mùa nước thấp, có ống vách; Đầu cọc ngập khi hồ ở MNLKT: bản mã, tai neo cần chống gỉ
A13: 8 | B13: HV-P008 | C13: B1-D08 | D13: BÈ 1 | E13: Cọc đã định vị | F13: -216.19 | G13: 59.89 | H13: 384.47 | I13: 0.35 | J13: 6.5 | K13: 6.6 | L13: 4Φ25 | M13: CB400-V | N13: Đai xoắn Φ8 a150 | O13: 0.635 | P13: 117.9 | Q13: 13.84 | R13: 216 | S13: 30.2 | T13: 44.6 | U13: 0.26 | V13: 0.63 | W13: 1 | X13: -17 | Y13: 7.3 | Z13: CÓ | AA13: ĐẠT | AB13: Mặt đất tại cọc thấp hơn MNDB: thi công mùa nước thấp, có ống vách; Đầu cọc ngập khi hồ ở MNLKT: bản mã, tai neo cần chống gỉ
A14: 9 | B14: HV-P009 | C14: B1-D09 | D14: BÈ 1 | E14: Cọc đã định vị | F14: -195.7 | G14: 50.34 | H14: 384.17 | I14: 0.35 | J14: 6.5 | K14: 6.6 | L14: 4Φ25 | M14: CB400-V | N14: Đai xoắn Φ8 a150 | O14: 0.635 | P14: 117.9 | Q14: 9.52 | R14: 216 | S14: 30.2 | T14: 44.6 | U14: 0.26 | V14: 0.63 | W14: 1 | X14: -22.4 | Y14: 12.3 | Z14: CÓ | AA14: ĐẠT | AB14: Mặt đất tại cọc thấp hơn MNDB: thi công mùa nước thấp, có ống vách; Đầu cọc ngập khi hồ ở MNLKT: bản mã, tai neo cần chống gỉ
A15: 10 | B15: HV-P010 | C15: B1-D10 | D15: BÈ 1 | E15: Cọc đã định vị | F15: -185.52 | G15: 45.22 | H15: 384.69 | I15: 0.35 | J15: 6.5 | K15: 6.6 | L15: 4Φ25 | M15: CB400-V | N15: Đai xoắn Φ8 a150 | O15: 0.635 | P15: 117.9 | Q15: 7.68 | R15: 216 | S15: 30.2 | T15: 44.6 | U15: 0.26 | V15: 0.63 | W15: 1 | X15: -30 | Y15: 11.5 | Z15: không | AA15: ĐẠT | AB15: Đầu cọc ngập khi hồ ở MNLKT: bản mã, tai neo cần chống gỉ; Cáp chúc xuống dốc khi nước thấp: kiểm tra cáp không tì vào mặt đất / mũ cọc
A16: 11 | B16: HV-P011 | C16: B1-D11 | D16: BÈ 1 | E16: Cọc đã định vị | F16: -174.02 | G16: 38.02 | H16: 384.44 | I16: 0.35 | J16: 6.5 | K16: 6.6 | L16: 4Φ25 | M16: CB400-V | N16: Đai xoắn Φ8 a150 | O16: 0.635 | P16: 117.9 | Q16: 6.75 | R16: 216 | S16: 30.2 | T16: 44.6 | U16: 0.26 | V16: 0.63 | W16: 1 | X16: -31.8 | Y16: 15 | Z16: CÓ | AA16: ĐẠT | AB16: Mặt đất tại cọc thấp hơn MNDB: thi công mùa nước thấp, có ống vách; Đầu cọc ngập khi hồ ở MNLKT: bản mã, tai neo cần chống gỉ; Cáp chúc xuống dốc khi nước thấp: kiểm tra cáp không tì vào mặt đất / mũ cọc
A17: 12 | B17: HV-P012 | C17: B1-D12 | D17: BÈ 1 | E17: Cọc đã định vị | F17: -161.95 | G17: 30.54 | H17: 383.76 | I17: 0.35 | J17: 6.5 | K17: 6.6 | L17: 4Φ25 | M17: CB400-V | N17: Đai xoắn Φ8 a150 | O17: 0.635 | P17: 117.9 | Q17: 5.7 | R17: 216 | S17: 30.2 | T17: 44.6 | U17: 0.26 | V17: 0.63 | W17: 1 | X17: -31.6 | Y17: 23.6 | Z17: CÓ | AA17: ĐẠT | AB17: Mặt đất tại cọc thấp hơn MNDB: thi công mùa nước thấp, có ống vách; Đầu cọc ngập khi hồ ở MNLKT: bản mã, tai neo cần chống gỉ; Cáp chúc xuống dốc khi nước thấp: kiểm tra cáp không tì vào mặt đất / mũ cọc
... A236: 231 | B236: HV-P295 | C236: B9-D20 | D236: BÈ 9 | E236: Cọc mới (ven bờ) | F236: 130.67 | G236: 394.29 | H236: 384.02 | I236: 0.35 | J236: 6.5 | K236: 6.6 | L236: 4Φ25 | M236: CB400-V | N236: Đai xoắn Φ8 a150 | O236: 0.635 | P236: 117.9 | Q236: 14.5 | R236: 311 | S236: 30.9 | T236: 44.6 | U236: 0.27 | V236: 0.65 | W236: 1 | X236: -14.6 | Y236: 8.7 | Z236: CÓ | AA236: ĐẠT | AB236: Chuyển từ neo đáy sang cọc khoan nhồi (vị trí ven bờ); Mặt đất tại cọc thấp hơn MNDB: thi công mùa nước thấp, có ống vách; Đầu cọc ngập khi hồ ở MNLKT: bản mã, tai neo cần chống gỉ

Sheet DeNeoDay_TungDe
A1: THỐNG KÊ VÀ TÍNH TOÁN TỪNG ĐẾ NEO ĐÁY: ĐẾ BTCT + 4 VÍT XOẮN (32 ĐẾ) — HV-FPV-2026
A2: CHÚ Ý: Gió tính toán V = 20 m/s là cấp gió vận hành, THẤP HƠN gió tiêu chuẩn TCVN 2737:2023 vùng II-B (V ≈ 29,7 m/s, q0 = 0,54 kN/m²): áp lực gió chỉ bằng 45% mức tiêu chuẩn. Cáp, cọc và đế neo định cỡ ở cấp gió này CHƯA được kiểm tra với bão thiết kế; nhập V = 30 m/s ở Tab 2 để kiểm tra.
A3: Đế dùng chung hai dây: kiểm tra dây 1 căng + dây 2 ở lực căng trước, ngược lại, và cả hai cùng căng, ở MNC và MNLKT. SV-1: T_v ≤ 0.9W' + nQ_a | SV-2: 1.5T_h ≤ bám dính + gờ + nH_u | SV-3: 1.5M_lật ≤ M_giữ | SV-4: N_1 ≤ Q_a | SV-5: W'/B² ≤ 5,14c_u/2.5.
A5: STT | B5: MÃ ĐẾ | C5: DÂY 1 | D5: BÈ 1 | E5: T 1 (kN) | F5: Dài 1 (m) | G5: DÂY 2 | H5: BÈ 2 | I5: T 2 (kN) | J5: Dài 2 (m) | K5: X (m) | L5: Y (m) | M5: Cao độ đáy (m) | N5: Sâu nước MNC (m) | O5: Sâu nước MNLKT (m) | P5: Tổ hợp chi phối | Q5: T_h (kN) | R5: T_v (kN) | S5: B (m) | T5: t (m) | U5: V bê tông (m³) | V5: Nặng trên cạn (kN) | W5: W' trong nước (kN) | X5: Cẩu (tấn) | Y5: Lưới thép 2 lớp | Z5: Thép bản (kg) | AA5: Số vít | AB5: Vít Ø × dày | AC5: Dài 1 vít (m) | AD5: Sức chống nhổ (kN) | AE5: M_lật (kNm) | AF5: M_giữ (kNm) | AG5: N 1 vít (kN) | AH5: SV-1 nhổ | AI5: SV-2 trượt | AJ5: SV-3 lật | AK5: SV-4 một vít | AL5: SV-5 nền | AM5: SV-6 thép | AN5: KẾT LUẬN | AO5: GHI CHÚ
A6: 1 | B6: HV-DV001 | C6: B1-D15 | D6: BÈ 1 | E6: 30.2 | F6: 12.56 | G6: B2-D13 | H6: BÈ 2 | I6: 27.8 | J6: 12.57 | K6: -128.58 | L6: 44.11 | M6: 378.3 | N6: 1.7 | O6: 7.7 | P6: cả hai dây căng (MN cao) | Q6: 2.5 | R6: 29.7 | S6: 2.5 | T6: 0.4 | U6: 2.48 | V6: 62.5 | W6: 37.5 | X6: 6.4 | Y6: Ø12 a200 | Z6: 119 | AA6: 4 | AB6: Ø89×5 | AC6: 3.7 | AD6: 65.4 | AE6: 38.6 | AF6: 126 | AG6: 0 | AH6: 0.45 | AI6: 0.27 | AJ6: 0.46 | AK6: 0 | AL6: 0.15 | AM6: 0.62 | AN6: ĐẠT | AO6: Đế dùng chung hai bè: hai tai neo
A7: 2 | B7: HV-DV002 | C7: B1-D19 | D7: BÈ 1 | E7: 30.2 | F7: 11.3 | G7: B2-D20 | H7: BÈ 2 | I7: 27.8 | J7: 11.3 | K7: -138.58 | L7: 31.21 | M7: 378.3 | N7: 1.7 | O7: 7.7 | P7: cả hai dây căng (MN cao) | Q7: 2.1 | R7: 32.1 | S7: 2.5 | T7: 0.4 | U7: 2.48 | V7: 62.5 | W7: 37.5 | X7: 6.4 | Y7: Ø12 a200 | Z7: 119 | AA7: 4 | AB7: Ø89×5 | AC7: 3.7 | AD7: 65.4 | AE7: 41.2 | AF7: 126 | AG7: 0 | AH7: 0.49 | AI7: 0.27 | AJ7: 0.49 | AK7: 0 | AL7: 0.15 | AM7: 0.62 | AN7: ĐẠT | AO7: Đế dùng chung hai bè: hai tai neo
A8: 3 | B8: HV-DV003 | C8: B2-D12 | D8: BÈ 2 | E8: 27.8 | F8: 10.08 | G8: B3-D22 | H8: BÈ 3 | I8: 38.6 | J8: 10.07 | K8: -42.64 | L8: -28.74 | M8: 378.3 | N8: 1.7 | O8: 7.7 | P8: cả hai dây căng (MN cao) | Q8: 8.7 | R8: 39.7 | S8: 2.5 | T8: 0.4 | U8: 2.48 | V8: 62.5 | W8: 37.5 | X8: 6.4 | Y8: Ø12 a200 | Z8: 119 | AA8: 4 | AB8: Ø89×5 | AC8: 3.7 | AD8: 65.4 | AE8: 54.4 | AF8: 126 | AG8: 2.59 | AH8: 0.61 | AI8: 0.36 | AJ8: 0.65 | AK8: 0.33 | AL8: 0.15 | AM8: 0.62 | AN8: ĐẠT | AO8: Đế dùng chung hai bè: hai tai neo
A9: 4 | B9: HV-DV004 | C9: B2-D17 | D9: BÈ 2 | E9: 27.8 | F9: 9.01 | G9: B3-D17 | H9: BÈ 3 | I9: 38.6 | J9: 9.02 | K9: -48.54 | L9: -35.03 | M9: 378.3 | N9: 1.7 | O9: 7.7 | P9: cả hai dây căng (MN cao) | Q9: 8.4 | R9: 42.5 | S9: 2.5 | T9: 0.4 | U9: 2.48 | V9: 62.5 | W9: 37.5 | X9: 6.4 | Y9: Ø12 a200 | Z9: 119 | AA9: 4 | AB9: Ø89×5 | AC9: 3.7 | AD9: 65.4 | AE9: 57.7 | AF9: 126 | AG9: 3.3 | AH9: 0.65 | AI9: 0.36 | AJ9: 0.69 | AK9: 0.42 | AL9: 0.15 | AM9: 0.62 | AN9: ĐẠT | AO9: Đế dùng chung hai bè: hai tai neo
A10: 5 | B10: HV-DV005 | C10: B2-D18 | D10: BÈ 2 | E10: 27.8 | F10: 14.23 | G10: B3-D13 | H10: BÈ 3 | I10: 38.6 | J10: 14.23 | K10: -28.46 | L10: -18.93 | M10: 378.3 | N10: 1.7 | O10: 7.7 | P10: cả hai dây căng (MN cao) | Q10: 9.6 | R10: 31 | S10: 2.5 | T10: 0.4 | U10: 2.48 | V10: 62.5 | W10: 37.5 | X10: 6.4 | Y10: Ø12 a200 | Z10: 119 | AA10: 4 | AB10: Ø89×5 | AC10: 3.7 | AD10: 65.4 | AE10: 44 | AF10: 126 | AG10: 0.38 | AH10: 0.47 | AI10: 0.36 | AJ10: 0.52 | AK10: 0.05 | AL10: 0.15 | AM10: 0.62 | AN10: ĐẠT | AO10: Đế dùng chung hai bè: hai tai neo
A11: 6 | B11: HV-DV006 | C11: B3-D12 | D11: BÈ 3 | E11: 38.6 | F11: 9.36 | G11: B3A-D23 | H11: BÈ 3A | I11: 73.7 | J11: 9.35 | K11: 16.6 | L11: -124.06 | M11: 378.3 | N11: 1.7 | O11: 7.7 | P11: cả hai dây căng (MN cao) | Q11: 27.3 | R11: 70.3 | S11: 3.25 | T11: 0.4 | U11: 4.21 | V11: 105.6 | W11: 63.4 | X11: 10.8 | Y11: Ø12 a200 | Z11: 202 | AA11: 4 | AB11: Ø89×5 | AC11: 3.7 | AD11: 88.7 | AE11: 129.2 | AF11: 205.9 | AG11: 5.89 | AH11: 0.79 | AI11: 0.55 | AJ11: 0.94 | AK11: 0.74 | AL11: 0.15 | AM11: 0.62 | AN11: ĐẠT | AO11: Đế dùng chung hai bè: hai tai neo; Đế lớn hơn đế mẫu
A12: 7 | B12: HV-DV007 | C12: B3-D14 | D12: BÈ 3 | E12: 38.6 | F12: 15.33 | G12: B3A-D21 | H12: BÈ 3A | I12: 73.7 | J12: 15.33 | K12: 42.39 | L12: -119.37 | M12: 378.3 | N12: 1.7 | O12: 7.7 | P12: cả hai dây căng (MN cao) | Q12: 31.5 | R12: 49.4 | S12: 2.5 | T12: 0.4 | U12: 2.48 | V12: 62.5 | W12: 37.5 | X12: 6.4 | Y12: Ø12 a200 | Z12: 119 | AA12: 4 | AB12: Ø89×5 | AC12: 3.7 | AD12: 65.4 | AE12: 79 | AF12: 126 | AG12: 7.83 | AH12: 0.75 | AI12: 0.74 | AJ12: 0.94 | AK12: 0.99 | AL12: 0.15 | AM12: 0.62 | AN12: ĐẠT | AO12: Đế dùng chung hai bè: hai tai neo
A13: 8 | B13: HV-DV008 | C13: B3-D20 | D13: BÈ 3 | E13: 38.6 | F13: 12.34 | G13: B3A-D22 | H13: BÈ 3A | I13: 73.7 | J13: 12.34 | K13: 29.5 | L13: -121.71 | M13: 378.3 | N13: 1.7 | O13: 7.7 | P13: cả hai dây căng (MN cao) | Q13: 29.9 | R13: 58.3 | S13: 2.75 | T13: 0.4 | U13: 3.01 | V13: 75.6 | W13: 45.4 | X13: 7.7 | Y13: Ø12 a200 | Z13: 141 | AA13: 4 | AB13: Ø89×5 | AC13: 3.7 | AD13: 72.5 | AE13: 96.7 | AF13: 149.5 | AG13: 7.79 | AH13: 0.8 | AI13: 0.67 | AJ13: 0.97 | AK13: 0.98 | AL13: 0.15 | AM13: 0.62 | AN13: ĐẠT | AO13: Đế dùng chung hai bè: hai tai neo; Đế lớn hơn đế mẫu
A14: 9 | B14: HV-DV009 | C14: B3-D21 | D14: BÈ 3 | E14: 38.6 | F14: 9.6 | G14: B3A-D24 | H14: BÈ 3A | I14: 73.7 | J14: 9.59 | K14: 5.97 | L14: -128.68 | M14: 378.3 | N14: 1.7 | O14: 7.7 | P14: cả hai dây căng (MN cao) | Q14: 27.6 | R14: 69.2 | S14: 3.25 | T14: 0.4 | U14: 4.21 | V14: 105.6 | W14: 63.4 | X14: 10.8 | Y14: Ø12 a200 | Z14: 202 | AA14: 4 | AB14: Ø89×5 | AC14: 3.7 | AD14: 88.7 | AE14: 127.6 | AF14: 205.9 | AG14: 5.62 | AH14: 0.78 | AI14: 0.55 | AJ14: 0.93 | AK14: 0.71 | AL14: 0.15 | AM14: 0.62 | AN14: ĐẠT | AO14: Đế dùng chung hai bè: hai tai neo; Đế lớn hơn đế mẫu
A15: 10 | B15: HV-DV010 | C15: B3A-D36 | D15: BÈ 3A | E15: 73.7 | F15: 20.96 | G15: B5A-D32 | H15: BÈ 5A | I15: 87.3 | J15: 20.92 | K15: 198.11 | L15: -227.76 | M15: 378.3 | N15: 1.7 | O15: 7.7 | P15: B5A-D32 căng, B3A-D36 chùng (MN cao) | Q15: 77.5 | R15: 31.2 | S15: 2.75 | T15: 0.4 | U15: 3.01 | V15: 75.6 | W15: 45.4 | X15: 7.7 | Y15: Ø12 a200 | Z15: 141 | AA15: 4 | AB15: Ø89×5 | AC15: 3.7 | AD15: 72.5 | AE15: 85.5 | AF15: 149.5 | AG15: 5.64 | AH15: 0.75 | AI15: 0.81 | AJ15: 0.86 | AK15: 0.71 | AL15: 0.15 | AM15: 0.62 | AN15: ĐẠT | AO15: Đế dùng chung hai bè: hai tai neo; Đế lớn hơn đế mẫu
A16: 11 | B16: HV-DV011 | C16: B3A-D37 | D16: BÈ 3A | E16: 73.7 | F16: 20.95 | G16: B5A-D31 | H16: BÈ 5A | I16: 87.3 | J16: 20.92 | K16: 198.11 | L16: -213.26 | M16: 378.3 | N16: 1.7 | O16: 7.7 | P16: B5A-D31 căng, B3A-D37 chùng (MN cao) | Q16: 77.5 | R16: 31.2 | S16: 2.75 | T16: 0.4 | U16: 3.01 | V16: 75.6 | W16: 45.4 | X16: 7.7 | Y16: Ø12 a200 | Z16: 141 | AA16: 4 | AB16: Ø89×5 | AC16: 3.7 | AD16: 72.5 | AE16: 85.5 | AF16: 149.5 | AG16: 5.64 | AH16: 0.75 | AI16: 0.81 | AJ16: 0.86 | AK16: 0.71 | AL16: 0.15 | AM16: 0.62 | AN16: ĐẠT | AO16: Đế dùng chung hai bè: hai tai neo; Đế lớn hơn đế mẫu
A17: 12 | B17: HV-DV012 | C17: B3A-D38 | D17: BÈ 3A | E17: 73.7 | F17: 21.06 | G17: B5A-D30 | H17: BÈ 5A | I17: 87.3 | J17: 20.8 | K17: 198.23 | L17: -198.38 | M17: 378.3 | N17: 1.7 | O17: 7.7 | P17: B5A-D30 căng, B3A-D38 chùng (MN cao) | Q17: 77.5 | R17: 31.3 | S17: 2.75 | T17: 0.4 | U17: 3.01 | V17: 75.6 | W17: 45.4 | X17: 7.7 | Y17: Ø12 a200 | Z17: 141 | AA17: 4 | AB17: Ø89×5 | AC17: 3.7 | AD17: 72.5 | AE17: 85.6 | AF17: 149.5 | AG17: 5.67 | AH17: 0.75 | AI17: 0.81 | AJ17: 0.86 | AK17: 0.72 | AL17: 0.15 | AM17: 0.62 | AN17: ĐẠT | AO17: Đế dùng chung hai bè: hai tai neo; Đế lớn hơn đế mẫu
... A37: 32 | B37: HV-DV032 | C37: B8-D48 | D37: BÈ 8 | E37: 59.1 | F37: 11.49 | G37: B9-D16 | H37: BÈ 9 | I37: 30.9 | J37: 11.49 | K37: 121.79 | L37: 292.95 | M37: 378.3 | N37: 1.7 | O37: 7.7 | P37: cả hai dây căng (MN cao) | Q37: 23.7 | R37: 49.2 | S37: 2.5 | T37: 0.4 | U37: 2.48 | V37: 62.5 | W37: 37.5 | X37: 6.4 | Y37: Ø12 a200 | Z37: 119 | AA37: 4 | AB37: Ø89×5 | AC37: 3.7 | AD37: 65.4 | AE37: 74.5 | AF37: 126 | AG37: 6.88 | AH37: 0.75 | AI37: 0.59 | AJ37: 0.89 | AK37: 0.87 | AL37: 0.15 | AM37: 0.62 | AN37: ĐẠT | AO37: Đế dùng chung hai bè: hai tai neo; Địa hình IFC tại điểm này cao hơn đáy thiết kế 2,5 m: kiểm tra khảo sát / nạo vét trước khi đặt đế
A39: TỔNG | B39: 32 đế | R39: 1643 | U39: 92.8 | Z39: 4401 | AA39: 128 | AD39: 2275
A40: Ghi chú: cột M_lật, M_giữ, N 1 vít, sức chống nhổ là của tổ hợp chi phối; các cột SV là giá trị lớn nhất trên mọi tổ hợp.

Sheet VitXoan
A1: TÍNH TOÁN VÍT XOẮN — HV-FPV-2026
A3: BƯỚC | B3: ĐẠI LƯỢNG | C3: CÔNG THỨC | D3: GIÁ TRỊ | E3: ĐƠN VỊ
A4: 1 | B4: Ma sát thân vít | C4: α × c_u × π × D_ren × L = 0.8 × 20 × π × 0.105 × 3 | D4: 15.83 | E4: kN
A5: 2 | B5: Sức chịu của cánh xoắn | C5: Không tính (vít chỉ có ren, không có cánh lớn) | D5: 0 | E5: kN
A6: 3 | B6: Sức chịu kéo của ống thép | C6: A_thép × f_y | D6: 310.1 | E6: kN
A7: 4 | B7: Sức chịu nhổ cực hạn Q_u | C7: min(bước 1 + bước 2 ; bước 3) | D7: 15.83 | E7: kN
A8: 5 | B8: Sức chịu nhổ cho phép Q_a | C8: Q_u / 2 | D8: 7.92 | E8: kN
A9: 6 | B9: Sức chịu ngang theo đất (Broms) | C9: Cọc ngắn đầu tự do, đất dính | D9: 20.62 | E9: kN
A10: 7 | B10: Sức chịu ngang theo thép ống | C10: Khớp dẻo trong thân vít | D10: 14.98 | E10: kN
A11: 8 | B11: Sức chịu ngang cực hạn H_u | C11: min(bước 6 ; bước 7) | D11: 14.98 | E11: kN
A12: 9 | B12: 4 vít của một đế: chống nhổ | C12: 4 × Q_a | D12: 31.7 | E12: kN
A13: 10 | B13: Chiều dài chế tạo một vít | C13: ngàm 3 + dày đế 0.4 + đầu khóa 0,3 | D13: 3.7 | E13: m
A14: 11 | B14: Tổng số vít / tổng chiều dài | C14: 32 đế × 4 vít | D14: 128 cây / 473.6 m
A16: Vít chỉ là phần phụ: phần lớn lực nhổ do trọng lượng đế gánh. Sức chịu của vít tỷ lệ thuận với c_u bùn (GIẢ ĐỊNH). Sức chịu nhổ và sức chịu ngang tính độc lập, chưa xét tương tác. Chưa thiết kế khóa đầu vít và chống ăn mòn.
A18: MÃ ĐẾ | B18: B (m) | C18: Lực nhổ T_v (kN) | D18: 0,9 W' (kN) | E18: Phần vít phải gánh (kN) | F18: N lớn nhất 1 vít (kN) | G18: Q_a (kN) | H18: Mức sử dụng 1 vít | I18: KẾT LUẬN
A19: HV-DV001 | B19: 2.5 | C19: 29.7 | D19: 33.8 | E19: 0 | F19: 0 | G19: 7.92 | H19: 0 | I19: ĐẠT
A20: HV-DV002 | B20: 2.5 | C20: 32.1 | D20: 33.8 | E20: 0 | F20: 0 | G20: 7.92 | H20: 0 | I20: ĐẠT
A21: HV-DV003 | B21: 2.5 | C21: 39.7 | D21: 33.8 | E21: 5.9 | F21: 2.59 | G21: 7.92 | H21: 0.33 | I21: ĐẠT
A22: HV-DV004 | B22: 2.5 | C22: 42.5 | D22: 33.8 | E22: 8.7 | F22: 3.3 | G22: 7.92 | H22: 0.42 | I22: ĐẠT
A23: HV-DV005 | B23: 2.5 | C23: 31 | D23: 33.8 | E23: 0 | F23: 0.38 | G23: 7.92 | H23: 0.05 | I23: ĐẠT
A24: HV-DV006 | B24: 3.25 | C24: 70.3 | D24: 57 | E24: 13.2 | F24: 5.89 | G24: 7.92 | H24: 0.74 | I24: ĐẠT
A25: HV-DV007 | B25: 2.5 | C25: 49.4 | D25: 33.8 | E25: 15.6 | F25: 7.83 | G25: 7.92 | H25: 0.99 | I25: ĐẠT
A26: HV-DV008 | B26: 2.75 | C26: 58.3 | D26: 40.8 | E26: 17.5 | F26: 7.79 | G26: 7.92 | H26: 0.98 | I26: ĐẠT
A27: HV-DV009 | B27: 3.25 | C27: 69.2 | D27: 57 | E27: 12.1 | F27: 5.62 | G27: 7.92 | H27: 0.71 | I27: ĐẠT
A28: HV-DV010 | B28: 2.75 | C28: 54.3 | D28: 40.8 | E28: 13.5 | F28: 5.64 | G28: 7.92 | H28: 0.71 | I28: ĐẠT
A29: HV-DV011 | B29: 2.75 | C29: 54.3 | D29: 40.8 | E29: 13.5 | F29: 5.64 | G29: 7.92 | H29: 0.71 | I29: ĐẠT
A30: HV-DV012 | B30: 2.75 | C30: 54.3 | D30: 40.8 | E30: 13.5 | F30: 5.67 | G30: 7.92 | H30: 0.72 | I30: ĐẠT
... A50: HV-DV032 | B50: 2.5 | C50: 49.2 | D50: 33.8 | E50: 15.4 | F50: 6.88 | G50: 7.92 | H50: 0.87 | I50: ĐẠT

Sheet KhoiLuong_BaoGia
A1: KHỐI LƯỢNG VÀ BÁO GIÁ THI CÔNG — HV-FPV-2026
A2: Phương án chốt: Cọc khoan nhồi D350 ven bờ + đế BTCT giữ bằng vít xoắn dưới đáy hồ
A3: Đơn giá cọc khoan nhồi là giá THAM KHẢO thị trường do Chủ đầu tư cung cấp, không phải báo giá nhà thầu. Hạng mục ghi "CHƯA CÓ ĐƠN GIÁ" chưa nằm trong tổng.
A5: STT | B5: HẠNG MỤC | C5: ĐƠN VỊ | D5: KHỐI LƯỢNG | E5: ĐƠN GIÁ (VNĐ) | F5: THÀNH TIỀN (VNĐ) | G5: GHI CHÚ
A6: A | B6: Cọc khoan nhồi trên bờ (đổ bê tông tại chỗ) | C6: md | D6: 1524.6 | E6: 480000 | F6: 731808000 | G6: Đơn giá trọn gói vật tư + nhân công; 231 cọc
A7: B.1 | B7: Đế BTCT neo đáy: bê tông B25 đúc sẵn (gồm ván khuôn, lỗ chờ, gờ chống trượt) | C7: m³ | D7: 92.8 | E7: 0 | F7: 0 | G7: CHƯA CÓ ĐƠN GIÁ — nhập để tính
A8: B.2 | B8: Đế BTCT neo đáy: cốt thép lưới 2 lớp | C8: kg | D8: 4400.6 | E8: 0 | F8: 0 | G8: CHƯA CÓ ĐƠN GIÁ — nhập để tính
A9: B.3 | B9: Vít xoắn ống thép Ø89×5, ren Ø105, mạ kẽm nhúng nóng | C9: md | D9: 473.6 | E9: 0 | F9: 0 | G9: CHƯA CÓ ĐƠN GIÁ — nhập để tính
A10: B.4 | B10: Hạ đế xuống đáy hồ, vặn vít, khóa đầu vít (cẩu trên sà lan, thợ lặn) | C10: đế | D10: 32 | E10: 0 | F10: 0 | G10: CHƯA CÓ ĐƠN GIÁ — nhập để tính
A11: B.5 | B11: Khấu hao lắp đặt sàn đạo nổi / sà lan | C11: chiến dịch | D11: 1 | E11: 50000000 | F11: 50000000 | G11: Cho cả chiến dịch lắp đế neo đáy
B12: CHÚ Ý: 4 hạng mục CHƯA CÓ ĐƠN GIÁ, tổng bên dưới CHƯA gồm các hạng mục này.
B13: CỘNG CHI PHÍ TRỰC TIẾP | F13: 781808000
B14: Dự phòng phí 5% | F14: 39090400
B15: Thuế VAT 8% | F15: 65671872
B16: TỔNG CỘNG (chưa gồm hạng mục chưa có đơn giá) | F16: 886570272
A18: KHỐI LƯỢNG KHÁC (không có trong báo giá)
B19: Bê tông cọc khoan nhồi | C19: m³ | D19: 146.7
B20: Cốt thép cọc khoan nhồi | C20: tấn | D20: 38.3
B21: Đế nặng nhất khi cẩu | C21: tấn | D21: 10.8
B22: Chưa gồm: cáp neo và phụ kiện, tai neo và khóa đầu vít của đế, bích neo đầu cọc, khảo sát, thử tải.
A24: KHỐI LƯỢNG THEO BÈ (đế dùng chung tính mỗi bè một nửa)
A25: BÈ | B25: Số cọc bờ | C25: Cọc bờ (md) | D25: Số đế | E25: Bê tông đế (m³) | F25: Thép bản (kg) | G25: Vít (md)
A26: BÈ 1 | B26: 17 | C26: 112.2 | D26: 1 | E26: 2.5 | F26: 119 | G26: 14.8
A27: BÈ 2 | B27: 15 | C27: 99 | D27: 2.5 | E27: 6.2 | F27: 299 | G27: 37
A28: BÈ 3 | B28: 15 | C28: 99 | D28: 3.5 | E28: 10.7 | F28: 511 | G28: 51.8
A29: BÈ 3A | B29: 31 | C29: 204.6 | D29: 9.5 | E29: 29.5 | F29: 1391 | G29: 140.6
A30: BÈ 5A | B30: 36 | C30: 237.6 | D30: 6.5 | E30: 19.5 | F30: 918 | G30: 96.2
A31: BÈ 6 | B31: 28 | C31: 184.8 | D31: 1.5 | E31: 4.5 | F31: 212 | G31: 22.2
A32: BÈ 7 | B32: 24 | C32: 158.4 | D32: 4.5 | E32: 12.5 | F32: 592 | G32: 66.6
A33: BÈ 8 | B33: 46 | C33: 303.6 | D33: 2.5 | E33: 6.2 | F33: 299 | G33: 37
A34: BÈ 9 | B34: 19 | C34: 125.4 | D34: 0.5 | E34: 1.2 | F34: 60 | G34: 7.4

Sheet ChieuDaiCatCap
A1: BẢNG CHIỀU DÀI CẮT CÁP NEO (295 TUYẾN: 231 dây bờ, 64 dây đáy) — HV-FPV-2026
A2: Nguyên tắc: KHÔNG lắp cáp bằng cách kéo căng. Mỗi dây cắt theo khoảng cách thẳng từ bích bè tới chốt neo ở mực nước mà khoảng cách đó DÀI NHẤT: dây đáy ở MNLKT 386 m, dây bờ ở MNC 380 m. Ở các mực nước khác dây chùng đúng bằng cột "Độ chùng".
A3: Giả thiết: cáp thẳng, không giãn (chưa xét độ võng và độ giãn khi chịu lực); bích bè cao hơn mặt nước 0,35 m; chiều dài tính từ CHỐT tới CHỐT, CHƯA gồm đoạn bện đầu, khuyên lót, ma-ní, tăng đơ.
A4: Cao độ đáy hồ tại đế là cao độ THIẾT KẾ (giả định): đáy thật thấp hơn thì dây đáy phải dài hơn — phải đo cao độ đáy từng đế trước khi cắt. Cao độ mặt đất tại cọc bờ lấy theo địa hình IFC, chưa phải khảo sát. Đầu dây phía bè cần có đoạn điều chỉnh.
A6: STT | B6: KÝ HIỆU DÂY | C6: BÈ | D6: LOẠI | E6: MÃ ĐẾ | F6: Tầm vươn (m) | G6: Cao độ chốt neo (m) | H6: Khoảng cách ở MNC (m) | I6: Khoảng cách ở MNDB (m) | J6: Khoảng cách ở MNLKT (m) | K6: Mực nước chi phối | L6: CHIỀU DÀI CẮT (m) | M6: Độ chùng ở MNC (m) | N6: Độ chùng ở MNDB (m) | O6: Độ chùng ở MNLKT (m) | P6: Độ rơ ngang ở MNC (m) | Q6: Độ rơ ngang ở MNDB (m) | R6: Độ rơ ngang ở MNLKT (m) | S6: Góc cáp ở MNC (°) | T6: Góc cáp ở MNDB (°) | U6: Góc cáp ở MNLKT (°) | V6: GHI CHÚ
A7: 1 | B7: B1-D01 | C7: BÈ 1 | D7: BỜ | E7: - | F7: 12.64 | G7: 384.39 | H7: 13.27 | I7: 12.65 | J7: 12.79 | K7: MNC | L7: 13.27 | M7: 0 | N7: 0.62 | O7: 0.48 | P7: 0 | Q7: 0.62 | R7: 0.48 | S7: -17.7 | T7: 2.1 | U7: 8.8
A8: 2 | B8: B1-D02 | C8: BÈ 1 | D8: BỜ | E8: - | F8: 13.7 | G8: 384.47 | H8: 14.31 | I8: 13.71 | J8: 13.83 | K8: MNC | L8: 14.31 | M8: 0 | N8: 0.6 | O8: 0.48 | P8: 0 | Q8: 0.6 | R8: 0.48 | S8: -16.8 | T8: 1.6 | U8: 7.8
A9: 3 | B9: B1-D03 | C9: BÈ 1 | D9: BỜ | E9: - | F9: 16.49 | G9: 384.43 | H9: 16.99 | I9: 16.5 | J9: 16.6 | K9: MNC | L9: 16.99 | M9: 0 | N9: 0.49 | O9: 0.39 | P9: 0 | Q9: 0.49 | R9: 0.39 | S9: -13.9 | T9: 1.5 | U9: 6.6
A10: 4 | B10: B1-D04 | C10: BÈ 1 | D10: BỜ | E10: - | F10: 32.3 | G10: 384.51 | H10: 32.57 | I10: 32.3 | J10: 32.35 | K10: MNC | L10: 32.57 | M10: 0 | N10: 0.26 | O10: 0.21 | P10: 0 | Q10: 0.26 | R10: 0.21 | S10: -7.3 | T10: 0.6 | U10: 3.3
A11: 5 | B11: B1-D05 | C11: BÈ 1 | D11: BỜ | E11: - | F11: 32.11 | G11: 384.69 | H11: 32.4 | I11: 32.11 | J11: 32.15 | K11: MNC | L11: 32.4 | M11: 0 | N11: 0.29 | O11: 0.25 | P11: 0 | Q11: 0.29 | R11: 0.25 | S11: -7.7 | T11: 0.3 | U11: 3
A12: 6 | B12: B1-D06 | C12: BÈ 1 | D12: BỜ | E12: - | F12: 33.12 | G12: 384.73 | H12: 33.41 | I12: 33.12 | J12: 33.16 | K12: MNC | L12: 33.41 | M12: 0 | N12: 0.29 | O12: 0.25 | P12: 0 | Q12: 0.29 | R12: 0.25 | S12: -7.5 | T12: 0.2 | U12: 2.8
A13: 7 | B13: B1-D07 | C13: BÈ 1 | D13: BỜ | E13: - | F13: 12.78 | G13: 384.35 | H13: 13.39 | I13: 12.79 | J13: 12.94 | K13: MNC | L13: 13.39 | M13: 0 | N13: 0.6 | O13: 0.45 | P13: 0 | Q13: 0.6 | R13: 0.46 | S13: -17.4 | T13: 2.2 | U13: 8.9
A14: 8 | B14: B1-D08 | C14: BÈ 1 | D14: BỜ | E14: - | F14: 13.84 | G14: 384.57 | H14: 14.47 | I14: 13.84 | J14: 13.95 | K14: MNC | L14: 14.47 | M14: 0 | N14: 0.63 | O14: 0.51 | P14: 0 | Q14: 0.63 | R14: 0.52 | S14: -17 | T14: 1.2 | U14: 7.3
A15: 9 | B15: B1-D09 | C15: BÈ 1 | D15: BỜ | E15: - | F15: 9.52 | G15: 384.27 | H15: 10.29 | I15: 9.54 | J15: 9.75 | K15: MNC | L15: 10.29 | M15: 0 | N15: 0.76 | O15: 0.55 | P15: 0 | Q15: 0.76 | R15: 0.56 | S15: -22.4 | T15: 3.5 | U15: 12.3 | V15: Dây bờ ngắn (< 10 m): góc cáp đổi nhiều theo mực nước, giữ bè kém khi chùng
A16: 10 | B16: B1-D10 | C16: BÈ 1 | D16: BỜ | E16: - | F16: 7.68 | G16: 384.79 | H16: 8.87 | I16: 7.68 | J16: 7.84 | K16: MNC | L16: 8.87 | M16: 0 | N16: 1.19 | O16: 1.03 | P16: 0 | Q16: 1.19 | R16: 1.05 | S16: -30 | T16: 0.4 | U16: 11.5 | V16: Dây bờ ngắn (< 10 m): góc cáp đổi nhiều theo mực nước, giữ bè kém khi chùng
A17: 11 | B17: B1-D11 | C17: BÈ 1 | D17: BỜ | E17: - | F17: 6.75 | G17: 384.54 | H17: 7.94 | I17: 6.76 | J17: 6.99 | K17: MNC | L17: 7.94 | M17: 0 | N17: 1.19 | O17: 0.95 | P17: 0 | Q17: 1.19 | R17: 0.98 | S17: -31.8 | T17: 2.7 | U17: 15 | V17: Dây bờ ngắn (< 10 m): góc cáp đổi nhiều theo mực nước, giữ bè kém khi chùng
A18: 12 | B18: B1-D12 | C18: BÈ 1 | D18: BỜ | E18: - | F18: 5.7 | G18: 383.86 | H18: 6.7 | I18: 5.78 | J18: 6.22 | K18: MNC | L18: 6.7 | M18: 0 | N18: 0.91 | O18: 0.48 | P18: 0 | Q18: 0.92 | R18: 0.52 | S18: -31.6 | T18: 9.8 | U18: 23.6 | V18: Dây bờ ngắn (< 10 m): góc cáp đổi nhiều theo mực nước, giữ bè kém khi chùng
A19: 13 | B19: B1-D13 | C19: BÈ 1 | D19: BỜ | E19: - | F19: 13.25 | G19: 384.68 | H19: 13.94 | I19: 13.25 | J19: 13.35 | K19: MNC | L19: 13.94 | M19: 0 | N19: 0.69 | O19: 0.59 | P19: 0 | Q19: 0.69 | R19: 0.59 | S19: -18.1 | T19: 0.7 | U19: 7.2
A20: 14 | B20: B1-D14 | C20: BÈ 1 | D20: BỜ | E20: - | F20: 42.92 | G20: 384.28 | H20: 43.1 | I20: 42.92 | J20: 42.97 | K20: MNC | L20: 43.1 | M20: 0 | N20: 0.18 | O20: 0.13 | P20: 0 | Q20: 0.18 | R20: 0.13 | S20: -5.2 | T20: 0.8 | U20: 2.8
A21: 15 | B21: B1-D15 | C21: BÈ 1 | D21: ĐÁY | E21: DV-001 | F21: 12.56 | G21: 378.85 | H21: 12.65 | I21: 13.92 | J21: 14.63 | K21: MNLKT | L21: 14.63 | M21: 1.98 | N21: 0.71 | O21: 0 | P21: 1.99 | Q21: 0.78 | R21: 0 | S21: 6.8 | T21: 25.5 | U21: 30.8 | V21: Đo cao độ đáy thực tế trước khi cắt
A22: 16 | B22: B1-D16 | C22: BÈ 1 | D22: BỜ | E22: - | F22: 44 | G22: 384.16 | H22: 44.16 | I22: 44.01 | J22: 44.05 | K22: MNC | L22: 44.16 | M22: 0 | N22: 0.16 | O22: 0.11 | P22: 0 | Q22: 0.16 | R22: 0.11 | S22: -5 | T22: 0.9 | U22: 2.8
A23: 17 | B23: B1-D17 | C23: BÈ 1 | D23: BỜ | E23: - | F23: 24.5 | G23: 384.17 | H23: 24.8 | I23: 24.51 | J23: 24.6 | K23: MNC | L23: 24.8 | M23: 0 | N23: 0.29 | O23: 0.2 | P23: 0 | Q23: 0.29 | R23: 0.2 | S23: -8.9 | T23: 1.6 | U23: 5.1
A24: 18 | B24: B1-D18 | C24: BÈ 1 | D24: BỜ | E24: - | F24: 17 | G24: 384.17 | H24: 17.42 | I24: 17.01 | J24: 17.14 | K24: MNC | L24: 17.42 | M24: 0 | N24: 0.41 | O24: 0.28 | P24: 0 | Q24: 0.41 | R24: 0.29 | S24: -12.7 | T24: 2.3 | U24: 7.3
A25: 19 | B25: B1-D19 | C25: BÈ 1 | D25: ĐÁY | E25: DV-002 | F25: 11.3 | G25: 378.85 | H25: 11.4 | I25: 12.79 | J25: 13.56 | K25: MNLKT | L25: 13.56 | M25: 2.16 | N25: 0.77 | O25: 0 | P25: 2.18 | Q25: 0.86 | R25: 0 | S25: 7.6 | T25: 28 | U25: 33.6 | V25: Đo cao độ đáy thực tế trước khi cắt
A26: 20 | B26: B2-D01 | C26: BÈ 2 | D26: BỜ | E26: - | F26: 12.97 | G26: 384.75 | H26: 13.7 | I26: 12.97 | J26: 13.07 | K26: MNC | L26: 13.7 | M26: 0 | N26: 0.73 | O26: 0.63 | P26: 0 | Q26: 0.73 | R26: 0.63 | S26: -18.8 | T26: 0.4 | U26: 7
A27: 21 | B27: B2-D02 | C27: BÈ 2 | D27: BỜ | E27: - | F27: 36.85 | G27: 384.57 | H27: 37.09 | I27: 36.85 | J27: 36.89 | K27: MNC | L27: 37.09 | M27: 0 | N27: 0.24 | O27: 0.2 | P27: 0 | Q27: 0.24 | R27: 0.2 | S27: -6.5 | T27: 0.4 | U27: 2.8
A28: 22 | B28: B2-D03 | C28: BÈ 2 | D28: BỜ | E28: - | F28: 38.53 | G28: 384.81 | H28: 38.79 | I28: 38.53 | J28: 38.56 | K28: MNC | L28: 38.79 | M28: 0 | N28: 0.26 | O28: 0.23 | P28: 0 | Q28: 0.26 | R28: 0.23 | S28: -6.6 | T28: 0.1 | U28: 2.3
A29: 23 | B29: B2-D04 | C29: BÈ 2 | D29: BỜ | E29: - | F29: 41.84 | G29: 384.61 | H29: 42.06 | I29: 41.84 | J29: 41.88 | K29: MNC | L29: 42.06 | M29: 0 | N29: 0.22 | O29: 0.18 | P29: 0 | Q29: 0.22 | R29: 0.18 | S29: -5.8 | T29: 0.3 | U29: 2.4
A30: 24 | B30: B2-D05 | C30: BÈ 2 | D30: BỜ | E30: - | F30: 22.74 | G30: 384.83 | H30: 23.18 | I30: 22.74 | J30: 22.79 | K30: MNC | L30: 23.18 | M30: 0 | N30: 0.44 | O30: 0.39 | P30: 0 | Q30: 0.44 | R30: 0.39 | S30: -11.1 | T30: 0.1 | U30: 3.8
A31: 25 | B31: B2-D06 | C31: BÈ 2 | D31: BỜ | E31: - | F31: 19.22 | G31: 384.94 | H31: 19.76 | I31: 19.22 | J31: 19.27 | K31: MNC | L31: 19.76 | M31: 0 | N31: 0.54 | O31: 0.49 | P31: 0 | Q31: 0.54 | R31: 0.49 | S31: -13.4 | T31: -0.3 | U31: 4.2
A32: 26 | B32: B2-D07 | C32: BÈ 2 | D32: BỜ | E32: - | F32: 12.97 | G32: 384.23 | H32: 13.54 | I32: 12.98 | J32: 13.14 | K32: MNC | L32: 13.54 | M32: 0 | N32: 0.55 | O32: 0.4 | P32: 0 | Q32: 0.55 | R32: 0.4 | S32: -16.7 | T32: 2.7 | U32: 9.3
A33: 27 | B33: B2-D08 | C33: BÈ 2 | D33: BỜ | E33: - | F33: 13.7 | G33: 384.54 | H33: 14.33 | I33: 13.7 | J33: 13.82 | K33: MNC | L33: 14.33 | M33: 0 | N33: 0.62 | O33: 0.51 | P33: 0 | Q33: 0.62 | R33: 0.51 | S33: -17 | T33: 1.3 | U33: 7.5
A34: 28 | B34: B2-D09 | C34: BÈ 2 | D34: BỜ | E34: - | F34: 12.77 | G34: 384.06 | H34: 13.3 | I34: 12.79 | J34: 12.97 | K34: MNC | L34: 13.3 | M34: 0 | N34: 0.51 | O34: 0.33 | P34: 0 | Q34: 0.51 | R34: 0.33 | S34: -16.2 | T34: 3.5 | U34: 10.1
A35: 29 | B35: B2-D10 | C35: BÈ 2 | D35: BỜ | E35: - | F35: 15.13 | G35: 384.59 | H35: 15.71 | I35: 15.13 | J35: 15.23 | K35: MNC | L35: 15.71 | M35: 0 | N35: 0.58 | O35: 0.48 | P35: 0 | Q35: 0.58 | R35: 0.48 | S35: -15.7 | T35: 1 | U35: 6.6
A36: 30 | B36: B2-D11 | C36: BÈ 2 | D36: BỜ | E36: - | F36: 15.01 | G36: 384.18 | H36: 15.49 | I36: 15.03 | J36: 15.17 | K36: MNC | L36: 15.49 | M36: 0 | N36: 0.46 | O36: 0.32 | P36: 0 | Q36: 0.46 | R36: 0.33 | S36: -14.3 | T36: 2.6 | U36: 8.2
A37: 31 | B37: B2-D12 | C37: BÈ 2 | D37: ĐÁY | E37: DV-003 | F37: 10.08 | G37: 378.85 | H37: 10.19 | I37: 11.73 | J37: 12.56 | K37: MNLKT | L37: 12.56 | M37: 2.37 | N37: 0.83 | O37: 0 | P37: 2.39 | Q37: 0.96 | R37: 0 | S37: 8.5 | T37: 30.8 | U37: 36.7 | V37: Cáp dốc tới 37°: thành phần đứng lớn tại bích bè; Đo cao độ đáy thực tế trước khi cắt
A38: 32 | B38: B2-D13 | C38: BÈ 2 | D38: ĐÁY | E38: DV-001 | F38: 12.57 | G38: 378.85 | H38: 12.66 | I38: 13.93 | J38: 14.64 | K38: MNLKT | L38: 14.64 | M38: 1.98 | N38: 0.71 | O38: 0 | P38: 1.99 | Q38: 0.78 | R38: 0 | S38: 6.8 | T38: 25.5 | U38: 30.8 | V38: Đo cao độ đáy thực tế trước khi cắt
A39: 33 | B39: B2-D14 | C39: BÈ 2 | D39: BỜ | E39: - | F39: 30 | G39: 384.19 | H39: 30.24 | I39: 30.01 | J39: 30.08 | K39: MNC | L39: 30.24 | M39: 0 | N39: 0.24 | O39: 0.17 | P39: 0 | Q39: 0.24 | R39: 0.17 | S39: -7.3 | T39: 1.3 | U39: 4.1
A40: 34 | B40: B2-D15 | C40: BÈ 2 | D40: BỜ | E40: - | F40: 17 | G40: 384.24 | H40: 17.44 | I40: 17.01 | J40: 17.13 | K40: MNC | L40: 17.44 | M40: 0 | N40: 0.43 | O40: 0.31 | P40: 0 | Q40: 0.43 | R40: 0.31 | S40: -12.9 | T40: 2.1 | U40: 7.1
A41: 35 | B41: B2-D16 | C41: BÈ 2 | D41: BỜ | E41: - | F41: 36.5 | G41: 384.18 | H41: 36.7 | I41: 36.51 | J41: 36.56 | K41: MNC | L41: 36.7 | M41: 0 | N41: 0.19 | O41: 0.14 | P41: 0 | Q41: 0.19 | R41: 0.14 | S41: -6 | T41: 1.1 | U41: 3.4
...

Sheet CT_ThongSo
A1: BẢNG TÍNH CÓ CÔNG THỨC — THÔNG SỐ ĐẦU VÀO — HV-FPV-2026
A2: Ô có chữ "NHẬP" ở cột E (tô vàng trong file đính kèm) là ô nhập. Đổi ô nhập thì ba sheet CT_LucDay, CT_CocKhoanNhoi, CT_DeVitXoan tự tính lại. Thông số đất là GIẢ ĐỊNH, chưa có khảo sát.
A3: CHÚ Ý: Gió tính toán V = 20 m/s là cấp gió vận hành, THẤP HƠN gió tiêu chuẩn TCVN 2737:2023 vùng II-B (V ≈ 29,7 m/s, q0 = 0,54 kN/m²): áp lực gió chỉ bằng 45% mức tiêu chuẩn. Cáp, cọc và đế neo định cỡ ở cấp gió này CHƯA được kiểm tra với bão thiết kế; nhập V = 30 m/s ở Tab 2 để kiểm tra.
A4: NHÓM | B4: THÔNG SỐ | C4: GIÁ TRỊ | D4: ĐƠN VỊ | E4: LOẠI Ô | F4: GHI CHÚ / CÔNG THỨC
A5: Gió | B5: Vận tốc gió tính toán V | C5: 20 | D5: m/s | E5: NHẬP
A6: Gió | B6: Khối lượng riêng không khí ρ | C6: 1.25 | D6: kg/m³ | E6: NHẬP
A7: Gió | B7: Áp lực gió q | C7: =0.5*CT_ThongSo!$C$6*CT_ThongSo!$C$5^2 -> 250 | D7: N/m² | E7: công thức | F7: q = 0,5 ρ V²
A8: Gió | B8: Diện tích một tấm pin | C8: 2.701 | D8: m² | E8: NHẬP
A9: Gió | B9: Góc nghiêng tấm pin | C9: 12 | D9: ° | E9: NHẬP
A10: Gió | B10: Hệ số cản tấm pin | C10: 1.15 | E10: NHẬP
A11: Gió | B11: Hệ số che chắn giữa các hàng | C11: 0.55 | E11: NHẬP | F11: GIẢ ĐỊNH
A12: Gió | B12: Hệ số cản phao | C12: 1.1 | E12: NHẬP
A13: Gió | B13: Mạn khô của phao (cũng là chiều cao bích bè trên mặt nước) | C13: 0.35 | D13: m | E13: NHẬP
A14: Gió | B14: Hệ số gộp sóng + dòng chảy | C14: 1.05 | E14: NHẬP
A15: Dây neo | B15: Số dây làm việc n | C15: 6 | D15: dây | E15: NHẬP | F15: GIẢ ĐỊNH
A16: Dây neo | B16: Góc dây so với phương ngang α | C16: 30 | D16: ° | E16: NHẬP | F16: GIẢ ĐỊNH
A17: Dây neo | B17: Lực căng trước T_0 | C17: 5 | D17: kN | E17: NHẬP
A18: Dây neo | B18: Hệ số an toàn cáp yêu cầu | C18: 3 | E18: NHẬP
A19: Mực nước | B19: MNC | C19: 380 | D19: m | E19: NHẬP
A20: Mực nước | B20: MNLKT | C20: 386 | D20: m | E20: NHẬP
A21: Cọc bờ | B21: Đường kính cọc khoan nhồi D | C21: 0.35 | D21: m | E21: NHẬP
A22: Cọc bờ | B22: Chiều sâu ngàm L_tk | C22: 6.5 | D22: m | E22: NHẬP
A23: Cọc bờ | B23: Đoạn nhô trên mặt đất | C23: 0.1 | D23: m | E23: NHẬP
A24: Cọc bờ | B24: Điểm móc cáp cách mặt đất e | C24: 0.1 | D24: m | E24: NHẬP
A25: Cọc bờ | B25: c_u đất bờ | C25: 40 | D25: kPa | E25: NHẬP | F25: GIẢ ĐỊNH
A26: Cọc bờ | B26: Hệ số an toàn chịu ngang | C26: 2.5 | E26: NHẬP
A27: Cọc bờ | B27: Hệ số tải trọng khi kiểm tra uốn γ | C27: 1.2 | E27: NHẬP
A28: Cọc bờ | B28: Khoảng cách từ mặt cọc tới tim thép chủ | C28: 0.05 | D28: m | E28: NHẬP
A29: Cọc bờ | B29: Phản lực đất cực hạn p | C29: =9*CT_ThongSo!$C$25*CT_ThongSo!$C$21 -> 126 | D29: kN/m | E29: công thức | F29: p = 9 c_u D
A30: Cọc bờ | B30: Chiều sâu làm việc g | C30: =MAX(0.1,CT_ThongSo!$C$22-1.5*CT_ThongSo!$C$21) -> 5.975 | D30: m | E30: công thức | F30: g = L − 1,5 D
A31: Cọc bờ | B31: Sức chịu ngang cực hạn H_u (Broms) | C31: =(-(CT_ThongSo!$C$24+1.5*CT_ThongSo!$C$21+CT_ThongSo!$C$30)+SQRT((CT_ThongSo!$C$24+1.5*CT_ThongSo!$C$21+CT_ThongSo!$C$30)^2+CT_ThongSo!$C$30^2))*CT_ThongSo!$C$29 -> 290.1583 | D31: kN | E31: công thức | F31: Nghiệm của 0,5/p·H² + (e + 1,5D + g)·H − 0,5·p·g² = 0
A32: Cọc bờ | B32: Sức chịu ngang cho phép | C32: =CT_ThongSo!$C$31/CT_ThongSo!$C$26 -> 116.06332 | D32: kN | E32: công thức | F32: H_u / hệ số an toàn
A33: Đế BTCT | B33: Chiều cao tai neo trên mặt đế | C33: 0.15 | D33: m | E33: NHẬP
A34: Đế BTCT | B34: Trọng lượng riêng bê tông | C34: 25 | D34: kN/m³ | E34: NHẬP
A35: Đế BTCT | B35: Trọng lượng riêng nước | C35: 10 | D35: kN/m³ | E35: NHẬP | F35: Trọng lượng đế trong nước đã trừ đẩy nổi
A36: Đế BTCT | B36: Hệ số trọng lượng đế khi chống nhổ | C36: 0.9 | E36: NHẬP | F36: GIẢ ĐỊNH
A37: Đế BTCT | B37: c_u bùn đáy hồ | C37: 20 | D37: kPa | E37: NHẬP | F37: GIẢ ĐỊNH; dùng cho cả đáy đế và thân vít
A38: Đế BTCT | B38: γ' bùn | C38: 6 | D38: kN/m³ | E38: NHẬP | F38: GIẢ ĐỊNH
A39: Đế BTCT | B39: Hệ số bám dính đáy đế | C39: 0.5 | E39: NHẬP | F39: GIẢ ĐỊNH
A40: Đế BTCT | B40: Chiều sâu gờ chống trượt | C40: 0.15 | D40: m | E40: NHẬP
...

Sheet CT_LucDay
A1: BẢNG TÍNH CÓ CÔNG THỨC — LỰC GIÓ VÀ LỰC CĂNG DÂY — HV-FPV-2026
A2: Các cột có chữ (NHẬP) là ô nhập. F pin = q × C_d × A × che chắn; F = (F pin + F phao) × hệ số sóng, dòng chảy; T = max(F × k + T_0 ; F / (n × cos α) + T_0).
A3: CHÚ Ý: Gió tính toán V = 20 m/s là cấp gió vận hành, THẤP HƠN gió tiêu chuẩn TCVN 2737:2023 vùng II-B (V ≈ 29,7 m/s, q0 = 0,54 kN/m²): áp lực gió chỉ bằng 45% mức tiêu chuẩn. Cáp, cọc và đế neo định cỡ ở cấp gió này CHƯA được kiểm tra với bão thiết kế; nhập V = 30 m/s ở Tab 2 để kiểm tra.
A5: BÈ | B5: Số tấm pin (NHẬP) | C5: Dài bè (m) (NHẬP) | D5: Rộng bè (m) (NHẬP) | E5: Hệ số tập trung k (NHẬP) | F5: Lực đứt cáp (kN) (NHẬP) | G5: A đón gió (m²) | H5: F pin (kN) | I5: F phao (kN) | J5: F tổng (kN) | K5: T cách k (kN) | L5: T cách n dây (kN) | M5: T dây (kN) | N5: HSAT cáp | O5: KẾT LUẬN | P5: Cáp
A6: BÈ 1 | B6: 808 | C6: 94.4 | D6: 46.1 | E6: 0.306 | F6: 235 | G6: =B6*CT_ThongSo!$C$8*SIN(RADIANS(CT_ThongSo!$C$9)) -> 453.74814 | H6: =CT_ThongSo!$C$7*CT_ThongSo!$C$10*G6*CT_ThongSo!$C$11/1000 -> 71.748924 | I6: =CT_ThongSo!$C$7*CT_ThongSo!$C$12*(C6+D6)/2*MAX(0.05,CT_ThongSo!$C$13)/1000 -> 6.7615625 | J6: =(H6+I6)*CT_ThongSo!$C$14 -> 82.436011 | K6: =IF(E6>0,J6*E6+CT_ThongSo!$C$17,0) -> 30.225419 | L6: =J6/(CT_ThongSo!$C$15*COS(RADIANS(CT_ThongSo!$C$16)))+CT_ThongSo!$C$17 -> 20.864818 | M6: =MAX(K6,L6) -> 30.225419 | N6: =F6/M6 -> 7.7749128 | O6: =IF(N6>=CT_ThongSo!$C$18,"ĐẠT","KHÔNG ĐẠT") -> ĐẠT | P6: PES-28
A7: BÈ 2 | B7: 788 | C7: 91.8 | D7: 52.1 | E7: 0.282 | F7: 235 | G7: =B7*CT_ThongSo!$C$8*SIN(RADIANS(CT_ThongSo!$C$9)) -> 442.51675 | H7: =CT_ThongSo!$C$7*CT_ThongSo!$C$10*G7*CT_ThongSo!$C$11/1000 -> 69.972961 | I7: =CT_ThongSo!$C$7*CT_ThongSo!$C$12*(C7+D7)/2*MAX(0.05,CT_ThongSo!$C$13)/1000 -> 6.9251875 | J7: =(H7+I7)*CT_ThongSo!$C$14 -> 80.743056 | K7: =IF(E7>0,J7*E7+CT_ThongSo!$C$17,0) -> 27.769542 | L7: =J7/(CT_ThongSo!$C$15*COS(RADIANS(CT_ThongSo!$C$16)))+CT_ThongSo!$C$17 -> 20.539008 | M7: =MAX(K7,L7) -> 27.769542 | N7: =F7/M7 -> 8.4625091 | O7: =IF(N7>=CT_ThongSo!$C$18,"ĐẠT","KHÔNG ĐẠT") -> ĐẠT | P7: PES-28
A8: BÈ 3 | B8: 1068 | C8: 92 | D8: 64.1 | E8: 0.313 | F8: 235 | G8: =B8*CT_ThongSo!$C$8*SIN(RADIANS(CT_ThongSo!$C$9)) -> 599.7562 | H8: =CT_ThongSo!$C$7*CT_ThongSo!$C$10*G8*CT_ThongSo!$C$11/1000 -> 94.836449 | I8: =CT_ThongSo!$C$7*CT_ThongSo!$C$12*(C8+D8)/2*MAX(0.05,CT_ThongSo!$C$13)/1000 -> 7.5123125 | J8: =(H8+I8)*CT_ThongSo!$C$14 -> 107.4662 | K8: =IF(E8>0,J8*E8+CT_ThongSo!$C$17,0) -> 38.636921 | L8: =J8/(CT_ThongSo!$C$15*COS(RADIANS(CT_ThongSo!$C$16)))+CT_ThongSo!$C$17 -> 25.68188 | M8: =MAX(K8,L8) -> 38.636921 | N8: =F8/M8 -> 6.0822653 | O8: =IF(N8>=CT_ThongSo!$C$18,"ĐẠT","KHÔNG ĐẠT") -> ĐẠT | P8: PES-28
A9: BÈ 3A | B9: 3657 | C9: 164.6 | D9: 148 | E9: 0.155 | F9: 235 | G9: =B9*CT_ThongSo!$C$8*SIN(RADIANS(CT_ThongSo!$C$9)) -> 2053.6596 | H9: =CT_ThongSo!$C$7*CT_ThongSo!$C$10*G9*CT_ThongSo!$C$11/1000 -> 324.73492 | I9: =CT_ThongSo!$C$7*CT_ThongSo!$C$12*(C9+D9)/2*MAX(0.05,CT_ThongSo!$C$13)/1000 -> 15.043875 | J9: =(H9+I9)*CT_ThongSo!$C$14 -> 356.76774 | K9: =IF(E9>0,J9*E9+CT_ThongSo!$C$17,0) -> 60.298999 | L9: =J9/(CT_ThongSo!$C$15*COS(RADIANS(CT_ThongSo!$C$16)))+CT_ThongSo!$C$17 -> 73.659983 | M9: =MAX(K9,L9) -> 73.659983 | N9: =F9/M9 -> 3.1903347 | O9: =IF(N9>=CT_ThongSo!$C$18,"ĐẠT","KHÔNG ĐẠT") -> ĐẠT | P9: PES-28
A10: BÈ 5A | B10: 4410 | C10: 182.2 | D10: 148 | E10: 0.144 | F10: 305 | G10: =B10*CT_ThongSo!$C$8*SIN(RADIANS(CT_ThongSo!$C$9)) -> 2476.5214 | H10: =CT_ThongSo!$C$7*CT_ThongSo!$C$10*G10*CT_ThongSo!$C$11/1000 -> 391.59995 | I10: =CT_ThongSo!$C$7*CT_ThongSo!$C$12*(C10+D10)/2*MAX(0.05,CT_ThongSo!$C$13)/1000 -> 15.890875 | J10: =(H10+I10)*CT_ThongSo!$C$14 -> 427.86536 | K10: =IF(E10>0,J10*E10+CT_ThongSo!$C$17,0) -> 66.612612 | L10: =J10/(CT_ThongSo!$C$15*COS(RADIANS(CT_ThongSo!$C$16)))+CT_ThongSo!$C$17 -> 87.342727 | M10: =MAX(K10,L10) -> 87.342727 | N10: =F10/M10 -> 3.4919908 | O10: =IF(N10>=CT_ThongSo!$C$18,"ĐẠT","KHÔNG ĐẠT") -> ĐẠT | P10: PES-32
A11: BÈ 6 | B11: 1860 | C11: 112.1 | D11: 109.4 | E11: 0.194 | F11: 235 | G11: =B11*CT_ThongSo!$C$8*SIN(RADIANS(CT_ThongSo!$C$9)) -> 1044.5192 | H11: =CT_ThongSo!$C$7*CT_ThongSo!$C$10*G11*CT_ThongSo!$C$11/1000 -> 165.1646 | I11: =CT_ThongSo!$C$7*CT_ThongSo!$C$12*(C11+D11)/2*MAX(0.05,CT_ThongSo!$C$13)/1000 -> 10.659688 | J11: =(H11+I11)*CT_ThongSo!$C$14 -> 184.6155 | K11: =IF(E11>0,J11*E11+CT_ThongSo!$C$17,0) -> 40.815408 | L11: =J11/(CT_ThongSo!$C$15*COS(RADIANS(CT_ThongSo!$C$16)))+CT_ThongSo!$C$17 -> 40.52927 | M11: =MAX(K11,L11) -> 40.815408 | N11: =F11/M11 -> 5.7576296 | O11: =IF(N11>=CT_ThongSo!$C$18,"ĐẠT","KHÔNG ĐẠT") -> ĐẠT | P11: PES-28
A12: BÈ 7 | B12: 2133 | C12: 144 | D12: 93.2 | E12: 0.164 | F12: 235 | G12: =B12*CT_ThongSo!$C$8*SIN(RADIANS(CT_ThongSo!$C$9)) -> 1197.8277 | H12: =CT_ThongSo!$C$7*CT_ThongSo!$C$10*G12*CT_ThongSo!$C$11/1000 -> 189.4065 | I12: =CT_ThongSo!$C$7*CT_ThongSo!$C$12*(C12+D12)/2*MAX(0.05,CT_ThongSo!$C$13)/1000 -> 11.41525 | J12: =(H12+I12)*CT_ThongSo!$C$14 -> 210.86284 | K12: =IF(E12>0,J12*E12+CT_ThongSo!$C$17,0) -> 39.581506 | L12: =J12/(CT_ThongSo!$C$15*COS(RADIANS(CT_ThongSo!$C$16)))+CT_ThongSo!$C$17 -> 45.580573 | M12: =MAX(K12,L12) -> 45.580573 | N12: =F12/M12 -> 5.1557053 | O12: =IF(N12>=CT_ThongSo!$C$18,"ĐẠT","KHÔNG ĐẠT") -> ĐẠT | P12: PES-28
A13: BÈ 8 | B13: 2861 | C13: 180 | D13: 106.9 | E13: 0.106 | F13: 235 | G13: =B13*CT_ThongSo!$C$8*SIN(RADIANS(CT_ThongSo!$C$9)) -> 1606.6503 | H13: =CT_ThongSo!$C$7*CT_ThongSo!$C$10*G13*CT_ThongSo!$C$11/1000 -> 254.05157 | I13: =CT_ThongSo!$C$7*CT_ThongSo!$C$12*(C13+D13)/2*MAX(0.05,CT_ThongSo!$C$13)/1000 -> 13.807063 | J13: =(H13+I13)*CT_ThongSo!$C$14 -> 281.25157 | K13: =IF(E13>0,J13*E13+CT_ThongSo!$C$17,0) -> 34.812666 | L13: =J13/(CT_ThongSo!$C$15*COS(RADIANS(CT_ThongSo!$C$16)))+CT_ThongSo!$C$17 -> 59.12689 | M13: =MAX(K13,L13) -> 59.12689 | N13: =F13/M13 -> 3.974503 | O13: =IF(N13>=CT_ThongSo!$C$18,"ĐẠT","KHÔNG ĐẠT") -> ĐẠT | P13: PES-28
A14: BÈ 9 | B14: 769 | C14: 110 | D14: 36.6 | E14: 0.327 | F14: 235 | G14: =B14*CT_ThongSo!$C$8*SIN(RADIANS(CT_ThongSo!$C$9)) -> 431.84693 | H14: =CT_ThongSo!$C$7*CT_ThongSo!$C$10*G14*CT_ThongSo!$C$11/1000 -> 68.285795 | I14: =CT_ThongSo!$C$7*CT_ThongSo!$C$12*(C14+D14)/2*MAX(0.05,CT_ThongSo!$C$13)/1000 -> 7.055125 | J14: =(H14+I14)*CT_ThongSo!$C$14 -> 79.107966 | K14: =IF(E14>0,J14*E14+CT_ThongSo!$C$17,0) -> 30.868305 | L14: =J14/(CT_ThongSo!$C$15*COS(RADIANS(CT_ThongSo!$C$16)))+CT_ThongSo!$C$17 -> 20.224335 | M14: =MAX(K14,L14) -> 30.868305 | N14: =F14/M14 -> 7.6129868 | O14: =IF(N14>=CT_ThongSo!$C$18,"ĐẠT","KHÔNG ĐẠT") -> ĐẠT | P14: PES-28

Sheet CT_CocKhoanNhoi
A1: BẢNG TÍNH CÓ CÔNG THỨC — CỌC KHOAN NHỒI VEN BỜ — HV-FPV-2026
A2: D, L, e, c_u và các hệ số: sheet CT_ThongSo. BP-1: T ≤ H_u / hệ số an toàn. BP-2: γ × M_max ≤ M_rd, với M_max = T × (e + 1,5D + 0,5T/p) và M_rd = A_thanh × R_s × (D/2 − a) × k.
A3: k = 2 / tan(π / n) là hệ số tay đòn của n thanh xếp tròn ở hướng bất lợi nhất (lồng thép không định hướng khi thả vào lỗ khoan); công thức đúng cho n chẵn.
A5: BÈ | B5: Số cọc (NHẬP) | C5: Số thanh thép chủ n (NHẬP) | D5: Đường kính thanh (mm) (NHẬP) | E5: R_s thép (MPa) (NHẬP) | F5: T dây (kN) | G5: H cho phép (kN) | H5: BP-1 ngang | I5: M_max (kNm) | J5: γ × M_max (kNm) | K5: Hệ số tay đòn k | L5: M_rd (kNm) | M5: BP-2 uốn | N5: KẾT LUẬN | O5: Tổng dài cọc (m) | P5: Bê tông (m³)
A6: BÈ 1 | B6: 17 | C6: 4 | D6: 25 | E6: 350 | F6: =VLOOKUP(A6,CT_LucDay!$A$6:$M$14,13,FALSE) -> 30.225419 | G6: =CT_ThongSo!$C$32 -> 116.06332 | H6: =F6/G6 -> 0.26042181 | I6: =F6*(CT_ThongSo!$C$24+1.5*CT_ThongSo!$C$21+0.5*F6/CT_ThongSo!$C$29) -> 22.516189 | J6: =CT_ThongSo!$C$27*I6 -> 27.019426 | K6: =2/TAN(PI()/C6) -> 2 | L6: =PI()*D6^2/4/1000000*E6*1000*(CT_ThongSo!$C$21/2-CT_ThongSo!$C$28)*K6 -> 42.951462 | M6: =J6/L6 -> 0.62906884 | N6: =IF(AND(H6<=1,M6<=1),"ĐẠT","KHÔNG ĐẠT") -> ĐẠT | O6: =B6*(CT_ThongSo!$C$22+CT_ThongSo!$C$23) -> 112.2 | P6: =O6*PI()*CT_ThongSo!$C$21^2/4 -> 10.794905
A7: BÈ 2 | B7: 15 | C7: 4 | D7: 25 | E7: 350 | F7: =VLOOKUP(A7,CT_LucDay!$A$6:$M$14,13,FALSE) -> 27.769542 | G7: =CT_ThongSo!$C$32 -> 116.06332 | H7: =F7/G7 -> 0.239262 | I7: =F7*(CT_ThongSo!$C$24+1.5*CT_ThongSo!$C$21+0.5*F7/CT_ThongSo!$C$29) -> 20.416072 | J7: =CT_ThongSo!$C$27*I7 -> 24.499287 | K7: =2/TAN(PI()/C7) -> 2 | L7: =PI()*D7^2/4/1000000*E7*1000*(CT_ThongSo!$C$21/2-CT_ThongSo!$C$28)*K7 -> 42.951462 | M7: =J7/L7 -> 0.57039472 | N7: =IF(AND(H7<=1,M7<=1),"ĐẠT","KHÔNG ĐẠT") -> ĐẠT | O7: =B7*(CT_ThongSo!$C$22+CT_ThongSo!$C$23) -> 99 | P7: =O7*PI()*CT_ThongSo!$C$21^2/4 -> 9.5249162
A8: BÈ 3 | B8: 15 | C8: 4 | D8: 25 | E8: 350 | F8: =VLOOKUP(A8,CT_LucDay!$A$6:$M$14,13,FALSE) -> 38.636921 | G8: =CT_ThongSo!$C$32 -> 116.06332 | H8: =F8/G8 -> 0.33289519 | I8: =F8*(CT_ThongSo!$C$24+1.5*CT_ThongSo!$C$21+0.5*F8/CT_ThongSo!$C$29) -> 30.071931 | J8: =CT_ThongSo!$C$27*I8 -> 36.086317 | K8: =2/TAN(PI()/C8) -> 2 | L8: =PI()*D8^2/4/1000000*E8*1000*(CT_ThongSo!$C$21/2-CT_ThongSo!$C$28)*K8 -> 42.951462 | M8: =J8/L8 -> 0.84016505 | N8: =IF(AND(H8<=1,M8<=1),"ĐẠT","KHÔNG ĐẠT") -> ĐẠT | O8: =B8*(CT_ThongSo!$C$22+CT_ThongSo!$C$23) -> 99 | P8: =O8*PI()*CT_ThongSo!$C$21^2/4 -> 9.5249162
A9: BÈ 3A | B9: 31 | C9: 6 | D9: 28 | E9: 350 | F9: =VLOOKUP(A9,CT_LucDay!$A$6:$M$14,13,FALSE) -> 73.659983 | G9: =CT_ThongSo!$C$32 -> 116.06332 | H9: =F9/G9 -> 0.63465342 | I9: =F9*(CT_ThongSo!$C$24+1.5*CT_ThongSo!$C$21+0.5*F9/CT_ThongSo!$C$29) -> 67.568414 | J9: =CT_ThongSo!$C$27*I9 -> 81.082097 | K9: =2/TAN(PI()/C9) -> 3.4641016 | L9: =PI()*D9^2/4/1000000*E9*1000*(CT_ThongSo!$C$21/2-CT_ThongSo!$C$28)*K9 -> 93.319977 | M9: =J9/L9 -> 0.86886109 | N9: =IF(AND(H9<=1,M9<=1),"ĐẠT","KHÔNG ĐẠT") -> ĐẠT | O9: =B9*(CT_ThongSo!$C$22+CT_ThongSo!$C$23) -> 204.6 | P9: =O9*PI()*CT_ThongSo!$C$21^2/4 -> 19.684827
A10: BÈ 5A | B10: 36 | C10: 6 | D10: 32 | E10: 350 | F10: =VLOOKUP(A10,CT_LucDay!$A$6:$M$14,13,FALSE) -> 87.342727 | G10: =CT_ThongSo!$C$32 -> 116.06332 | H10: =F10/G10 -> 0.75254376 | I10: =F10*(CT_ThongSo!$C$24+1.5*CT_ThongSo!$C$21+0.5*F10/CT_ThongSo!$C$29) -> 84.86203 | J10: =CT_ThongSo!$C$27*I10 -> 101.83444 | K10: =2/TAN(PI()/C10) -> 3.4641016 | L10: =PI()*D10^2/4/1000000*E10*1000*(CT_ThongSo!$C$21/2-CT_ThongSo!$C$28)*K10 -> 121.88732 | M10: =J10/L10 -> 0.83548016 | N10: =IF(AND(H10<=1,M10<=1),"ĐẠT","KHÔNG ĐẠT") -> ĐẠT | O10: =B10*(CT_ThongSo!$C$22+CT_ThongSo!$C$23) -> 237.6 | P10: =O10*PI()*CT_ThongSo!$C$21^2/4 -> 22.859799
A11: BÈ 6 | B11: 28 | C11: 4 | D11: 25 | E11: 350 | F11: =VLOOKUP(A11,CT_LucDay!$A$6:$M$14,13,FALSE) -> 40.815408 | G11: =CT_ThongSo!$C$32 -> 116.06332 | H11: =F11/G11 -> 0.351665 | I11: =F11*(CT_ThongSo!$C$24+1.5*CT_ThongSo!$C$21+0.5*F11/CT_ThongSo!$C$29) -> 32.120334 | J11: =CT_ThongSo!$C$27*I11 -> 38.544401 | K11: =2/TAN(PI()/C11) -> 2 | L11: =PI()*D11^2/4/1000000*E11*1000*(CT_ThongSo!$C$21/2-CT_ThongSo!$C$28)*K11 -> 42.951462 | M11: =J11/L11 -> 0.89739439 | N11: =IF(AND(H11<=1,M11<=1),"ĐẠT","KHÔNG ĐẠT") -> ĐẠT | O11: =B11*(CT_ThongSo!$C$22+CT_ThongSo!$C$23) -> 184.8 | P11: =O11*PI()*CT_ThongSo!$C$21^2/4 -> 17.779844
A12: BÈ 7 | B12: 24 | C12: 4 | D12: 28 | E12: 350 | F12: =VLOOKUP(A12,CT_LucDay!$A$6:$M$14,13,FALSE) -> 45.580573 | G12: =CT_ThongSo!$C$32 -> 116.06332 | H12: =F12/G12 -> 0.3927216 | I12: =F12*(CT_ThongSo!$C$24+1.5*CT_ThongSo!$C$21+0.5*F12/CT_ThongSo!$C$29) -> 36.732257 | J12: =CT_ThongSo!$C$27*I12 -> 44.078709 | K12: =2/TAN(PI()/C12) -> 2 | L12: =PI()*D12^2/4/1000000*E12*1000*(CT_ThongSo!$C$21/2-CT_ThongSo!$C$28)*K12 -> 53.878314 | M12: =J12/L12 -> 0.81811596 | N12: =IF(AND(H12<=1,M12<=1),"ĐẠT","KHÔNG ĐẠT") -> ĐẠT | O12: =B12*(CT_ThongSo!$C$22+CT_ThongSo!$C$23) -> 158.4 | P12: =O12*PI()*CT_ThongSo!$C$21^2/4 -> 15.239866
A13: BÈ 8 | B13: 46 | C13: 6 | D13: 25 | E13: 350 | F13: =VLOOKUP(A13,CT_LucDay!$A$6:$M$14,13,FALSE) -> 59.12689 | G13: =CT_ThongSo!$C$32 -> 116.06332 | H13: =F13/G13 -> 0.50943648 | I13: =F13*(CT_ThongSo!$C$24+1.5*CT_ThongSo!$C$21+0.5*F13/CT_ThongSo!$C$29) -> 50.827279 | J13: =CT_ThongSo!$C$27*I13 -> 60.992734 | K13: =2/TAN(PI()/C13) -> 3.4641016 | L13: =PI()*D13^2/4/1000000*E13*1000*(CT_ThongSo!$C$21/2-CT_ThongSo!$C$28)*K13 -> 74.394115 | M13: =J13/L13 -> 0.81985967 | N13: =IF(AND(H13<=1,M13<=1),"ĐẠT","KHÔNG ĐẠT") -> ĐẠT | O13: =B13*(CT_ThongSo!$C$22+CT_ThongSo!$C$23) -> 303.6 | P13: =O13*PI()*CT_ThongSo!$C$21^2/4 -> 29.209743
